Workbook

Sheet 期望
B2: 释放奇术时主属性 | C2: 破竹 | D2: <--下拉菜单 | E2: 武学常驻属性 | F2: 通用增伤 | G2: 蓄力增伤 | H2: 断石之构 | I2: 易水歌 | J2: 征人归 | K2: 极乐泣血
E3: 150.7 | F3: =VLOOKUP($F$7,目标属性!$A:$R,3,FALSE)+IF(I3="√",5%,0)+IF(J3="√",8%,0)+IF(J5="火",1.5%,0)+IF(J5="毒",1%,0)+I5+IF(G5="岳山倾",3.5%,0)+E18 -> 0.303 | G3: 0 | H3: √ | I3: √ | J3: × | K3: ×
B4: 最小外功攻击 | C4: 最大外功攻击 | D4: 外功穿透 | E4: 外攻伤害加成 | G4: 套装 | H4: 5层惊神 | I4: 九枪Q层数 | J4: 天工 | K4: 玉鳞脍
B5: 3407.3 | C5: 2543.3 | D5: 63.5 | E5: 0 | G5: 燕归 | H5: × | I5: 0 | J5: 火 | K5: √
B6: 最小鸣金攻击 | C6: 最大鸣金攻击 | D6: 鸣金穿透 | E6: 鸣金伤害加成 | F6: 目标
E7: 0 | F7: 笃山衔蝉 | G7: <-下拉菜单
B8: 最小裂石攻击 | C8: 最大裂石攻击 | D8: 裂石穿透 | E8: 裂石伤害加成 | F8: 目标防御 | I8: 忘川泥鱼易水断石 记得填真实延迟
E9: 0 | F9: =VLOOKUP($F$7,目标属性!$A:$R,2,FALSE) -> 559
B10: 最小牵丝攻击 | C10: 最大牵丝攻击 | D10: 牵丝穿透 | E10: 牵丝伤害加成 | F10: 判定抗性
E11: 0 | F11: 2.15
B12: 最小破竹攻击 | C12: 最大破竹攻击 | D12: 破竹穿透 | E12: 破竹伤害加成
B13: 490.8 | C13: 1221.8 | D13: =IF(B13>=441,29.6,29) -> 29.6 | E13: =IF(B13>=441,14.8%,14.5%) -> 0.148
B14: 最小无相攻击 | C14: 最大无相攻击 | D14: 无相穿透 | E14: 固伤加成
B15: 66 | C15: =66+59.8 -> 125.8 | E15: 0.3
A16: 括号内-> | B16: 精准率 | C16: 1.0086 | D16: 会心伤害加成 | E16: =54.4%+IF(F19="√",10%,0)+IF(K3="√",3.5%,0) -> 0.644
B17: 会心率 | C17: 0.7265 | D17: 会意伤害加成 | E17: =35% -> 0.35
B18: 会意率 | C18: 0.0986 | D18: 首领增伤 | E18: 0.088 | F18: 沧海帖 | G18: 行藏帖
B19: 直接会心率 | C19: =IF(H3="√",4.1%,0)+IF(I3="√",4.6%,0) -> 0.087 | F19: √ | G19: ×
B20: 直接会意率 | C20: 0 | F20: 相杀瘫痪 | G20: 易伤层数
B21: 武器增伤 | F21: √ | G21: 8
B22: 双刀 | C22: 0.086 | D22: 定音
B23: 绳标 | C23: 0.086 | D23: 鼠鼠 | E23: 0.32
B24: 全武器增伤 | C24: 0.084 | D24: 双刀轻击
B25: 单体奇术 | C25: 0 | F25: 提前打断
B26: 群体奇术 | C26: 0 | D26: 平均延迟(ms) | E26: 6 | F26: √
B27: N/A | C27: 0
B28: 用时 | C28: =74.5+E26*108/1000-IF(E26>=12,2.8,0)-IF(AND($E$26<12,$E$26>6,$F$26="√"),1.2,0) -> 75.148 | E28: 总期望 | Q28: 外功 | AF28: 固伤 | AU28: 鸣金 | BJ28: 裂石 | BY28: 牵丝 | CN28: 破竹 | DC28: 无相
F29: 次数 | G29: 定音增伤 | H29: 期望伤害 | I29: 占比 | J29: 增伤 | K29: 补正 | L29: 生效会心 | M29: 生效会意 | N29: 生效精准 | O29: 武器类型 | P29: 生效增伤 | Q29: 最小 | R29: 平均 | S29: 最大 | T29: 穿透增伤 | U29: 伤害加成 | V29: 倍率 | W29: 擦伤伤害 | X29: 擦伤占比 | Y29: 会心伤害 | Z29: 会心占比 | AA29: 会意伤害 | AB29: 会意占比 | AC29: 普攻伤害 | AD29: 普攻占比 | AE29: 平均伤害 | AF29: 最小 | AG29: 平均 | AH29: 最大 | AI29: 穿透增伤 | AJ29: 伤害加成 | AK29: 倍率 | AL29: 擦伤伤害 | AM29: 擦伤占比 | AN29: 会心伤害 | AO29: 会心占比 | AP29: 会意伤害 | AQ29: 会意占比 | AR29: 普攻伤害 | AS29: 普攻占比 | AT29: 平均伤害 | AU29: 最小 | AV29: 平均 | AW29: 最大 | AX29: 穿透增伤 | AY29: 伤害加成 | AZ29: 倍率 | BA29: 擦伤伤害 | BB29: 擦伤占比 | BC29: 会心伤害 | BD29: 会心占比 | BE29: 会意伤害 | BF29: 会意占比 | BG29: 普攻伤害 | BH29: 普攻占比 | BI29: 平均伤害 | BJ29: 最小 | BK29: 平均 | BL29: 最大 | BM29: 穿透增伤 | BN29: 伤害加成 | BO29: 倍率 | BP29: 擦伤伤害 | BQ29: 擦伤占比 | BR29: 会心伤害 | BS29: 会心占比 | BT29: 会意伤害 | BU29: 会意占比 | BV29: 普攻伤害 | BW29: 普攻占比 | BX29: 平均伤害 | BY29: 最小 | BZ29: 平均 | CA29: 最大 | CB29: 穿透增伤 | CC29: 伤害加成 | CD29: 倍率 | CE29: 擦伤伤害 | CF29: 擦伤占比 | CG29: 会心伤害 | CH29: 会心占比 | CI29: 会意伤害 | CJ29: 会意占比 | CK29: 普攻伤害 | CL29: 普攻占比 | CM29: 平均伤害 | CN29: 最小 | CO29: 平均 | CP29: 最大 | CQ29: 穿透增伤 | CR29: 伤害加成 | CS29: 倍率 | CT29: 擦伤伤害 | CU29: 擦伤占比 | CV29: 会心伤害 | CW29: 会心占比 | CX29: 会意伤害 | CY29: 会意占比 | CZ29: 普攻伤害 | DA29: 普攻占比 | DB29: 平均伤害 | DC29: 最小 | DD29: 平均 | DE29: 最大 | DF29: 穿透增伤 | DG29: 伤害加成 | DH29: 倍率 | DI29: 擦伤伤害 | DJ29: 擦伤占比 | DK29: 会心伤害 | DL29: 会心占比 | DM29: 会意伤害 | DN29: 会意占比 | DO29: 普攻伤害 | DP29: 普攻占比 | DQ29: 平均伤害
B30: 总伤 | C30: =SUM(H30:H142) -> 7795282.3 | E30: 萧呤千浪(单次流星红人) | F30: 1 | H30: =IF(VLOOKUP($E30,武器奇术!$A:$R,18,FALSE)="天工",AE30,(AE30+AT30+BI30+BX30+CM30+DB30+DQ30))*(1+J30)*F30*K30*(1+G30) -> 25395.924 | I30: =H30/$C$30 -> 0.0032578582 | J30: =$F$3+VLOOKUP($E30,武器奇术!$A:$R,12,FALSE)+VLOOKUP($E30,武器奇术!$A:$R,14,FALSE)*$G$3+$P30+IF($F$21="√",5%,0) -> 0.473 | K30: =VLOOKUP($E30,武器奇术!$A:$R,11,FALSE) -> 1 | L30: =IF(VLOOKUP($E30,武器奇术!$A:$R,15,FALSE)="天工",0%,IF($C$17+VLOOKUP($E30,武器奇术!$A:$R,7,FALSE)>80%,80%,$C$17+VLOOKUP($E30,武器奇术!$A:$R,7,FALSE))+IF($C$19>20%,20%,$C$19)) -> 0.887 | M30: =IF(VLOOKUP($E30,武器奇术!$A:$R,15,FALSE)="天工",0%,IF($C$18+VLOOKUP($E30,武器奇术!$A:$R,9,FALSE)>40%,40%,$C$18+VLOOKUP($E30,武器奇术!$A:$R,9,FALSE))+IF($C$20>10%,10%,$C$20)) -> 0.0986 | N30: =IF(VLOOKUP($E30,武器奇术!$A:$R,15,FALSE)="天工",100%,MIN($C$16,1)) -> 1 | O30: =VLOOKUP($E30,武器奇术!$A:$R,16,FALSE) -> N/A | P30: =VLOOKUP($O30,$B$22:$C$27,2,FALSE)+IF(OR($O30="双刀",$O30="绳标"),$C$24,0) -> 0 | Q30: =$B$5*(1+VLOOKUP($E30,武器奇术!$A:$R,5,FALSE)+IF($G$5="飞隼",0.1,0)+IF($G$5="撼天",0.05,0))-$F$9*IF(VLOOKUP($E30,武器奇术!$A:$S,19,FALSE)=1,0.9,1)+IF($I$5="√",160,0) -> 2848.3 | R30: =(Q30+S30)/2 -> 2848.3 | S30: =MAX($C$5,$B$5)*(1+VLOOKUP($E30,武器奇术!$A:$R,5,FALSE)+IF($G$5="飞隼",0.1,0)+IF($G$5="撼天",0.05,0))-$F$9*IF(VLOOKUP($E30,武器奇术!$A:$S,19,FALSE)=1,0.9,1)+IF($I$5="√",320,0) -> 2848.3 | T30: =IF(($D$5+VLOOKUP($E30,武器奇术!$A:$R,13,FALSE)+IF($I$3="√",10,0)-VLOOKUP($F$7,目标属性!$A:$R,5,FALSE))>0,($D$5+VLOOKUP($E30,武器奇术!$A:$R,13,FALSE)+IF($I$3="√",10,0)-VLOOKUP($F$7,目标属性!$A:$R,5,FALSE))/200,($D$5+VLOOKUP($E30,武器奇术!$A:$R,13,FALSE)+IF($I$3="√",10,0)-VLOOKUP($F$7,目标属性!$A:$R,5,FALSE))/100) -> 0.2675 | U30: =$E$5+IF(VLOOKUP($E30,武器奇术!$A:$R,18,FALSE)="鼠鼠",0.24,0) -> 0 | V30: 1 | W30: =Q30*VLOOKUP($E30,武器奇术!$A:$R,2,FALSE)*(1+T30)*(1+U30)*V30 -> 5379.9502 | X30: =(1-IF(VLOOKUP($E30,武器奇术!$A:$R,16,FALSE)="陌刀",1,$N30))*(1-$M30) -> 0 | Y30: =R30*VLOOKUP($E30,武器奇术!$A:$R,2,FALSE)*(1+T30)*(1+U30)*V30*(1+$E$16+VLOOKUP($E30,武器奇术!$A:$R,8,FALSE)) -> 11534.613 | Z30: =IF($L30+$M30<=100%,$N30*$L30,$N30*(1-$M30)) -> 0.887 | AA30: =S30*VLOOKUP($E30,武器奇术!$A:$R,2,FALSE)*(1+T30)*(1+U30)*V30*(1+$E$17+VLOOKUP($E30,武器奇术!$A:$R,10,FALSE)) -> 7262.9328 | AB30: =$M30 -> 0.0986 | AC30: =R30*VLOOKUP($E30,武器奇术!$A:$R,2,FALSE)*(1+T30)*(1+U30)*V30 -> 5379.9502 | AD30: =MAX((1-X30-Z30-AB30),0) -> 0.0144 | AE30: =W30*X30+Y30*Z30+AA30*AB30+AC30*AD30 -> 11024.798 | AF30: =VLOOKUP($E30,武器奇术!$A:$R,3,FALSE)*(1+IF(VLOOKUP($E30,武器奇术!$A:$R,15,FALSE)="武器",$E$15,0)) -> 358 | AG30: =(AF30+AH30)/2 -> 358 | AH30: =VLOOKUP($E30,武器奇术!$A:$R,3,FALSE)*(1+IF(VLOOKUP($E30,武器奇术!$A:$R,15,FALSE)="武器",$E$15,0)) -> 358 | AI30: =IF(($D$5+VLOOKUP($E30,武器奇术!$A:$R,13,FALSE)+IF($I$3="√",10,0)-VLOOKUP($F$7,目标属性!$A:$R,5,FALSE))>0,($D$5+VLOOKUP($E30,武器奇术!$A:$R,13,FALSE)+IF($I$3="√",10,0)-VLOOKUP($F$7,目标属性!$A:$R,5,FALSE))/200,($D$5+VLOOKUP($E30,武器奇术!$A:$R,13,FALSE)+IF($I$3="√",10,0)-VLOOKUP($F$7,目标属性!$A:$R,5,FALSE))/100) -> 0.2675 | AJ30: =$E$5+IF(VLOOKUP($E30,武器奇术!$A:$R,18,FALSE)="鼠鼠",0.24,0) -> 0 | AK30: 1 | AL30: =AF30*(1+AI30)*(1+AJ30)*AK30 -> 453.765 | AM30: =(1-IF(VLOOKUP($E30,武器奇术!$A:$R,16,FALSE)="陌刀",1,$N30))*(1-$M30) -> 0 | AN30: =AG30*(1+AI30)*(1+AJ30)*AK30*(1+$E$16+VLOOKUP($E30,武器奇术!$A:$R,8,FALSE)) -> 972.87216 | AO30: =IF($L30+$M30<=100%,$N30*$L30,$N30*(1-$M30)) -> 0.887 | AP30: =AH30*(1+AI30)*(1+AJ30)*AK30*(1+$E$17+VLOOKUP($E30,武器奇术!$A:$R,10,FALSE)) -> 612.58275 | AQ30: =$M30 -> 0.0986 | AR30: =AG30*(1+AI30)*(1+AJ30)*AK30 -> 453.765 | AS30: =MAX((1-AM30-AO30-AQ30),0) -> 0.0144 | AT30: =AL30*AM30+AN30*AO30+AP30*AQ30+AR30*AS30 -> 929.87248 | AU30: =IF(VLOOKUP($E30,武器奇术!$A:$R,18,FALSE)="极乐",0,$B$7*IF($G$5="撼天",1.05,1)+IF(AND(VLOOKUP($E30,武器奇术!$A:$R,15,FALSE)="武器",VLOOKUP($E30,武器奇术!$A:$R,17,FALSE)="鸣金"),$E$3*(1+$E$15),0)) -> 0 | AV30: =(AU30+AW30)/2 -> 0 | AW30: =IF(VLOOKUP($E30,武器奇术!$A:$R,18,FALSE)="极乐",0,MAX($C$7*IF($G$5="撼天",1.05,1)+IF(AND(VLOOKUP($E30,武器奇术!$A:$R,15,FALSE)="武器",VLOOKUP($E30,武器奇术!$A:$R,17,FALSE)="鸣金"),$E$3*(1+$E$15),0),AU30)) -> 0 | AX30: =IF(($D$7+IF(VLOOKUP($E30,武器奇术!$A:$R,17,FALSE)="鸣金",$D$15,0)-VLOOKUP($F$7,目标属性!$A:$R,6,FALSE))>0,($D$7+IF(VLOOKUP($E30,武器奇术!$A:$R,17,FALSE)="鸣金",$D$15,0)-VLOOKUP($F$7,目标属性!$A:$R,6,FALSE))/200,($D$7+IF(VLOOKUP($E30,武器奇术!$A:$R,17,FALSE)="鸣金",$D$15,0)-VLOOKUP($F$7,目标属性!$A:$R,6,FALSE))/100) -> -0.24 | AY30: =$E$7 -> 0 | AZ30: 1 | BA30: =AU30*IF(VLOOKUP($E30,武器奇术!$A:$R,17,FALSE)="鸣金",VLOOKUP($E30,武器奇术!$A:$R,4,FALSE),VLOOKUP($E30,武器奇术!$A:$R,2,FALSE))*(1+AX30)*(1+AY30)*AZ30 -> 0 | BB30: =(1-IF(VLOOKUP($E30,武器奇术!$A:$R,16,FALSE)="陌刀",1,$N30))*(1-$M30) -> 0 | BC30: =AV30*IF(VLOOKUP($E30,武器奇术!$A:$R,17,FALSE)="鸣金",VLOOKUP($E30,武器奇术!$A:$R,4,FALSE),VLOOKUP($E30,武器奇术!$A:$R,2,FALSE))*(1+AX30)*(1+AY30)*AZ30*(1+$E$16+VLOOKUP($E30,武器奇术!$A:$R,8,FALSE)) -> 0 | BD30: =IF($L30+$M30<=100%,$N30*$L30,$N30*(1-$M30)) -> 0.887 | BE30: =AW30*IF(VLOOKUP($E30,武器奇术!$A:$R,17,FALSE)="鸣金",VLOOKUP($E30,武器奇术!$A:$R,4,FALSE),VLOOKUP($E30,武器奇术!$A:$R,2,FALSE))*(1+AX30)*(1+AY30)*AZ30*(1+$E$17+VLOOKUP($E30,武器奇术!$A:$R,10,FALSE)) -> 0 | BF30: =$M30 -> 0.0986 | BG30: =AV30*IF(VLOOKUP($E30,武器奇术!$A:$R,17,FALSE)="鸣金",VLOOKUP($E30,武器奇术!$A:$R,4,FALSE),VLOOKUP($E30,武器奇术!$A:$R,2,FALSE))*(1+AX30)*(1+AY30)*AZ30 -> 0 | BH30: =MAX((1-BB30-BD30-BF30),0) -> 0.0144 | BI30: =BA30*BB30+BC30*BD30+BE30*BF30+BG30*BH30 -> 0 | BJ30: =IF(VLOOKUP($E30,武器奇术!$A:$R,18,FALSE)="极乐",0,$B$9*IF($G$5="撼天",1.05,1)+IF(AND(VLOOKUP($E30,武器奇术!$A:$R,15,FALSE)="武器",VLOOKUP($E30,武器奇术!$A:$R,17,FALSE)="裂石"),$E$3*(1+$E$15),0)) -> 0 | BK30: =(BJ30+BL30)/2 -> 0 | BL30: =IF(VLOOKUP($E30,武器奇术!$A:$R,18,FALSE)="极乐",0,MAX($C$9*IF($G$5="撼天",1.05,1)+IF(AND(VLOOKUP($E30,武器奇术!$A:$R,15,FALSE)="武器",VLOOKUP($E30,武器奇术!$A:$R,17,FALSE)="裂石"),$E$3*(1+$E$15),0),BJ30)) -> 0 | BM30: =IF(($D$9+IF(VLOOKUP($E30,武器奇术!$A:$R,17,FALSE)="裂石",$D$15,0)-VLOOKUP($F$7,目标属性!$A:$R,6,FALSE))>0,($D$9+IF(VLOOKUP($E30,武器奇术!$A:$R,17,FALSE)="裂石",$D$15,0)-VLOOKUP($F$7,目标属性!$A:$R,6,FALSE))/200,($D$9+IF(VLOOKUP($E30,武器奇术!$A:$R,17,FALSE)="裂石",$D$15,0)-VLOOKUP($F$7,目标属性!$A:$R,6,FALSE))/100) -> -0.24 | BN30: =$E$9 -> 0 | BO30: 1 | BP30: =BJ30*IF(VLOOKUP($E30,武器奇术!$A:$R,17,FALSE)="裂石",VLOOKUP($E30,武器奇术!$A:$R,4,FALSE),VLOOKUP($E30,武器奇术!$A:$R,2,FALSE))*(1+BM30)*(1+BN30)*BO30 -> 0 | BQ30: =(1-IF(VLOOKUP($E30,武器奇术!$A:$R,16,FALSE)="陌刀",1,$N30))*(1-$M30) -> 0 | BR30: =BK30*IF(VLOOKUP($E30,武器奇术!$A:$R,17,FALSE)="裂石",VLOOKUP($E30,武器奇术!$A:$R,4,FALSE),VLOOKUP($E30,武器奇术!$A:$R,2,FALSE))*(1+BM30)*(1+BN30)*BO30*(1+$E$16+VLOOKUP($E30,武器奇术!$A:$R,8,FALSE)) -> 0 | BS30: =IF($L30+$M30<=100%,$N30*$L30,$N30*(1-$M30)) -> 0.887 | BT30: =BL30*IF(VLOOKUP($E30,武器奇术!$A:$R,17,FALSE)="裂石",VLOOKUP($E30,武器奇术!$A:$R,4,FALSE),VLOOKUP($E30,武器奇术!$A:$R,2,FALSE))*(1+BM30)*(1+BN30)*BO30*(1+$E$17+VLOOKUP($E30,武器奇术!$A:$R,10,FALSE)) -> 0 | BU30: =$M30 -> 0.0986 | BV30: =BK30*IF(VLOOKUP($E30,武器奇术!$A:$R,17,FALSE)="裂石",VLOOKUP($E30,武器奇术!$A:$R,4,FALSE),VLOOKUP($E30,武器奇术!$A:$R,2,FALSE))*(1+BM30)*(1+BN30)*BO30 -> 0 | BW30: =MAX((1-BQ30-BS30-BU30),0) -> 0.0144 | BX30: =BP30*BQ30+BR30*BS30+BT30*BU30+BV30*BW30 -> 0 | BY30: =IF(VLOOKUP($E30,武器奇术!$A:$R,18,FALSE)="极乐",0,$B$11*IF($G$5="撼天",1.05,1)+IF(AND(VLOOKUP($E30,武器奇术!$A:$R,15,FALSE)="武器",VLOOKUP($E30,武器奇术!$A:$R,17,FALSE)="牵丝"),$E$3*(1+$E$15),0)) -> 0 | BZ30: =(BY30+CA30)/2 -> 0 | CA30: =IF(VLOOKUP($E30,武器奇术!$A:$R,18,FALSE)="极乐",0,MAX($C$11*IF($G$5="撼天",1.05,1)+IF(AND(VLOOKUP($E30,武器奇术!$A:$R,15,FALSE)="武器",VLOOKUP($E30,武器奇术!$A:$R,17,FALSE)="牵丝"),$E$3*(1+$E$15),0),BY30)) -> 0 | CB30: =IF(($D$11+IF(VLOOKUP($E30,武器奇术!$A:$R,17,FALSE)="牵丝",$D$15,0)-VLOOKUP($F$7,目标属性!$A:$R,6,FALSE))>0,($D$11+IF(VLOOKUP($E30,武器奇术!$A:$R,17,FALSE)="牵丝",$D$15,0)-VLOOKUP($F$7,目标属性!$A:$R,6,FALSE))/200,($D$11+IF(VLOOKUP($E30,武器奇术!$A:$R,17,FALSE)="牵丝",$D$15,0)-VLOOKUP($F$7,目标属性!$A:$R,6,FALSE))/100) -> -0.24 | CC30: =$E$11 -> 0 | CD30: 1 | CE30: =BY30*IF(VLOOKUP($E30,武器奇术!$A:$R,17,FALSE)="牵丝",VLOOKUP($E30,武器奇术!$A:$R,4,FALSE),VLOOKUP($E30,武器奇术!$A:$R,2,FALSE))*(1+CB30)*(1+CC30)*CD30 -> 0 | CF30: =(1-IF(VLOOKUP($E30,武器奇术!$A:$R,16,FALSE)="陌刀",1,$N30))*(1-$M30) -> 0 | CG30: =BZ30*IF(VLOOKUP($E30,武器奇术!$A:$R,17,FALSE)="牵丝",VLOOKUP($E30,武器奇术!$A:$R,4,FALSE),VLOOKUP($E30,武器奇术!$A:$R,2,FALSE))*(1+CB30)*(1+CC30)*CD30*(1+$E$16+VLOOKUP($E30,武器奇术!$A:$R,8,FALSE)) -> 0 | CH30: =IF($L30+$M30<=100%,$N30*$L30,$N30*(1-$M30)) -> 0.887 | CI30: =CA30*IF(VLOOKUP($E30,武器奇术!$A:$R,17,FALSE)="牵丝",VLOOKUP($E30,武器奇术!$A:$R,4,FALSE),VLOOKUP($E30,武器奇术!$A:$R,2,FALSE))*(1+CB30)*(1+CC30)*CD30*(1+$E$17+VLOOKUP($E30,武器奇术!$A:$R,10,FALSE)) -> 0 | CJ30: =$M30 -> 0.0986 | CK30: =BZ30*IF(VLOOKUP($E30,武器奇术!$A:$R,17,FALSE)="牵丝",VLOOKUP($E30,武器奇术!$A:$R,4,FALSE),VLOOKUP($E30,武器奇术!$A:$R,2,FALSE))*(1+CB30)*(1+CC30)*CD30 -> 0 | CL30: =MAX((1-CF30-CH30-CJ30),0) -> 0.0144 | CM30: =CE30*CF30+CG30*CH30+CI30*CJ30+CK30*CL30 -> 0 | CN30: =IF(VLOOKUP($E30,武器奇术!$A:$R,18,FALSE)="极乐",0,$B$13*IF($G$5="撼天",1.05,1)+IF(AND(VLOOKUP($E30,武器奇术!$A:$R,15,FALSE)="武器",VLOOKUP($E30,武器奇术!$A:$R,17,FALSE)="破竹"),$E$3*(1+$E$15),0)) -> 490.8 | CO30: =(CN30+CP30)/2 -> 856.3 | CP30: =IF(VLOOKUP($E30,武器奇术!$A:$R,18,FALSE)="极乐",0,MAX($C$13*IF($G$5="撼天",1.05,1)+IF(AND(VLOOKUP($E30,武器奇术!$A:$R,15,FALSE)="武器",VLOOKUP($E30,武器奇术!$A:$R,17,FALSE)="破竹"),$E$3*(1+$E$15),0),CN30)) -> 1221.8 | CQ30: =IF(($D$13+IF(VLOOKUP($E30,武器奇术!$A:$R,17,FALSE)="破竹",$D$15,0)-VLOOKUP($F$7,目标属性!$A:$R,6,FALSE)+IF(VLOOKUP($E30,武器奇术!$A:$V,22,FALSE)=1,4,0)+IF(VLOOKUP($E30,武器奇术!$A:$T,20,FALSE)=1,10,0))>0,($D$13+IF(VLOOKUP($E30,武器奇术!$A:$R,17,FALSE)="破竹",$D$15,0)-VLOOKUP($F$7,目标属性!$A:$R,6,FALSE)+IF(VLOOKUP($E30,武器奇术!$A:$V,22,FALSE)=1,4,0)+IF(VLOOKUP($E30,武器奇术!$A:$T,20,FALSE)=1,10,0))/200,($D$13+IF(VLOOKUP($E30,武器奇术!$A:$R,17,FALSE)="破竹",$D$15,0)-VLOOKUP($F$7,目标属性!$A:$R,6,FALSE)+IF(VLOOKUP($E30,武器奇术!$A:$V,22,FALSE)=1,4,0)+IF(VLOOKUP($E30,武器奇术!$A:$T,20,FALSE)=1,10,0))/100) -> 0.028 | CR30: =$E$13 -> 0.148 | CS30: 1 | CT30: =CN30*IF(VLOOKUP($E30,武器奇术!$A:$R,17,FALSE)="破竹",VLOOKUP($E30,武器奇术!$A:$R,4,FALSE),VLOOKUP($E30,武器奇术!$A:$R,2,FALSE))*(1+CQ30)*(1+CR30)*CS30 -> 1294.7186 | CU30: =(1-IF(VLOOKUP($E30,武器奇术!$A:$R,16,FALSE)="陌刀",1,$N30))*(1-$M30) -> 0 | CV30: =CO30*IF(VLOOKUP($E30,武器奇术!$A:$R,17,FALSE)="破竹",VLOOKUP($E30,武器奇术!$A:$R,4,FALSE),VLOOKUP($E30,武器奇术!$A:$R,2,FALSE))*(1+CQ30)*(1+CR30)*CS30*(1+$E$16+VLOOKUP($E30,武器奇术!$A:$R,8,FALSE)) -> 4843.0789 | CW30: =IF($L30+$M30<=100%,$N30*$L30,$N30*(1-$M30)) -> 0.887 | CX30: =CP30*IF(VLOOKUP($E30,武器奇术!$A:$R,17,FALSE)="破竹",VLOOKUP($E30,武器奇术!$A:$R,4,FALSE),VLOOKUP($E30,武器奇术!$A:$R,2,FALSE))*(1+CQ30)*(1+CR30)*CS30*(1+$E$17+VLOOKUP($E30,武器奇术!$A:$R,10,FALSE)) -> 4351.1566 | CY30: =$M30 -> 0.0986 | CZ30: =CO30*IF(VLOOKUP($E30,武器奇术!$A:$R,17,FALSE)="破竹",VLOOKUP($E30,武器奇术!$A:$R,4,FALSE),VLOOKUP($E30,武器奇术!$A:$R,2,FALSE))*(1+CQ30)*(1+CR30)*CS30 -> 2258.8987 | DA30: =MAX((1-CU30-CW30-CY30),0) -> 0.0144 | DB30: =CT30*CU30+CV30*CW30+CX30*CY30+CZ30*DA30 -> 4757.3632 | DC30: =IF(VLOOKUP($E30,武器奇术!$A:$R,18,FALSE)="极乐",0,$B$15) -> 66 | DD30: =(DC30+DE30)/2 -> 95.9 | DE30: =IF(VLOOKUP($E30,武器奇术!$A:$R,18,FALSE)="极乐",0,$C$15) -> 125.8 | DF30: =IF((IF(VLOOKUP($E30,武器奇术!$A:$R,17,FALSE)="鸣金",$D$7,0)+IF(VLOOKUP($E30,武器奇术!$A:$R,17,FALSE)="裂石",$D$9,0)+IF(VLOOKUP($E30,武器奇术!$A:$R,17,FALSE)="牵丝",$D$11,0)+IF(VLOOKUP($E30,武器奇术!$A:$R,17,FALSE)="破竹",$D$13,0)+$D$15-VLOOKUP($F$7,目标属性!$A:$R,6,FALSE)+IF(VLOOKUP($E30,武器奇术!$A:$V,22,FALSE)=1,4,0)+IF(VLOOKUP($E30,武器奇术!$A:$T,20,FALSE)=1,10,0))>0,(IF(VLOOKUP($E30,武器奇术!$A:$R,17,FALSE)="鸣金",$D$7,0)+IF(VLOOKUP($E30,武器奇术!$A:$R,17,FALSE)="裂石",$D$9,0)+IF(VLOOKUP($E30,武器奇术!$A:$R,17,FALSE)="牵丝",$D$11,0)+IF(VLOOKUP($E30,武器奇术!$A:$R,17,FALSE)="破竹",$D$13,0)+$D$15-VLOOKUP($F$7,目标属性!$A:$R,6,FALSE)+IF(VLOOKUP($E30,武器奇术!$A:$V,22,FALSE)=1,4,0)+IF(VLOOKUP($E30,武器奇术!$A:$T,20,FALSE)=1,10,0))/200,(IF(VLOOKUP($E30,武器奇术!$A:$R,17,FALSE)="鸣金",$D$7,0)+IF(VLOOKUP($E30,武器奇术!$A:$R,17,FALSE)="裂石",$D$9,0)+IF(VLOOKUP($E30,武器奇术!$A:$R,17,FALSE)="牵丝",$D$11,0)+IF(VLOOKUP($E30,武器奇术!$A:$R,17,FALSE)="破竹",$D$13,0)+$D$15-VLOOKUP($F$7,目标属性!$A:$R,6,FALSE)+IF(VLOOKUP($E30,武器奇术!$A:$V,22,FALSE)=1,4,0)+IF(VLOOKUP($E30,武器奇术!$A:$T,20,FALSE)=1,10,0))/100) -> 0.028 | DG30: =$E$13 -> 0.148 | DH30: 1 | DI30: =DC30*IF(VLOOKUP($E30,武器奇术!$A:$R,17,FALSE)="破竹",VLOOKUP($E30,武器奇术!$A:$R,4,FALSE),VLOOKUP($E30,武器奇术!$A:$R,2,FALSE))*(1+DF30)*(1+DG30)*DH30 -> 174.10641 | DJ30: =(1-IF(VLOOKUP($E30,武器奇术!$A:$R,16,FALSE)="陌刀",1,$N30))*(1-$M30) -> 0 | DK30: =DD30*IF(VLOOKUP($E30,武器奇术!$A:$R,17,FALSE)="破竹",VLOOKUP($E30,武器奇术!$A:$R,4,FALSE),VLOOKUP($E30,武器奇术!$A:$R,2,FALSE))*(1+DF30)*(1+DG30)*DH30*(1+$E$16+VLOOKUP($E30,武器奇术!$A:$R,8,FALSE)) -> 542.39317 | DL30: =IF($L30+$M30<=100%,$N30*$L30,$N30*(1-$M30)) -> 0.887 | DM30: =DE30*IF(VLOOKUP($E30,武器奇术!$A:$R,17,FALSE)="破竹",VLOOKUP($E30,武器奇术!$A:$R,4,FALSE),VLOOKUP($E30,武器奇术!$A:$R,2,FALSE))*(1+DF30)*(1+DG30)*DH30*(1+$E$17+VLOOKUP($E30,武器奇术!$A:$R,10,FALSE)) -> 448.00744 | DN30: =$M30 -> 0.0986 | DO30: =DD30*IF(VLOOKUP($E30,武器奇术!$A:$R,17,FALSE)="破竹",VLOOKUP($E30,武器奇术!$A:$R,4,FALSE),VLOOKUP($E30,武器奇术!$A:$R,2,FALSE))*(1+DF30)*(1+DG30)*DH30 -> 252.98189 | DP30: =MAX((1-DJ30-DL30-DN30),0) -> 0.0144 | DQ30: =DI30*DJ30+DK30*DL30+DM30*DN30+DO30*DP30 -> 528.91921
E31: 萧呤千浪(单次流星红人) | F31: 1 | H31: =IF(VLOOKUP($E31,武器奇术!$A:$R,18,FALSE)="天工",AE31,(AE31+AT31+BI31+BX31+CM31+DB31+DQ31))*(1+J31)*F31*K31*(1+G31) -> 25395.924 | I31: =H31/$C$30 -> 0.0032578582 | J31: =$F$3+VLOOKUP($E31,武器奇术!$A:$R,12,FALSE)+VLOOKUP($E31,武器奇术!$A:$R,14,FALSE)*$G$3+$P31+IF($F$21="√",5%,0) -> 0.473 | K31: =VLOOKUP($E31,武器奇术!$A:$R,11,FALSE) -> 1 | L31: =IF(VLOOKUP($E31,武器奇术!$A:$R,15,FALSE)="天工",0%,IF($C$17+VLOOKUP($E31,武器奇术!$A:$R,7,FALSE)>80%,80%,$C$17+VLOOKUP($E31,武器奇术!$A:$R,7,FALSE))+IF($C$19>20%,20%,$C$19)) -> 0.887 | M31: =IF(VLOOKUP($E31,武器奇术!$A:$R,15,FALSE)="天工",0%,IF($C$18+VLOOKUP($E31,武器奇术!$A:$R,9,FALSE)>40%,40%,$C$18+VLOOKUP($E31,武器奇术!$A:$R,9,FALSE))+IF($C$20>10%,10%,$C$20)) -> 0.0986 | N31: =IF(VLOOKUP($E31,武器奇术!$A:$R,15,FALSE)="天工",100%,MIN($C$16,1)) -> 1 | O31: =VLOOKUP($E31,武器奇术!$A:$R,16,FALSE) -> N/A | P31: =VLOOKUP($O31,$B$22:$C$27,2,FALSE)+IF(OR($O31="双刀",$O31="绳标"),$C$24,0) -> 0 | Q31: =$B$5*(1+VLOOKUP($E31,武器奇术!$A:$R,5,FALSE)+IF($G$5="飞隼",0.1,0)+IF($G$5="撼天",0.05,0))-$F$9*IF(VLOOKUP($E31,武器奇术!$A:$S,19,FALSE)=1,0.9,1)+IF($I$5="√",160,0) -> 2848.3 | R31: =(Q31+S31)/2 -> 2848.3 | S31: =MAX($C$5,$B$5)*(1+VLOOKUP($E31,武器奇术!$A:$R,5,FALSE)+IF($G$5="飞隼",0.1,0)+IF($G$5="撼天",0.05,0))-$F$9*IF(VLOOKUP($E31,武器奇术!$A:$S,19,FALSE)=1,0.9,1)+IF($I$5="√",320,0) -> 2848.3 | T31: =IF(($D$5+VLOOKUP($E31,武器奇术!$A:$R,13,FALSE)+IF($I$3="√",10,0)-VLOOKUP($F$7,目标属性!$A:$R,5,FALSE))>0,($D$5+VLOOKUP($E31,武器奇术!$A:$R,13,FALSE)+IF($I$3="√",10,0)-VLOOKUP($F$7,目标属性!$A:$R,5,FALSE))/200,($D$5+VLOOKUP($E31,武器奇术!$A:$R,13,FALSE)+IF($I$3="√",10,0)-VLOOKUP($F$7,目标属性!$A:$R,5,FALSE))/100) -> 0.2675 | U31: =$E$5+IF(VLOOKUP($E31,武器奇术!$A:$R,18,FALSE)="鼠鼠",0.24,0) -> 0 | V31: 1 | W31: =Q31*VLOOKUP($E31,武器奇术!$A:$R,2,FALSE)*(1+T31)*(1+U31)*V31 -> 5379.9502 | X31: =(1-IF(VLOOKUP($E31,武器奇术!$A:$R,16,FALSE)="陌刀",1,$N31))*(1-$M31) -> 0 | Y31: =R31*VLOOKUP($E31,武器奇术!$A:$R,2,FALSE)*(1+T31)*(1+U31)*V31*(1+$E$16+VLOOKUP($E31,武器奇术!$A:$R,8,FALSE)) -> 11534.613 | Z31: =IF($L31+$M31<=100%,$N31*$L31,$N31*(1-$M31)) -> 0.887 | AA31: =S31*VLOOKUP($E31,武器奇术!$A:$R,2,FALSE)*(1+T31)*(1+U31)*V31*(1+$E$17+VLOOKUP($E31,武器奇术!$A:$R,10,FALSE)) -> 7262.9328 | AB31: =$M31 -> 0.0986 | AC31: =R31*VLOOKUP($E31,武器奇术!$A:$R,2,FALSE)*(1+T31)*(1+U31)*V31 -> 5379.9502 | AD31: =MAX((1-X31-Z31-AB31),0) -> 0.0144 | AE31: =W31*X31+Y31*Z31+AA31*AB31+AC31*AD31 -> 11024.798 | AF31: =VLOOKUP($E31,武器奇术!$A:$R,3,FALSE)*(1+IF(VLOOKUP($E31,武器奇术!$A:$R,15,FALSE)="武器",$E$15,0)) -> 358 | AG31: =(AF31+AH31)/2 -> 358 | AH31: =VLOOKUP($E31,武器奇术!$A:$R,3,FALSE)*(1+IF(VLOOKUP($E31,武器奇术!$A:$R,15,FALSE)="武器",$E$15,0)) -> 358 | AI31: =IF(($D$5+VLOOKUP($E31,武器奇术!$A:$R,13,FALSE)+IF($I$3="√",10,0)-VLOOKUP($F$7,目标属性!$A:$R,5,FALSE))>0,($D$5+VLOOKUP($E31,武器奇术!$A:$R,13,FALSE)+IF($I$3="√",10,0)-VLOOKUP($F$7,目标属性!$A:$R,5,FALSE))/200,($D$5+VLOOKUP($E31,武器奇术!$A:$R,13,FALSE)+IF($I$3="√",10,0)-VLOOKUP($F$7,目标属性!$A:$R,5,FALSE))/100) -> 0.2675 | AJ31: =$E$5+IF(VLOOKUP($E31,武器奇术!$A:$R,18,FALSE)="鼠鼠",0.24,0) -> 0 | AK31: 1 | AL31: =AF31*(1+AI31)*(1+AJ31)*AK31 -> 453.765 | AM31: =(1-IF(VLOOKUP($E31,武器奇术!$A:$R,16,FALSE)="陌刀",1,$N31))*(1-$M31) -> 0 | AN31: =AG31*(1+AI31)*(1+AJ31)*AK31*(1+$E$16+VLOOKUP($E31,武器奇术!$A:$R,8,FALSE)) -> 972.87216 | AO31: =IF($L31+$M31<=100%,$N31*$L31,$N31*(1-$M31)) -> 0.887 | AP31: =AH31*(1+AI31)*(1+AJ31)*AK31*(1+$E$17+VLOOKUP($E31,武器奇术!$A:$R,10,FALSE)) -> 612.58275 | AQ31: =$M31 -> 0.0986 | AR31: =AG31*(1+AI31)*(1+AJ31)*AK31 -> 453.765 | AS31: =MAX((1-AM31-AO31-AQ31),0) -> 0.0144 | AT31: =AL31*AM31+AN31*AO31+AP31*AQ31+AR31*AS31 -> 929.87248 | AU31: =IF(VLOOKUP($E31,武器奇术!$A:$R,18,FALSE)="极乐",0,$B$7*IF($G$5="撼天",1.05,1)+IF(AND(VLOOKUP($E31,武器奇术!$A:$R,15,FALSE)="武器",VLOOKUP($E31,武器奇术!$A:$R,17,FALSE)="鸣金"),$E$3*(1+$E$15),0)) -> 0 | AV31: =(AU31+AW31)/2 -> 0 | AW31: =IF(VLOOKUP($E31,武器奇术!$A:$R,18,FALSE)="极乐",0,MAX($C$7*IF($G$5="撼天",1.05,1)+IF(AND(VLOOKUP($E31,武器奇术!$A:$R,15,FALSE)="武器",VLOOKUP($E31,武器奇术!$A:$R,17,FALSE)="鸣金"),$E$3*(1+$E$15),0),AU31)) -> 0 | AX31: =IF(($D$7+IF(VLOOKUP($E31,武器奇术!$A:$R,17,FALSE)="鸣金",$D$15,0)-VLOOKUP($F$7,目标属性!$A:$R,6,FALSE))>0,($D$7+IF(VLOOKUP($E31,武器奇术!$A:$R,17,FALSE)="鸣金",$D$15,0)-VLOOKUP($F$7,目标属性!$A:$R,6,FALSE))/200,($D$7+IF(VLOOKUP($E31,武器奇术!$A:$R,17,FALSE)="鸣金",$D$15,0)-VLOOKUP($F$7,目标属性!$A:$R,6,FALSE))/100) -> -0.24 | AY31: =$E$7 -> 0 | AZ31: 1 | BA31: =AU31*IF(VLOOKUP($E31,武器奇术!$A:$R,17,FALSE)="鸣金",VLOOKUP($E31,武器奇术!$A:$R,4,FALSE),VLOOKUP($E31,武器奇术!$A:$R,2,FALSE))*(1+AX31)*(1+AY31)*AZ31 -> 0 | BB31: =(1-IF(VLOOKUP($E31,武器奇术!$A:$R,16,FALSE)="陌刀",1,$N31))*(1-$M31) -> 0 | BC31: =AV31*IF(VLOOKUP($E31,武器奇术!$A:$R,17,FALSE)="鸣金",VLOOKUP($E31,武器奇术!$A:$R,4,FALSE),VLOOKUP($E31,武器奇术!$A:$R,2,FALSE))*(1+AX31)*(1+AY31)*AZ31*(1+$E$16+VLOOKUP($E31,武器奇术!$A:$R,8,FALSE)) -> 0 | BD31: =IF($L31+$M31<=100%,$N31*$L31,$N31*(1-$M31)) -> 0.887 | BE31: =AW31*IF(VLOOKUP($E31,武器奇术!$A:$R,17,FALSE)="鸣金",VLOOKUP($E31,武器奇术!$A:$R,4,FALSE),VLOOKUP($E31,武器奇术!$A:$R,2,FALSE))*(1+AX31)*(1+AY31)*AZ31*(1+$E$17+VLOOKUP($E31,武器奇术!$A:$R,10,FALSE)) -> 0 | BF31: =$M31 -> 0.0986 | BG31: =AV31*IF(VLOOKUP($E31,武器奇术!$A:$R,17,FALSE)="鸣金",VLOOKUP($E31,武器奇术!$A:$R,4,FALSE),VLOOKUP($E31,武器奇术!$A:$R,2,FALSE))*(1+AX31)*(1+AY31)*AZ31 -> 0 | BH31: =MAX((1-BB31-BD31-BF31),0) -> 0.0144 | BI31: =BA31*BB31+BC31*BD31+BE31*BF31+BG31*BH31 -> 0 | BJ31: =IF(VLOOKUP($E31,武器奇术!$A:$R,18,FALSE)="极乐",0,$B$9*IF($G$5="撼天",1.05,1)+IF(AND(VLOOKUP($E31,武器奇术!$A:$R,15,FALSE)="武器",VLOOKUP($E31,武器奇术!$A:$R,17,FALSE)="裂石"),$E$3*(1+$E$15),0)) -> 0 | BK31: =(BJ31+BL31)/2 -> 0 | BL31: =IF(VLOOKUP($E31,武器奇术!$A:$R,18,FALSE)="极乐",0,MAX($C$9*IF($G$5="撼天",1.05,1)+IF(AND(VLOOKUP($E31,武器奇术!$A:$R,15,FALSE)="武器",VLOOKUP($E31,武器奇术!$A:$R,17,FALSE)="裂石"),$E$3*(1+$E$15),0),BJ31)) -> 0 | BM31: =IF(($D$9+IF(VLOOKUP($E31,武器奇术!$A:$R,17,FALSE)="裂石",$D$15,0)-VLOOKUP($F$7,目标属性!$A:$R,6,FALSE))>0,($D$9+IF(VLOOKUP($E31,武器奇术!$A:$R,17,FALSE)="裂石",$D$15,0)-VLOOKUP($F$7,目标属性!$A:$R,6,FALSE))/200,($D$9+IF(VLOOKUP($E31,武器奇术!$A:$R,17,FALSE)="裂石",$D$15,0)-VLOOKUP($F$7,目标属性!$A:$R,6,FALSE))/100) -> -0.24 | BN31: =$E$9 -> 0 | BO31: 1 | BP31: =BJ31*IF(VLOOKUP($E31,武器奇术!$A:$R,17,FALSE)="裂石",VLOOKUP($E31,武器奇术!$A:$R,4,FALSE),VLOOKUP($E31,武器奇术!$A:$R,2,FALSE))*(1+BM31)*(1+BN31)*BO31 -> 0 | BQ31: =(1-IF(VLOOKUP($E31,武器奇术!$A:$R,16,FALSE)="陌刀",1,$N31))*(1-$M31) -> 0 | BR31: =BK31*IF(VLOOKUP($E31,武器奇术!$A:$R,17,FALSE)="裂石",VLOOKUP($E31,武器奇术!$A:$R,4,FALSE),VLOOKUP($E31,武器奇术!$A:$R,2,FALSE))*(1+BM31)*(1+BN31)*BO31*(1+$E$16+VLOOKUP($E31,武器奇术!$A:$R,8,FALSE)) -> 0 | BS31: =IF($L31+$M31<=100%,$N31*$L31,$N31*(1-$M31)) -> 0.887 | BT31: =BL31*IF(VLOOKUP($E31,武器奇术!$A:$R,17,FALSE)="裂石",VLOOKUP($E31,武器奇术!$A:$R,4,FALSE),VLOOKUP($E31,武器奇术!$A:$R,2,FALSE))*(1+BM31)*(1+BN31)*BO31*(1+$E$17+VLOOKUP($E31,武器奇术!$A:$R,10,FALSE)) -> 0 | BU31: =$M31 -> 0.0986 | BV31: =BK31*IF(VLOOKUP($E31,武器奇术!$A:$R,17,FALSE)="裂石",VLOOKUP($E31,武器奇术!$A:$R,4,FALSE),VLOOKUP($E31,武器奇术!$A:$R,2,FALSE))*(1+BM31)*(1+BN31)*BO31 -> 0 | BW31: =MAX((1-BQ31-BS31-BU31),0) -> 0.0144 | BX31: =BP31*BQ31+BR31*BS31+BT31*BU31+BV31*BW31 -> 0 | BY31: =IF(VLOOKUP($E31,武器奇术!$A:$R,18,FALSE)="极乐",0,$B$11*IF($G$5="撼天",1.05,1)+IF(AND(VLOOKUP($E31,武器奇术!$A:$R,15,FALSE)="武器",VLOOKUP($E31,武器奇术!$A:$R,17,FALSE)="牵丝"),$E$3*(1+$E$15),0)) -> 0 | BZ31: =(BY31+CA31)/2 -> 0 | CA31: =IF(VLOOKUP($E31,武器奇术!$A:$R,18,FALSE)="极乐",0,MAX($C$11*IF($G$5="撼天",1.05,1)+IF(AND(VLOOKUP($E31,武器奇术!$A:$R,15,FALSE)="武器",VLOOKUP($E31,武器奇术!$A:$R,17,FALSE)="牵丝"),$E$3*(1+$E$15),0),BY31)) -> 0 | CB31: =IF(($D$11+IF(VLOOKUP($E31,武器奇术!$A:$R,17,FALSE)="牵丝",$D$15,0)-VLOOKUP($F$7,目标属性!$A:$R,6,FALSE))>0,($D$11+IF(VLOOKUP($E31,武器奇术!$A:$R,17,FALSE)="牵丝",$D$15,0)-VLOOKUP($F$7,目标属性!$A:$R,6,FALSE))/200,($D$11+IF(VLOOKUP($E31,武器奇术!$A:$R,17,FALSE)="牵丝",$D$15,0)-VLOOKUP($F$7,目标属性!$A:$R,6,FALSE))/100) -> -0.24 | CC31: =$E$11 -> 0 | CD31: 1 | CE31: =BY31*IF(VLOOKUP($E31,武器奇术!$A:$R,17,FALSE)="牵丝",VLOOKUP($E31,武器奇术!$A:$R,4,FALSE),VLOOKUP($E31,武器奇术!$A:$R,2,FALSE))*(1+CB31)*(1+CC31)*CD31 -> 0 | CF31: =(1-IF(VLOOKUP($E31,武器奇术!$A:$R,16,FALSE)="陌刀",1,$N31))*(1-$M31) -> 0 | CG31: =BZ31*IF(VLOOKUP($E31,武器奇术!$A:$R,17,FALSE)="牵丝",VLOOKUP($E31,武器奇术!$A:$R,4,FALSE),VLOOKUP($E31,武器奇术!$A:$R,2,FALSE))*(1+CB31)*(1+CC31)*CD31*(1+$E$16+VLOOKUP($E31,武器奇术!$A:$R,8,FALSE)) -> 0 | CH31: =IF($L31+$M31<=100%,$N31*$L31,$N31*(1-$M31)) -> 0.887 | CI31: =CA31*IF(VLOOKUP($E31,武器奇术!$A:$R,17,FALSE)="牵丝",VLOOKUP($E31,武器奇术!$A:$R,4,FALSE),VLOOKUP($E31,武器奇术!$A:$R,2,FALSE))*(1+CB31)*(1+CC31)*CD31*(1+$E$17+VLOOKUP($E31,武器奇术!$A:$R,10,FALSE)) -> 0 | CJ31: =$M31 -> 0.0986 | CK31: =BZ31*IF(VLOOKUP($E31,武器奇术!$A:$R,17,FALSE)="牵丝",VLOOKUP($E31,武器奇术!$A:$R,4,FALSE),VLOOKUP($E31,武器奇术!$A:$R,2,FALSE))*(1+CB31)*(1+CC31)*CD31 -> 0 | CL31: =MAX((1-CF31-CH31-CJ31),0) -> 0.0144 | CM31: =CE31*CF31+CG31*CH31+CI31*CJ31+CK31*CL31 -> 0 | CN31: =IF(VLOOKUP($E31,武器奇术!$A:$R,18,FALSE)="极乐",0,$B$13*IF($G$5="撼天",1.05,1)+IF(AND(VLOOKUP($E31,武器奇术!$A:$R,15,FALSE)="武器",VLOOKUP($E31,武器奇术!$A:$R,17,FALSE)="破竹"),$E$3*(1+$E$15),0)) -> 490.8 | CO31: =(CN31+CP31)/2 -> 856.3 | CP31: =IF(VLOOKUP($E31,武器奇术!$A:$R,18,FALSE)="极乐",0,MAX($C$13*IF($G$5="撼天",1.05,1)+IF(AND(VLOOKUP($E31,武器奇术!$A:$R,15,FALSE)="武器",VLOOKUP($E31,武器奇术!$A:$R,17,FALSE)="破竹"),$E$3*(1+$E$15),0),CN31)) -> 1221.8 | CQ31: =IF(($D$13+IF(VLOOKUP($E31,武器奇术!$A:$R,17,FALSE)="破竹",$D$15,0)-VLOOKUP($F$7,目标属性!$A:$R,6,FALSE)+IF(VLOOKUP($E31,武器奇术!$A:$V,22,FALSE)=1,4,0)+IF(VLOOKUP($E31,武器奇术!$A:$T,20,FALSE)=1,10,0))>0,($D$13+IF(VLOOKUP($E31,武器奇术!$A:$R,17,FALSE)="破竹",$D$15,0)-VLOOKUP($F$7,目标属性!$A:$R,6,FALSE)+IF(VLOOKUP($E31,武器奇术!$A:$V,22,FALSE)=1,4,0)+IF(VLOOKUP($E31,武器奇术!$A:$T,20,FALSE)=1,10,0))/200,($D$13+IF(VLOOKUP($E31,武器奇术!$A:$R,17,FALSE)="破竹",$D$15,0)-VLOOKUP($F$7,目标属性!$A:$R,6,FALSE)+IF(VLOOKUP($E31,武器奇术!$A:$V,22,FALSE)=1,4,0)+IF(VLOOKUP($E31,武器奇术!$A:$T,20,FALSE)=1,10,0))/100) -> 0.028 | CR31: =$E$13 -> 0.148 | CS31: 1 | CT31: =CN31*IF(VLOOKUP($E31,武器奇术!$A:$R,17,FALSE)="破竹",VLOOKUP($E31,武器奇术!$A:$R,4,FALSE),VLOOKUP($E31,武器奇术!$A:$R,2,FALSE))*(1+CQ31)*(1+CR31)*CS31 -> 1294.7186 | CU31: =(1-IF(VLOOKUP($E31,武器奇术!$A:$R,16,FALSE)="陌刀",1,$N31))*(1-$M31) -> 0 | CV31: =CO31*IF(VLOOKUP($E31,武器奇术!$A:$R,17,FALSE)="破竹",VLOOKUP($E31,武器奇术!$A:$R,4,FALSE),VLOOKUP($E31,武器奇术!$A:$R,2,FALSE))*(1+CQ31)*(1+CR31)*CS31*(1+$E$16+VLOOKUP($E31,武器奇术!$A:$R,8,FALSE)) -> 4843.0789 | CW31: =IF($L31+$M31<=100%,$N31*$L31,$N31*(1-$M31)) -> 0.887 | CX31: =CP31*IF(VLOOKUP($E31,武器奇术!$A:$R,17,FALSE)="破竹",VLOOKUP($E31,武器奇术!$A:$R,4,FALSE),VLOOKUP($E31,武器奇术!$A:$R,2,FALSE))*(1+CQ31)*(1+CR31)*CS31*(1+$E$17+VLOOKUP($E31,武器奇术!$A:$R,10,FALSE)) -> 4351.1566 | CY31: =$M31 -> 0.0986 | CZ31: =CO31*IF(VLOOKUP($E31,武器奇术!$A:$R,17,FALSE)="破竹",VLOOKUP($E31,武器奇术!$A:$R,4,FALSE),VLOOKUP($E31,武器奇术!$A:$R,2,FALSE))*(1+CQ31)*(1+CR31)*CS31 -> 2258.8987 | DA31: =MAX((1-CU31-CW31-CY31),0) -> 0.0144 | DB31: =CT31*CU31+CV31*CW31+CX31*CY31+CZ31*DA31 -> 4757.3632 | DC31: =IF(VLOOKUP($E31,武器奇术!$A:$R,18,FALSE)="极乐",0,$B$15) -> 66 | DD31: =(DC31+DE31)/2 -> 95.9 | DE31: =IF(VLOOKUP($E31,武器奇术!$A:$R,18,FALSE)="极乐",0,$C$15) -> 125.8 | DF31: =IF((IF(VLOOKUP($E31,武器奇术!$A:$R,17,FALSE)="鸣金",$D$7,0)+IF(VLOOKUP($E31,武器奇术!$A:$R,17,FALSE)="裂石",$D$9,0)+IF(VLOOKUP($E31,武器奇术!$A:$R,17,FALSE)="牵丝",$D$11,0)+IF(VLOOKUP($E31,武器奇术!$A:$R,17,FALSE)="破竹",$D$13,0)+$D$15-VLOOKUP($F$7,目标属性!$A:$R,6,FALSE)+IF(VLOOKUP($E31,武器奇术!$A:$V,22,FALSE)=1,4,0)+IF(VLOOKUP($E31,武器奇术!$A:$T,20,FALSE)=1,10,0))>0,(IF(VLOOKUP($E31,武器奇术!$A:$R,17,FALSE)="鸣金",$D$7,0)+IF(VLOOKUP($E31,武器奇术!$A:$R,17,FALSE)="裂石",$D$9,0)+IF(VLOOKUP($E31,武器奇术!$A:$R,17,FALSE)="牵丝",$D$11,0)+IF(VLOOKUP($E31,武器奇术!$A:$R,17,FALSE)="破竹",$D$13,0)+$D$15-VLOOKUP($F$7,目标属性!$A:$R,6,FALSE)+IF(VLOOKUP($E31,武器奇术!$A:$V,22,FALSE)=1,4,0)+IF(VLOOKUP($E31,武器奇术!$A:$T,20,FALSE)=1,10,0))/200,(IF(VLOOKUP($E31,武器奇术!$A:$R,17,FALSE)="鸣金",$D$7,0)+IF(VLOOKUP($E31,武器奇术!$A:$R,17,FALSE)="裂石",$D$9,0)+IF(VLOOKUP($E31,武器奇术!$A:$R,17,FALSE)="牵丝",$D$11,0)+IF(VLOOKUP($E31,武器奇术!$A:$R,17,FALSE)="破竹",$D$13,0)+$D$15-VLOOKUP($F$7,目标属性!$A:$R,6,FALSE)+IF(VLOOKUP($E31,武器奇术!$A:$V,22,FALSE)=1,4,0)+IF(VLOOKUP($E31,武器奇术!$A:$T,20,FALSE)=1,10,0))/100) -> 0.028 | DG31: =$E$13 -> 0.148 | DH31: 1 | DI31: =DC31*IF(VLOOKUP($E31,武器奇术!$A:$R,17,FALSE)="破竹",VLOOKUP($E31,武器奇术!$A:$R,4,FALSE),VLOOKUP($E31,武器奇术!$A:$R,2,FALSE))*(1+DF31)*(1+DG31)*DH31 -> 174.10641 | DJ31: =(1-IF(VLOOKUP($E31,武器奇术!$A:$R,16,FALSE)="陌刀",1,$N31))*(1-$M31) -> 0 | DK31: =DD31*IF(VLOOKUP($E31,武器奇术!$A:$R,17,FALSE)="破竹",VLOOKUP($E31,武器奇术!$A:$R,4,FALSE),VLOOKUP($E31,武器奇术!$A:$R,2,FALSE))*(1+DF31)*(1+DG31)*DH31*(1+$E$16+VLOOKUP($E31,武器奇术!$A:$R,8,FALSE)) -> 542.39317 | DL31: =IF($L31+$M31<=100%,$N31*$L31,$N31*(1-$M31)) -> 0.887 | DM31: =DE31*IF(VLOOKUP($E31,武器奇术!$A:$R,17,FALSE)="破竹",VLOOKUP($E31,武器奇术!$A:$R,4,FALSE),VLOOKUP($E31,武器奇术!$A:$R,2,FALSE))*(1+DF31)*(1+DG31)*DH31*(1+$E$17+VLOOKUP($E31,武器奇术!$A:$R,10,FALSE)) -> 448.00744 | DN31: =$M31 -> 0.0986 | DO31: =DD31*IF(VLOOKUP($E31,武器奇术!$A:$R,17,FALSE)="破竹",VLOOKUP($E31,武器奇术!$A:$R,4,FALSE),VLOOKUP($E31,武器奇术!$A:$R,2,FALSE))*(1+DF31)*(1+DG31)*DH31 -> 252.98189 | DP31: =MAX((1-DJ31-DL31-DN31),0) -> 0.0144 | DQ31: =DI31*DJ31+DK31*DL31+DM31*DN31+DO31*DP31 -> 528.91921
E32: 萧呤千浪(单次流星红人) | F32: 1 | H32: =IF(VLOOKUP($E32,武器奇术!$A:$R,18,FALSE)="天工",AE32,(AE32+AT32+BI32+BX32+CM32+DB32+DQ32))*(1+J32)*F32*K32*(1+G32) -> 25395.924 | I32: =H32/$C$30 -> 0.0032578582 | J32: =$F$3+VLOOKUP($E32,武器奇术!$A:$R,12,FALSE)+VLOOKUP($E32,武器奇术!$A:$R,14,FALSE)*$G$3+$P32+IF($F$21="√",5%,0) -> 0.473 | K32: =VLOOKUP($E32,武器奇术!$A:$R,11,FALSE) -> 1 | L32: =IF(VLOOKUP($E32,武器奇术!$A:$R,15,FALSE)="天工",0%,IF($C$17+VLOOKUP($E32,武器奇术!$A:$R,7,FALSE)>80%,80%,$C$17+VLOOKUP($E32,武器奇术!$A:$R,7,FALSE))+IF($C$19>20%,20%,$C$19)) -> 0.887 | M32: =IF(VLOOKUP($E32,武器奇术!$A:$R,15,FALSE)="天工",0%,IF($C$18+VLOOKUP($E32,武器奇术!$A:$R,9,FALSE)>40%,40%,$C$18+VLOOKUP($E32,武器奇术!$A:$R,9,FALSE))+IF($C$20>10%,10%,$C$20)) -> 0.0986 | N32: =IF(VLOOKUP($E32,武器奇术!$A:$R,15,FALSE)="天工",100%,MIN($C$16,1)) -> 1 | O32: =VLOOKUP($E32,武器奇术!$A:$R,16,FALSE) -> N/A | P32: =VLOOKUP($O32,$B$22:$C$27,2,FALSE)+IF(OR($O32="双刀",$O32="绳标"),$C$24,0) -> 0 | Q32: =$B$5*(1+VLOOKUP($E32,武器奇术!$A:$R,5,FALSE)+IF($G$5="飞隼",0.1,0)+IF($G$5="撼天",0.05,0))-$F$9*IF(VLOOKUP($E32,武器奇术!$A:$S,19,FALSE)=1,0.9,1)+IF($I$5="√",160,0) -> 2848.3 | R32: =(Q32+S32)/2 -> 2848.3 | S32: =MAX($C$5,$B$5)*(1+VLOOKUP($E32,武器奇术!$A:$R,5,FALSE)+IF($G$5="飞隼",0.1,0)+IF($G$5="撼天",0.05,0))-$F$9*IF(VLOOKUP($E32,武器奇术!$A:$S,19,FALSE)=1,0.9,1)+IF($I$5="√",320,0) -> 2848.3 | T32: =IF(($D$5+VLOOKUP($E32,武器奇术!$A:$R,13,FALSE)+IF($I$3="√",10,0)-VLOOKUP($F$7,目标属性!$A:$R,5,FALSE))>0,($D$5+VLOOKUP($E32,武器奇术!$A:$R,13,FALSE)+IF($I$3="√",10,0)-VLOOKUP($F$7,目标属性!$A:$R,5,FALSE))/200,($D$5+VLOOKUP($E32,武器奇术!$A:$R,13,FALSE)+IF($I$3="√",10,0)-VLOOKUP($F$7,目标属性!$A:$R,5,FALSE))/100) -> 0.2675 | U32: =$E$5+IF(VLOOKUP($E32,武器奇术!$A:$R,18,FALSE)="鼠鼠",0.24,0) -> 0 | V32: 1 | W32: =Q32*VLOOKUP($E32,武器奇术!$A:$R,2,FALSE)*(1+T32)*(1+U32)*V32 -> 5379.9502 | X32: =(1-IF(VLOOKUP($E32,武器奇术!$A:$R,16,FALSE)="陌刀",1,$N32))*(1-$M32) -> 0 | Y32: =R32*VLOOKUP($E32,武器奇术!$A:$R,2,FALSE)*(1+T32)*(1+U32)*V32*(1+$E$16+VLOOKUP($E32,武器奇术!$A:$R,8,FALSE)) -> 11534.613 | Z32: =IF($L32+$M32<=100%,$N32*$L32,$N32*(1-$M32)) -> 0.887 | AA32: =S32*VLOOKUP($E32,武器奇术!$A:$R,2,FALSE)*(1+T32)*(1+U32)*V32*(1+$E$17+VLOOKUP($E32,武器奇术!$A:$R,10,FALSE)) -> 7262.9328 | AB32: =$M32 -> 0.0986 | AC32: =R32*VLOOKUP($E32,武器奇术!$A:$R,2,FALSE)*(1+T32)*(1+U32)*V32 -> 5379.9502 | AD32: =MAX((1-X32-Z32-AB32),0) -> 0.0144 | AE32: =W32*X32+Y32*Z32+AA32*AB32+AC32*AD32 -> 11024.798 | AF32: =VLOOKUP($E32,武器奇术!$A:$R,3,FALSE)*(1+IF(VLOOKUP($E32,武器奇术!$A:$R,15,FALSE)="武器",$E$15,0)) -> 358 | AG32: =(AF32+AH32)/2 -> 358 | AH32: =VLOOKUP($E32,武器奇术!$A:$R,3,FALSE)*(1+IF(VLOOKUP($E32,武器奇术!$A:$R,15,FALSE)="武器",$E$15,0)) -> 358 | AI32: =IF(($D$5+VLOOKUP($E32,武器奇术!$A:$R,13,FALSE)+IF($I$3="√",10,0)-VLOOKUP($F$7,目标属性!$A:$R,5,FALSE))>0,($D$5+VLOOKUP($E32,武器奇术!$A:$R,13,FALSE)+IF($I$3="√",10,0)-VLOOKUP($F$7,目标属性!$A:$R,5,FALSE))/200,($D$5+VLOOKUP($E32,武器奇术!$A:$R,13,FALSE)+IF($I$3="√",10,0)-VLOOKUP($F$7,目标属性!$A:$R,5,FALSE))/100) -> 0.2675 | AJ32: =$E$5+IF(VLOOKUP($E32,武器奇术!$A:$R,18,FALSE)="鼠鼠",0.24,0) -> 0 | AK32: 1 | AL32: =AF32*(1+AI32)*(1+AJ32)*AK32 -> 453.765 | AM32: =(1-IF(VLOOKUP($E32,武器奇术!$A:$R,16,FALSE)="陌刀",1,$N32))*(1-$M32) -> 0 | AN32: =AG32*(1+AI32)*(1+AJ32)*AK32*(1+$E$16+VLOOKUP($E32,武器奇术!$A:$R,8,FALSE)) -> 972.87216 | AO32: =IF($L32+$M32<=100%,$N32*$L32,$N32*(1-$M32)) -> 0.887 | AP32: =AH32*(1+AI32)*(1+AJ32)*AK32*(1+$E$17+VLOOKUP($E32,武器奇术!$A:$R,10,FALSE)) -> 612.58275 | AQ32: =$M32 -> 0.0986 | AR32: =AG32*(1+AI32)*(1+AJ32)*AK32 -> 453.765 | AS32: =MAX((1-AM32-AO32-AQ32),0) -> 0.0144 | AT32: =AL32*AM32+AN32*AO32+AP32*AQ32+AR32*AS32 -> 929.87248 | AU32: =IF(VLOOKUP($E32,武器奇术!$A:$R,18,FALSE)="极乐",0,$B$7*IF($G$5="撼天",1.05,1)+IF(AND(VLOOKUP($E32,武器奇术!$A:$R,15,FALSE)="武器",VLOOKUP($E32,武器奇术!$A:$R,17,FALSE)="鸣金"),$E$3*(1+$E$15),0)) -> 0 | AV32: =(AU32+AW32)/2 -> 0 | AW32: =IF(VLOOKUP($E32,武器奇术!$A:$R,18,FALSE)="极乐",0,MAX($C$7*IF($G$5="撼天",1.05,1)+IF(AND(VLOOKUP($E32,武器奇术!$A:$R,15,FALSE)="武器",VLOOKUP($E32,武器奇术!$A:$R,17,FALSE)="鸣金"),$E$3*(1+$E$15),0),AU32)) -> 0 | AX32: =IF(($D$7+IF(VLOOKUP($E32,武器奇术!$A:$R,17,FALSE)="鸣金",$D$15,0)-VLOOKUP($F$7,目标属性!$A:$R,6,FALSE))>0,($D$7+IF(VLOOKUP($E32,武器奇术!$A:$R,17,FALSE)="鸣金",$D$15,0)-VLOOKUP($F$7,目标属性!$A:$R,6,FALSE))/200,($D$7+IF(VLOOKUP($E32,武器奇术!$A:$R,17,FALSE)="鸣金",$D$15,0)-VLOOKUP($F$7,目标属性!$A:$R,6,FALSE))/100) -> -0.24 | AY32: =$E$7 -> 0 | AZ32: 1 | BA32: =AU32*IF(VLOOKUP($E32,武器奇术!$A:$R,17,FALSE)="鸣金",VLOOKUP($E32,武器奇术!$A:$R,4,FALSE),VLOOKUP($E32,武器奇术!$A:$R,2,FALSE))*(1+AX32)*(1+AY32)*AZ32 -> 0 | BB32: =(1-IF(VLOOKUP($E32,武器奇术!$A:$R,16,FALSE)="陌刀",1,$N32))*(1-$M32) -> 0 | BC32: =AV32*IF(VLOOKUP($E32,武器奇术!$A:$R,17,FALSE)="鸣金",VLOOKUP($E32,武器奇术!$A:$R,4,FALSE),VLOOKUP($E32,武器奇术!$A:$R,2,FALSE))*(1+AX32)*(1+AY32)*AZ32*(1+$E$16+VLOOKUP($E32,武器奇术!$A:$R,8,FALSE)) -> 0 | BD32: =IF($L32+$M32<=100%,$N32*$L32,$N32*(1-$M32)) -> 0.887 | BE32: =AW32*IF(VLOOKUP($E32,武器奇术!$A:$R,17,FALSE)="鸣金",VLOOKUP($E32,武器奇术!$A:$R,4,FALSE),VLOOKUP($E32,武器奇术!$A:$R,2,FALSE))*(1+AX32)*(1+AY32)*AZ32*(1+$E$17+VLOOKUP($E32,武器奇术!$A:$R,10,FALSE)) -> 0 | BF32: =$M32 -> 0.0986 | BG32: =AV32*IF(VLOOKUP($E32,武器奇术!$A:$R,17,FALSE)="鸣金",VLOOKUP($E32,武器奇术!$A:$R,4,FALSE),VLOOKUP($E32,武器奇术!$A:$R,2,FALSE))*(1+AX32)*(1+AY32)*AZ32 -> 0 | BH32: =MAX((1-BB32-BD32-BF32),0) -> 0.0144 | BI32: =BA32*BB32+BC32*BD32+BE32*BF32+BG32*BH32 -> 0 | BJ32: =IF(VLOOKUP($E32,武器奇术!$A:$R,18,FALSE)="极乐",0,$B$9*IF($G$5="撼天",1.05,1)+IF(AND(VLOOKUP($E32,武器奇术!$A:$R,15,FALSE)="武器",VLOOKUP($E32,武器奇术!$A:$R,17,FALSE)="裂石"),$E$3*(1+$E$15),0)) -> 0 | BK32: =(BJ32+BL32)/2 -> 0 | BL32: =IF(VLOOKUP($E32,武器奇术!$A:$R,18,FALSE)="极乐",0,MAX($C$9*IF($G$5="撼天",1.05,1)+IF(AND(VLOOKUP($E32,武器奇术!$A:$R,15,FALSE)="武器",VLOOKUP($E32,武器奇术!$A:$R,17,FALSE)="裂石"),$E$3*(1+$E$15),0),BJ32)) -> 0 | BM32: =IF(($D$9+IF(VLOOKUP($E32,武器奇术!$A:$R,17,FALSE)="裂石",$D$15,0)-VLOOKUP($F$7,目标属性!$A:$R,6,FALSE))>0,($D$9+IF(VLOOKUP($E32,武器奇术!$A:$R,17,FALSE)="裂石",$D$15,0)-VLOOKUP($F$7,目标属性!$A:$R,6,FALSE))/200,($D$9+IF(VLOOKUP($E32,武器奇术!$A:$R,17,FALSE)="裂石",$D$15,0)-VLOOKUP($F$7,目标属性!$A:$R,6,FALSE))/100) -> -0.24 | BN32: =$E$9 -> 0 | BO32: 1 | BP32: =BJ32*IF(VLOOKUP($E32,武器奇术!$A:$R,17,FALSE)="裂石",VLOOKUP($E32,武器奇术!$A:$R,4,FALSE),VLOOKUP($E32,武器奇术!$A:$R,2,FALSE))*(1+BM32)*(1+BN32)*BO32 -> 0 | BQ32: =(1-IF(VLOOKUP($E32,武器奇术!$A:$R,16,FALSE)="陌刀",1,$N32))*(1-$M32) -> 0 | BR32: =BK32*IF(VLOOKUP($E32,武器奇术!$A:$R,17,FALSE)="裂石",VLOOKUP($E32,武器奇术!$A:$R,4,FALSE),VLOOKUP($E32,武器奇术!$A:$R,2,FALSE))*(1+BM32)*(1+BN32)*BO32*(1+$E$16+VLOOKUP($E32,武器奇术!$A:$R,8,FALSE)) -> 0 | BS32: =IF($L32+$M32<=100%,$N32*$L32,$N32*(1-$M32)) -> 0.887 | BT32: =BL32*IF(VLOOKUP($E32,武器奇术!$A:$R,17,FALSE)="裂石",VLOOKUP($E32,武器奇术!$A:$R,4,FALSE),VLOOKUP($E32,武器奇术!$A:$R,2,FALSE))*(1+BM32)*(1+BN32)*BO32*(1+$E$17+VLOOKUP($E32,武器奇术!$A:$R,10,FALSE)) -> 0 | BU32: =$M32 -> 0.0986 | BV32: =BK32*IF(VLOOKUP($E32,武器奇术!$A:$R,17,FALSE)="裂石",VLOOKUP($E32,武器奇术!$A:$R,4,FALSE),VLOOKUP($E32,武器奇术!$A:$R,2,FALSE))*(1+BM32)*(1+BN32)*BO32 -> 0 | BW32: =MAX((1-BQ32-BS32-BU32),0) -> 0.0144 | BX32: =BP32*BQ32+BR32*BS32+BT32*BU32+BV32*BW32 -> 0 | BY32: =IF(VLOOKUP($E32,武器奇术!$A:$R,18,FALSE)="极乐",0,$B$11*IF($G$5="撼天",1.05,1)+IF(AND(VLOOKUP($E32,武器奇术!$A:$R,15,FALSE)="武器",VLOOKUP($E32,武器奇术!$A:$R,17,FALSE)="牵丝"),$E$3*(1+$E$15),0)) -> 0 | BZ32: =(BY32+CA32)/2 -> 0 | CA32: =IF(VLOOKUP($E32,武器奇术!$A:$R,18,FALSE)="极乐",0,MAX($C$11*IF($G$5="撼天",1.05,1)+IF(AND(VLOOKUP($E32,武器奇术!$A:$R,15,FALSE)="武器",VLOOKUP($E32,武器奇术!$A:$R,17,FALSE)="牵丝"),$E$3*(1+$E$15),0),BY32)) -> 0 | CB32: =IF(($D$11+IF(VLOOKUP($E32,武器奇术!$A:$R,17,FALSE)="牵丝",$D$15,0)-VLOOKUP($F$7,目标属性!$A:$R,6,FALSE))>0,($D$11+IF(VLOOKUP($E32,武器奇术!$A:$R,17,FALSE)="牵丝",$D$15,0)-VLOOKUP($F$7,目标属性!$A:$R,6,FALSE))/200,($D$11+IF(VLOOKUP($E32,武器奇术!$A:$R,17,FALSE)="牵丝",$D$15,0)-VLOOKUP($F$7,目标属性!$A:$R,6,FALSE))/100) -> -0.24 | CC32: =$E$11 -> 0 | CD32: 1 | CE32: =BY32*IF(VLOOKUP($E32,武器奇术!$A:$R,17,FALSE)="牵丝",VLOOKUP($E32,武器奇术!$A:$R,4,FALSE),VLOOKUP($E32,武器奇术!$A:$R,2,FALSE))*(1+CB32)*(1+CC32)*CD32 -> 0 | CF32: =(1-IF(VLOOKUP($E32,武器奇术!$A:$R,16,FALSE)="陌刀",1,$N32))*(1-$M32) -> 0 | CG32: =BZ32*IF(VLOOKUP($E32,武器奇术!$A:$R,17,FALSE)="牵丝",VLOOKUP($E32,武器奇术!$A:$R,4,FALSE),VLOOKUP($E32,武器奇术!$A:$R,2,FALSE))*(1+CB32)*(1+CC32)*CD32*(1+$E$16+VLOOKUP($E32,武器奇术!$A:$R,8,FALSE)) -> 0 | CH32: =IF($L32+$M32<=100%,$N32*$L32,$N32*(1-$M32)) -> 0.887 | CI32: =CA32*IF(VLOOKUP($E32,武器奇术!$A:$R,17,FALSE)="牵丝",VLOOKUP($E32,武器奇术!$A:$R,4,FALSE),VLOOKUP($E32,武器奇术!$A:$R,2,FALSE))*(1+CB32)*(1+CC32)*CD32*(1+$E$17+VLOOKUP($E32,武器奇术!$A:$R,10,FALSE)) -> 0 | CJ32: =$M32 -> 0.0986 | CK32: =BZ32*IF(VLOOKUP($E32,武器奇术!$A:$R,17,FALSE)="牵丝",VLOOKUP($E32,武器奇术!$A:$R,4,FALSE),VLOOKUP($E32,武器奇术!$A:$R,2,FALSE))*(1+CB32)*(1+CC32)*CD32 -> 0 | CL32: =MAX((1-CF32-CH32-CJ32),0) -> 0.0144 | CM32: =CE32*CF32+CG32*CH32+CI32*CJ32+CK32*CL32 -> 0 | CN32: =IF(VLOOKUP($E32,武器奇术!$A:$R,18,FALSE)="极乐",0,$B$13*IF($G$5="撼天",1.05,1)+IF(AND(VLOOKUP($E32,武器奇术!$A:$R,15,FALSE)="武器",VLOOKUP($E32,武器奇术!$A:$R,17,FALSE)="破竹"),$E$3*(1+$E$15),0)) -> 490.8 | CO32: =(CN32+CP32)/2 -> 856.3 | CP32: =IF(VLOOKUP($E32,武器奇术!$A:$R,18,FALSE)="极乐",0,MAX($C$13*IF($G$5="撼天",1.05,1)+IF(AND(VLOOKUP($E32,武器奇术!$A:$R,15,FALSE)="武器",VLOOKUP($E32,武器奇术!$A:$R,17,FALSE)="破竹"),$E$3*(1+$E$15),0),CN32)) -> 1221.8 | CQ32: =IF(($D$13+IF(VLOOKUP($E32,武器奇术!$A:$R,17,FALSE)="破竹",$D$15,0)-VLOOKUP($F$7,目标属性!$A:$R,6,FALSE)+IF(VLOOKUP($E32,武器奇术!$A:$V,22,FALSE)=1,4,0)+IF(VLOOKUP($E32,武器奇术!$A:$T,20,FALSE)=1,10,0))>0,($D$13+IF(VLOOKUP($E32,武器奇术!$A:$R,17,FALSE)="破竹",$D$15,0)-VLOOKUP($F$7,目标属性!$A:$R,6,FALSE)+IF(VLOOKUP($E32,武器奇术!$A:$V,22,FALSE)=1,4,0)+IF(VLOOKUP($E32,武器奇术!$A:$T,20,FALSE)=1,10,0))/200,($D$13+IF(VLOOKUP($E32,武器奇术!$A:$R,17,FALSE)="破竹",$D$15,0)-VLOOKUP($F$7,目标属性!$A:$R,6,FALSE)+IF(VLOOKUP($E32,武器奇术!$A:$V,22,FALSE)=1,4,0)+IF(VLOOKUP($E32,武器奇术!$A:$T,20,FALSE)=1,10,0))/100) -> 0.028 | CR32: =$E$13 -> 0.148 | CS32: 1 | CT32: =CN32*IF(VLOOKUP($E32,武器奇术!$A:$R,17,FALSE)="破竹",VLOOKUP($E32,武器奇术!$A:$R,4,FALSE),VLOOKUP($E32,武器奇术!$A:$R,2,FALSE))*(1+CQ32)*(1+CR32)*CS32 -> 1294.7186 | CU32: =(1-IF(VLOOKUP($E32,武器奇术!$A:$R,16,FALSE)="陌刀",1,$N32))*(1-$M32) -> 0 | CV32: =CO32*IF(VLOOKUP($E32,武器奇术!$A:$R,17,FALSE)="破竹",VLOOKUP($E32,武器奇术!$A:$R,4,FALSE),VLOOKUP($E32,武器奇术!$A:$R,2,FALSE))*(1+CQ32)*(1+CR32)*CS32*(1+$E$16+VLOOKUP($E32,武器奇术!$A:$R,8,FALSE)) -> 4843.0789 | CW32: =IF($L32+$M32<=100%,$N32*$L32,$N32*(1-$M32)) -> 0.887 | CX32: =CP32*IF(VLOOKUP($E32,武器奇术!$A:$R,17,FALSE)="破竹",VLOOKUP($E32,武器奇术!$A:$R,4,FALSE),VLOOKUP($E32,武器奇术!$A:$R,2,FALSE))*(1+CQ32)*(1+CR32)*CS32*(1+$E$17+VLOOKUP($E32,武器奇术!$A:$R,10,FALSE)) -> 4351.1566 | CY32: =$M32 -> 0.0986 | CZ32: =CO32*IF(VLOOKUP($E32,武器奇术!$A:$R,17,FALSE)="破竹",VLOOKUP($E32,武器奇术!$A:$R,4,FALSE),VLOOKUP($E32,武器奇术!$A:$R,2,FALSE))*(1+CQ32)*(1+CR32)*CS32 -> 2258.8987 | DA32: =MAX((1-CU32-CW32-CY32),0) -> 0.0144 | DB32: =CT32*CU32+CV32*CW32+CX32*CY32+CZ32*DA32 -> 4757.3632 | DC32: =IF(VLOOKUP($E32,武器奇术!$A:$R,18,FALSE)="极乐",0,$B$15) -> 66 | DD32: =(DC32+DE32)/2 -> 95.9 | DE32: =IF(VLOOKUP($E32,武器奇术!$A:$R,18,FALSE)="极乐",0,$C$15) -> 125.8 | DF32: =IF((IF(VLOOKUP($E32,武器奇术!$A:$R,17,FALSE)="鸣金",$D$7,0)+IF(VLOOKUP($E32,武器奇术!$A:$R,17,FALSE)="裂石",$D$9,0)+IF(VLOOKUP($E32,武器奇术!$A:$R,17,FALSE)="牵丝",$D$11,0)+IF(VLOOKUP($E32,武器奇术!$A:$R,17,FALSE)="破竹",$D$13,0)+$D$15-VLOOKUP($F$7,目标属性!$A:$R,6,FALSE)+IF(VLOOKUP($E32,武器奇术!$A:$V,22,FALSE)=1,4,0)+IF(VLOOKUP($E32,武器奇术!$A:$T,20,FALSE)=1,10,0))>0,(IF(VLOOKUP($E32,武器奇术!$A:$R,17,FALSE)="鸣金",$D$7,0)+IF(VLOOKUP($E32,武器奇术!$A:$R,17,FALSE)="裂石",$D$9,0)+IF(VLOOKUP($E32,武器奇术!$A:$R,17,FALSE)="牵丝",$D$11,0)+IF(VLOOKUP($E32,武器奇术!$A:$R,17,FALSE)="破竹",$D$13,0)+$D$15-VLOOKUP($F$7,目标属性!$A:$R,6,FALSE)+IF(VLOOKUP($E32,武器奇术!$A:$V,22,FALSE)=1,4,0)+IF(VLOOKUP($E32,武器奇术!$A:$T,20,FALSE)=1,10,0))/200,(IF(VLOOKUP($E32,武器奇术!$A:$R,17,FALSE)="鸣金",$D$7,0)+IF(VLOOKUP($E32,武器奇术!$A:$R,17,FALSE)="裂石",$D$9,0)+IF(VLOOKUP($E32,武器奇术!$A:$R,17,FALSE)="牵丝",$D$11,0)+IF(VLOOKUP($E32,武器奇术!$A:$R,17,FALSE)="破竹",$D$13,0)+$D$15-VLOOKUP($F$7,目标属性!$A:$R,6,FALSE)+IF(VLOOKUP($E32,武器奇术!$A:$V,22,FALSE)=1,4,0)+IF(VLOOKUP($E32,武器奇术!$A:$T,20,FALSE)=1,10,0))/100) -> 0.028 | DG32: =$E$13 -> 0.148 | DH32: 1 | DI32: =DC32*IF(VLOOKUP($E32,武器奇术!$A:$R,17,FALSE)="破竹",VLOOKUP($E32,武器奇术!$A:$R,4,FALSE),VLOOKUP($E32,武器奇术!$A:$R,2,FALSE))*(1+DF32)*(1+DG32)*DH32 -> 174.10641 | DJ32: =(1-IF(VLOOKUP($E32,武器奇术!$A:$R,16,FALSE)="陌刀",1,$N32))*(1-$M32) -> 0 | DK32: =DD32*IF(VLOOKUP($E32,武器奇术!$A:$R,17,FALSE)="破竹",VLOOKUP($E32,武器奇术!$A:$R,4,FALSE),VLOOKUP($E32,武器奇术!$A:$R,2,FALSE))*(1+DF32)*(1+DG32)*DH32*(1+$E$16+VLOOKUP($E32,武器奇术!$A:$R,8,FALSE)) -> 542.39317 | DL32: =IF($L32+$M32<=100%,$N32*$L32,$N32*(1-$M32)) -> 0.887 | DM32: =DE32*IF(VLOOKUP($E32,武器奇术!$A:$R,17,FALSE)="破竹",VLOOKUP($E32,武器奇术!$A:$R,4,FALSE),VLOOKUP($E32,武器奇术!$A:$R,2,FALSE))*(1+DF32)*(1+DG32)*DH32*(1+$E$17+VLOOKUP($E32,武器奇术!$A:$R,10,FALSE)) -> 448.00744 | DN32: =$M32 -> 0.0986 | DO32: =DD32*IF(VLOOKUP($E32,武器奇术!$A:$R,17,FALSE)="破竹",VLOOKUP($E32,武器奇术!$A:$R,4,FALSE),VLOOKUP($E32,武器奇术!$A:$R,2,FALSE))*(1+DF32)*(1+DG32)*DH32 -> 252.98189 | DP32: =MAX((1-DJ32-DL32-DN32),0) -> 0.0144 | DQ32: =DI32*DJ32+DK32*DL32+DM32*DN32+DO32*DP32 -> 528.91921
E33: 萧呤千浪(单次流星红人) | F33: 1 | H33: =IF(VLOOKUP($E33,武器奇术!$A:$R,18,FALSE)="天工",AE33,(AE33+AT33+BI33+BX33+CM33+DB33+DQ33))*(1+J33)*F33*K33*(1+G33) -> 25395.924 | I33: =H33/$C$30 -> 0.0032578582 | J33: =$F$3+VLOOKUP($E33,武器奇术!$A:$R,12,FALSE)+VLOOKUP($E33,武器奇术!$A:$R,14,FALSE)*$G$3+$P33+IF($F$21="√",5%,0) -> 0.473 | K33: =VLOOKUP($E33,武器奇术!$A:$R,11,FALSE) -> 1 | L33: =IF(VLOOKUP($E33,武器奇术!$A:$R,15,FALSE)="天工",0%,IF($C$17+VLOOKUP($E33,武器奇术!$A:$R,7,FALSE)>80%,80%,$C$17+VLOOKUP($E33,武器奇术!$A:$R,7,FALSE))+IF($C$19>20%,20%,$C$19)) -> 0.887 | M33: =IF(VLOOKUP($E33,武器奇术!$A:$R,15,FALSE)="天工",0%,IF($C$18+VLOOKUP($E33,武器奇术!$A:$R,9,FALSE)>40%,40%,$C$18+VLOOKUP($E33,武器奇术!$A:$R,9,FALSE))+IF($C$20>10%,10%,$C$20)) -> 0.0986 | N33: =IF(VLOOKUP($E33,武器奇术!$A:$R,15,FALSE)="天工",100%,MIN($C$16,1)) -> 1 | O33: =VLOOKUP($E33,武器奇术!$A:$R,16,FALSE) -> N/A | P33: =VLOOKUP($O33,$B$22:$C$27,2,FALSE)+IF(OR($O33="双刀",$O33="绳标"),$C$24,0) -> 0 | Q33: =$B$5*(1+VLOOKUP($E33,武器奇术!$A:$R,5,FALSE)+IF($G$5="飞隼",0.1,0)+IF($G$5="撼天",0.05,0))-$F$9*IF(VLOOKUP($E33,武器奇术!$A:$S,19,FALSE)=1,0.9,1)+IF($I$5="√",160,0) -> 2848.3 | R33: =(Q33+S33)/2 -> 2848.3 | S33: =MAX($C$5,$B$5)*(1+VLOOKUP($E33,武器奇术!$A:$R,5,FALSE)+IF($G$5="飞隼",0.1,0)+IF($G$5="撼天",0.05,0))-$F$9*IF(VLOOKUP($E33,武器奇术!$A:$S,19,FALSE)=1,0.9,1)+IF($I$5="√",320,0) -> 2848.3 | T33: =IF(($D$5+VLOOKUP($E33,武器奇术!$A:$R,13,FALSE)+IF($I$3="√",10,0)-VLOOKUP($F$7,目标属性!$A:$R,5,FALSE))>0,($D$5+VLOOKUP($E33,武器奇术!$A:$R,13,FALSE)+IF($I$3="√",10,0)-VLOOKUP($F$7,目标属性!$A:$R,5,FALSE))/200,($D$5+VLOOKUP($E33,武器奇术!$A:$R,13,FALSE)+IF($I$3="√",10,0)-VLOOKUP($F$7,目标属性!$A:$R,5,FALSE))/100) -> 0.2675 | U33: =$E$5+IF(VLOOKUP($E33,武器奇术!$A:$R,18,FALSE)="鼠鼠",0.24,0) -> 0 | V33: 1 | W33: =Q33*VLOOKUP($E33,武器奇术!$A:$R,2,FALSE)*(1+T33)*(1+U33)*V33 -> 5379.9502 | X33: =(1-IF(VLOOKUP($E33,武器奇术!$A:$R,16,FALSE)="陌刀",1,$N33))*(1-$M33) -> 0 | Y33: =R33*VLOOKUP($E33,武器奇术!$A:$R,2,FALSE)*(1+T33)*(1+U33)*V33*(1+$E$16+VLOOKUP($E33,武器奇术!$A:$R,8,FALSE)) -> 11534.613 | Z33: =IF($L33+$M33<=100%,$N33*$L33,$N33*(1-$M33)) -> 0.887 | AA33: =S33*VLOOKUP($E33,武器奇术!$A:$R,2,FALSE)*(1+T33)*(1+U33)*V33*(1+$E$17+VLOOKUP($E33,武器奇术!$A:$R,10,FALSE)) -> 7262.9328 | AB33: =$M33 -> 0.0986 | AC33: =R33*VLOOKUP($E33,武器奇术!$A:$R,2,FALSE)*(1+T33)*(1+U33)*V33 -> 5379.9502 | AD33: =MAX((1-X33-Z33-AB33),0) -> 0.0144 | AE33: =W33*X33+Y33*Z33+AA33*AB33+AC33*AD33 -> 11024.798 | AF33: =VLOOKUP($E33,武器奇术!$A:$R,3,FALSE)*(1+IF(VLOOKUP($E33,武器奇术!$A:$R,15,FALSE)="武器",$E$15,0)) -> 358 | AG33: =(AF33+AH33)/2 -> 358 | AH33: =VLOOKUP($E33,武器奇术!$A:$R,3,FALSE)*(1+IF(VLOOKUP($E33,武器奇术!$A:$R,15,FALSE)="武器",$E$15,0)) -> 358 | AI33: =IF(($D$5+VLOOKUP($E33,武器奇术!$A:$R,13,FALSE)+IF($I$3="√",10,0)-VLOOKUP($F$7,目标属性!$A:$R,5,FALSE))>0,($D$5+VLOOKUP($E33,武器奇术!$A:$R,13,FALSE)+IF($I$3="√",10,0)-VLOOKUP($F$7,目标属性!$A:$R,5,FALSE))/200,($D$5+VLOOKUP($E33,武器奇术!$A:$R,13,FALSE)+IF($I$3="√",10,0)-VLOOKUP($F$7,目标属性!$A:$R,5,FALSE))/100) -> 0.2675 | AJ33: =$E$5+IF(VLOOKUP($E33,武器奇术!$A:$R,18,FALSE)="鼠鼠",0.24,0) -> 0 | AK33: 1 | AL33: =AF33*(1+AI33)*(1+AJ33)*AK33 -> 453.765 | AM33: =(1-IF(VLOOKUP($E33,武器奇术!$A:$R,16,FALSE)="陌刀",1,$N33))*(1-$M33) -> 0 | AN33: =AG33*(1+AI33)*(1+AJ33)*AK33*(1+$E$16+VLOOKUP($E33,武器奇术!$A:$R,8,FALSE)) -> 972.87216 | AO33: =IF($L33+$M33<=100%,$N33*$L33,$N33*(1-$M33)) -> 0.887 | AP33: =AH33*(1+AI33)*(1+AJ33)*AK33*(1+$E$17+VLOOKUP($E33,武器奇术!$A:$R,10,FALSE)) -> 612.58275 | AQ33: =$M33 -> 0.0986 | AR33: =AG33*(1+AI33)*(1+AJ33)*AK33 -> 453.765 | AS33: =MAX((1-AM33-AO33-AQ33),0) -> 0.0144 | AT33: =AL33*AM33+AN33*AO33+AP33*AQ33+AR33*AS33 -> 929.87248 | AU33: =IF(VLOOKUP($E33,武器奇术!$A:$R,18,FALSE)="极乐",0,$B$7*IF($G$5="撼天",1.05,1)+IF(AND(VLOOKUP($E33,武器奇术!$A:$R,15,FALSE)="武器",VLOOKUP($E33,武器奇术!$A:$R,17,FALSE)="鸣金"),$E$3*(1+$E$15),0)) -> 0 | AV33: =(AU33+AW33)/2 -> 0 | AW33: =IF(VLOOKUP($E33,武器奇术!$A:$R,18,FALSE)="极乐",0,MAX($C$7*IF($G$5="撼天",1.05,1)+IF(AND(VLOOKUP($E33,武器奇术!$A:$R,15,FALSE)="武器",VLOOKUP($E33,武器奇术!$A:$R,17,FALSE)="鸣金"),$E$3*(1+$E$15),0),AU33)) -> 0 | AX33: =IF(($D$7+IF(VLOOKUP($E33,武器奇术!$A:$R,17,FALSE)="鸣金",$D$15,0)-VLOOKUP($F$7,目标属性!$A:$R,6,FALSE))>0,($D$7+IF(VLOOKUP($E33,武器奇术!$A:$R,17,FALSE)="鸣金",$D$15,0)-VLOOKUP($F$7,目标属性!$A:$R,6,FALSE))/200,($D$7+IF(VLOOKUP($E33,武器奇术!$A:$R,17,FALSE)="鸣金",$D$15,0)-VLOOKUP($F$7,目标属性!$A:$R,6,FALSE))/100) -> -0.24 | AY33: =$E$7 -> 0 | AZ33: 1 | BA33: =AU33*IF(VLOOKUP($E33,武器奇术!$A:$R,17,FALSE)="鸣金",VLOOKUP($E33,武器奇术!$A:$R,4,FALSE),VLOOKUP($E33,武器奇术!$A:$R,2,FALSE))*(1+AX33)*(1+AY33)*AZ33 -> 0 | BB33: =(1-IF(VLOOKUP($E33,武器奇术!$A:$R,16,FALSE)="陌刀",1,$N33))*(1-$M33) -> 0 | BC33: =AV33*IF(VLOOKUP($E33,武器奇术!$A:$R,17,FALSE)="鸣金",VLOOKUP($E33,武器奇术!$A:$R,4,FALSE),VLOOKUP($E33,武器奇术!$A:$R,2,FALSE))*(1+AX33)*(1+AY33)*AZ33*(1+$E$16+VLOOKUP($E33,武器奇术!$A:$R,8,FALSE)) -> 0 | BD33: =IF($L33+$M33<=100%,$N33*$L33,$N33*(1-$M33)) -> 0.887 | BE33: =AW33*IF(VLOOKUP($E33,武器奇术!$A:$R,17,FALSE)="鸣金",VLOOKUP($E33,武器奇术!$A:$R,4,FALSE),VLOOKUP($E33,武器奇术!$A:$R,2,FALSE))*(1+AX33)*(1+AY33)*AZ33*(1+$E$17+VLOOKUP($E33,武器奇术!$A:$R,10,FALSE)) -> 0 | BF33: =$M33 -> 0.0986 | BG33: =AV33*IF(VLOOKUP($E33,武器奇术!$A:$R,17,FALSE)="鸣金",VLOOKUP($E33,武器奇术!$A:$R,4,FALSE),VLOOKUP($E33,武器奇术!$A:$R,2,FALSE))*(1+AX33)*(1+AY33)*AZ33 -> 0 | BH33: =MAX((1-BB33-BD33-BF33),0) -> 0.0144 | BI33: =BA33*BB33+BC33*BD33+BE33*BF33+BG33*BH33 -> 0 | BJ33: =IF(VLOOKUP($E33,武器奇术!$A:$R,18,FALSE)="极乐",0,$B$9*IF($G$5="撼天",1.05,1)+IF(AND(VLOOKUP($E33,武器奇术!$A:$R,15,FALSE)="武器",VLOOKUP($E33,武器奇术!$A:$R,17,FALSE)="裂石"),$E$3*(1+$E$15),0)) -> 0 | BK33: =(BJ33+BL33)/2 -> 0 | BL33: =IF(VLOOKUP($E33,武器奇术!$A:$R,18,FALSE)="极乐",0,MAX($C$9*IF($G$5="撼天",1.05,1)+IF(AND(VLOOKUP($E33,武器奇术!$A:$R,15,FALSE)="武器",VLOOKUP($E33,武器奇术!$A:$R,17,FALSE)="裂石"),$E$3*(1+$E$15),0),BJ33)) -> 0 | BM33: =IF(($D$9+IF(VLOOKUP($E33,武器奇术!$A:$R,17,FALSE)="裂石",$D$15,0)-VLOOKUP($F$7,目标属性!$A:$R,6,FALSE))>0,($D$9+IF(VLOOKUP($E33,武器奇术!$A:$R,17,FALSE)="裂石",$D$15,0)-VLOOKUP($F$7,目标属性!$A:$R,6,FALSE))/200,($D$9+IF(VLOOKUP($E33,武器奇术!$A:$R,17,FALSE)="裂石",$D$15,0)-VLOOKUP($F$7,目标属性!$A:$R,6,FALSE))/100) -> -0.24 | BN33: =$E$9 -> 0 | BO33: 1 | BP33: =BJ33*IF(VLOOKUP($E33,武器奇术!$A:$R,17,FALSE)="裂石",VLOOKUP($E33,武器奇术!$A:$R,4,FALSE),VLOOKUP($E33,武器奇术!$A:$R,2,FALSE))*(1+BM33)*(1+BN33)*BO33 -> 0 | BQ33: =(1-IF(VLOOKUP($E33,武器奇术!$A:$R,16,FALSE)="陌刀",1,$N33))*(1-$M33) -> 0 | BR33: =BK33*IF(VLOOKUP($E33,武器奇术!$A:$R,17,FALSE)="裂石",VLOOKUP($E33,武器奇术!$A:$R,4,FALSE),VLOOKUP($E33,武器奇术!$A:$R,2,FALSE))*(1+BM33)*(1+BN33)*BO33*(1+$E$16+VLOOKUP($E33,武器奇术!$A:$R,8,FALSE)) -> 0 | BS33: =IF($L33+$M33<=100%,$N33*$L33,$N33*(1-$M33)) -> 0.887 | BT33: =BL33*IF(VLOOKUP($E33,武器奇术!$A:$R,17,FALSE)="裂石",VLOOKUP($E33,武器奇术!$A:$R,4,FALSE),VLOOKUP($E33,武器奇术!$A:$R,2,FALSE))*(1+BM33)*(1+BN33)*BO33*(1+$E$17+VLOOKUP($E33,武器奇术!$A:$R,10,FALSE)) -> 0 | BU33: =$M33 -> 0.0986 | BV33: =BK33*IF(VLOOKUP($E33,武器奇术!$A:$R,17,FALSE)="裂石",VLOOKUP($E33,武器奇术!$A:$R,4,FALSE),VLOOKUP($E33,武器奇术!$A:$R,2,FALSE))*(1+BM33)*(1+BN33)*BO33 -> 0 | BW33: =MAX((1-BQ33-BS33-BU33),0) -> 0.0144 | BX33: =BP33*BQ33+BR33*BS33+BT33*BU33+BV33*BW33 -> 0 | BY33: =IF(VLOOKUP($E33,武器奇术!$A:$R,18,FALSE)="极乐",0,$B$11*IF($G$5="撼天",1.05,1)+IF(AND(VLOOKUP($E33,武器奇术!$A:$R,15,FALSE)="武器",VLOOKUP($E33,武器奇术!$A:$R,17,FALSE)="牵丝"),$E$3*(1+$E$15),0)) -> 0 | BZ33: =(BY33+CA33)/2 -> 0 | CA33: =IF(VLOOKUP($E33,武器奇术!$A:$R,18,FALSE)="极乐",0,MAX($C$11*IF($G$5="撼天",1.05,1)+IF(AND(VLOOKUP($E33,武器奇术!$A:$R,15,FALSE)="武器",VLOOKUP($E33,武器奇术!$A:$R,17,FALSE)="牵丝"),$E$3*(1+$E$15),0),BY33)) -> 0 | CB33: =IF(($D$11+IF(VLOOKUP($E33,武器奇术!$A:$R,17,FALSE)="牵丝",$D$15,0)-VLOOKUP($F$7,目标属性!$A:$R,6,FALSE))>0,($D$11+IF(VLOOKUP($E33,武器奇术!$A:$R,17,FALSE)="牵丝",$D$15,0)-VLOOKUP($F$7,目标属性!$A:$R,6,FALSE))/200,($D$11+IF(VLOOKUP($E33,武器奇术!$A:$R,17,FALSE)="牵丝",$D$15,0)-VLOOKUP($F$7,目标属性!$A:$R,6,FALSE))/100) -> -0.24 | CC33: =$E$11 -> 0 | CD33: 1 | CE33: =BY33*IF(VLOOKUP($E33,武器奇术!$A:$R,17,FALSE)="牵丝",VLOOKUP($E33,武器奇术!$A:$R,4,FALSE),VLOOKUP($E33,武器奇术!$A:$R,2,FALSE))*(1+CB33)*(1+CC33)*CD33 -> 0 | CF33: =(1-IF(VLOOKUP($E33,武器奇术!$A:$R,16,FALSE)="陌刀",1,$N33))*(1-$M33) -> 0 | CG33: =BZ33*IF(VLOOKUP($E33,武器奇术!$A:$R,17,FALSE)="牵丝",VLOOKUP($E33,武器奇术!$A:$R,4,FALSE),VLOOKUP($E33,武器奇术!$A:$R,2,FALSE))*(1+CB33)*(1+CC33)*CD33*(1+$E$16+VLOOKUP($E33,武器奇术!$A:$R,8,FALSE)) -> 0 | CH33: =IF($L33+$M33<=100%,$N33*$L33,$N33*(1-$M33)) -> 0.887 | CI33: =CA33*IF(VLOOKUP($E33,武器奇术!$A:$R,17,FALSE)="牵丝",VLOOKUP($E33,武器奇术!$A:$R,4,FALSE),VLOOKUP($E33,武器奇术!$A:$R,2,FALSE))*(1+CB33)*(1+CC33)*CD33*(1+$E$17+VLOOKUP($E33,武器奇术!$A:$R,10,FALSE)) -> 0 | CJ33: =$M33 -> 0.0986 | CK33: =BZ33*IF(VLOOKUP($E33,武器奇术!$A:$R,17,FALSE)="牵丝",VLOOKUP($E33,武器奇术!$A:$R,4,FALSE),VLOOKUP($E33,武器奇术!$A:$R,2,FALSE))*(1+CB33)*(1+CC33)*CD33 -> 0 | CL33: =MAX((1-CF33-CH33-CJ33),0) -> 0.0144 | CM33: =CE33*CF33+CG33*CH33+CI33*CJ33+CK33*CL33 -> 0 | CN33: =IF(VLOOKUP($E33,武器奇术!$A:$R,18,FALSE)="极乐",0,$B$13*IF($G$5="撼天",1.05,1)+IF(AND(VLOOKUP($E33,武器奇术!$A:$R,15,FALSE)="武器",VLOOKUP($E33,武器奇术!$A:$R,17,FALSE)="破竹"),$E$3*(1+$E$15),0)) -> 490.8 | CO33: =(CN33+CP33)/2 -> 856.3 | CP33: =IF(VLOOKUP($E33,武器奇术!$A:$R,18,FALSE)="极乐",0,MAX($C$13*IF($G$5="撼天",1.05,1)+IF(AND(VLOOKUP($E33,武器奇术!$A:$R,15,FALSE)="武器",VLOOKUP($E33,武器奇术!$A:$R,17,FALSE)="破竹"),$E$3*(1+$E$15),0),CN33)) -> 1221.8 | CQ33: =IF(($D$13+IF(VLOOKUP($E33,武器奇术!$A:$R,17,FALSE)="破竹",$D$15,0)-VLOOKUP($F$7,目标属性!$A:$R,6,FALSE)+IF(VLOOKUP($E33,武器奇术!$A:$V,22,FALSE)=1,4,0)+IF(VLOOKUP($E33,武器奇术!$A:$T,20,FALSE)=1,10,0))>0,($D$13+IF(VLOOKUP($E33,武器奇术!$A:$R,17,FALSE)="破竹",$D$15,0)-VLOOKUP($F$7,目标属性!$A:$R,6,FALSE)+IF(VLOOKUP($E33,武器奇术!$A:$V,22,FALSE)=1,4,0)+IF(VLOOKUP($E33,武器奇术!$A:$T,20,FALSE)=1,10,0))/200,($D$13+IF(VLOOKUP($E33,武器奇术!$A:$R,17,FALSE)="破竹",$D$15,0)-VLOOKUP($F$7,目标属性!$A:$R,6,FALSE)+IF(VLOOKUP($E33,武器奇术!$A:$V,22,FALSE)=1,4,0)+IF(VLOOKUP($E33,武器奇术!$A:$T,20,FALSE)=1,10,0))/100) -> 0.028 | CR33: =$E$13 -> 0.148 | CS33: 1 | CT33: =CN33*IF(VLOOKUP($E33,武器奇术!$A:$R,17,FALSE)="破竹",VLOOKUP($E33,武器奇术!$A:$R,4,FALSE),VLOOKUP($E33,武器奇术!$A:$R,2,FALSE))*(1+CQ33)*(1+CR33)*CS33 -> 1294.7186 | CU33: =(1-IF(VLOOKUP($E33,武器奇术!$A:$R,16,FALSE)="陌刀",1,$N33))*(1-$M33) -> 0 | CV33: =CO33*IF(VLOOKUP($E33,武器奇术!$A:$R,17,FALSE)="破竹",VLOOKUP($E33,武器奇术!$A:$R,4,FALSE),VLOOKUP($E33,武器奇术!$A:$R,2,FALSE))*(1+CQ33)*(1+CR33)*CS33*(1+$E$16+VLOOKUP($E33,武器奇术!$A:$R,8,FALSE)) -> 4843.0789 | CW33: =IF($L33+$M33<=100%,$N33*$L33,$N33*(1-$M33)) -> 0.887 | CX33: =CP33*IF(VLOOKUP($E33,武器奇术!$A:$R,17,FALSE)="破竹",VLOOKUP($E33,武器奇术!$A:$R,4,FALSE),VLOOKUP($E33,武器奇术!$A:$R,2,FALSE))*(1+CQ33)*(1+CR33)*CS33*(1+$E$17+VLOOKUP($E33,武器奇术!$A:$R,10,FALSE)) -> 4351.1566 | CY33: =$M33 -> 0.0986 | CZ33: =CO33*IF(VLOOKUP($E33,武器奇术!$A:$R,17,FALSE)="破竹",VLOOKUP($E33,武器奇术!$A:$R,4,FALSE),VLOOKUP($E33,武器奇术!$A:$R,2,FALSE))*(1+CQ33)*(1+CR33)*CS33 -> 2258.8987 | DA33: =MAX((1-CU33-CW33-CY33),0) -> 0.0144 | DB33: =CT33*CU33+CV33*CW33+CX33*CY33+CZ33*DA33 -> 4757.3632 | DC33: =IF(VLOOKUP($E33,武器奇术!$A:$R,18,FALSE)="极乐",0,$B$15) -> 66 | DD33: =(DC33+DE33)/2 -> 95.9 | DE33: =IF(VLOOKUP($E33,武器奇术!$A:$R,18,FALSE)="极乐",0,$C$15) -> 125.8 | DF33: =IF((IF(VLOOKUP($E33,武器奇术!$A:$R,17,FALSE)="鸣金",$D$7,0)+IF(VLOOKUP($E33,武器奇术!$A:$R,17,FALSE)="裂石",$D$9,0)+IF(VLOOKUP($E33,武器奇术!$A:$R,17,FALSE)="牵丝",$D$11,0)+IF(VLOOKUP($E33,武器奇术!$A:$R,17,FALSE)="破竹",$D$13,0)+$D$15-VLOOKUP($F$7,目标属性!$A:$R,6,FALSE)+IF(VLOOKUP($E33,武器奇术!$A:$V,22,FALSE)=1,4,0)+IF(VLOOKUP($E33,武器奇术!$A:$T,20,FALSE)=1,10,0))>0,(IF(VLOOKUP($E33,武器奇术!$A:$R,17,FALSE)="鸣金",$D$7,0)+IF(VLOOKUP($E33,武器奇术!$A:$R,17,FALSE)="裂石",$D$9,0)+IF(VLOOKUP($E33,武器奇术!$A:$R,17,FALSE)="牵丝",$D$11,0)+IF(VLOOKUP($E33,武器奇术!$A:$R,17,FALSE)="破竹",$D$13,0)+$D$15-VLOOKUP($F$7,目标属性!$A:$R,6,FALSE)+IF(VLOOKUP($E33,武器奇术!$A:$V,22,FALSE)=1,4,0)+IF(VLOOKUP($E33,武器奇术!$A:$T,20,FALSE)=1,10,0))/200,(IF(VLOOKUP($E33,武器奇术!$A:$R,17,FALSE)="鸣金",$D$7,0)+IF(VLOOKUP($E33,武器奇术!$A:$R,17,FALSE)="裂石",$D$9,0)+IF(VLOOKUP($E33,武器奇术!$A:$R,17,FALSE)="牵丝",$D$11,0)+IF(VLOOKUP($E33,武器奇术!$A:$R,17,FALSE)="破竹",$D$13,0)+$D$15-VLOOKUP($F$7,目标属性!$A:$R,6,FALSE)+IF(VLOOKUP($E33,武器奇术!$A:$V,22,FALSE)=1,4,0)+IF(VLOOKUP($E33,武器奇术!$A:$T,20,FALSE)=1,10,0))/100) -> 0.028 | DG33: =$E$13 -> 0.148 | DH33: 1 | DI33: =DC33*IF(VLOOKUP($E33,武器奇术!$A:$R,17,FALSE)="破竹",VLOOKUP($E33,武器奇术!$A:$R,4,FALSE),VLOOKUP($E33,武器奇术!$A:$R,2,FALSE))*(1+DF33)*(1+DG33)*DH33 -> 174.10641 | DJ33: =(1-IF(VLOOKUP($E33,武器奇术!$A:$R,16,FALSE)="陌刀",1,$N33))*(1-$M33) -> 0 | DK33: =DD33*IF(VLOOKUP($E33,武器奇术!$A:$R,17,FALSE)="破竹",VLOOKUP($E33,武器奇术!$A:$R,4,FALSE),VLOOKUP($E33,武器奇术!$A:$R,2,FALSE))*(1+DF33)*(1+DG33)*DH33*(1+$E$16+VLOOKUP($E33,武器奇术!$A:$R,8,FALSE)) -> 542.39317 | DL33: =IF($L33+$M33<=100%,$N33*$L33,$N33*(1-$M33)) -> 0.887 | DM33: =DE33*IF(VLOOKUP($E33,武器奇术!$A:$R,17,FALSE)="破竹",VLOOKUP($E33,武器奇术!$A:$R,4,FALSE),VLOOKUP($E33,武器奇术!$A:$R,2,FALSE))*(1+DF33)*(1+DG33)*DH33*(1+$E$17+VLOOKUP($E33,武器奇术!$A:$R,10,FALSE)) -> 448.00744 | DN33: =$M33 -> 0.0986 | DO33: =DD33*IF(VLOOKUP($E33,武器奇术!$A:$R,17,FALSE)="破竹",VLOOKUP($E33,武器奇术!$A:$R,4,FALSE),VLOOKUP($E33,武器奇术!$A:$R,2,FALSE))*(1+DF33)*(1+DG33)*DH33 -> 252.98189 | DP33: =MAX((1-DJ33-DL33-DN33),0) -> 0.0144 | DQ33: =DI33*DJ33+DK33*DL33+DM33*DN33+DO33*DP33 -> 528.91921
