Workbook

Sheet 期望
B1: 最小攻击 | C1: 最大攻击 | D1: 穿透 | E1: 伤害加成 | F1: 武学属性 | G1: 裂石 | H1: 怪物属性 | K1: 期望 | L1: 会心期望 | M1: 会意期望 | N1: 普通期望 | O1: 擦伤期望 | P1: 次数 | Q1: 技能 | R1: 增益1 | S1: 增益2 | T1: 增益3 | U1: 增益4 | V1: 增益5 | W1: 增益6 | X1: 增益7 | Y1: 增益8 | Z1: 增益9 | AA1: 增益10 | AB1: 增益11 | AC1: 增益12 | AD1: 增益13 | AE1: 增益14 | AF1: 增益15 | AG1: 类型 | AH1: 外功倍率 | AI1: 外攻固伤 | AJ1: 属性倍率 | AK1: 属性固伤 | AL1: 通用增伤 | AM1: 外攻加成 | AN1: 即时小外 | AO1: 即时大外 | AP1: 外穿加成 | AQ1: 外伤加成 | AR1: 属攻加成 | AS1: 即时小鸣 | AT1: 即时大鸣 | AU1: 鸣金穿透 | AV1: 鸣金加成 | AW1: 即时小裂 | AX1: 即时大裂 | AY1: 裂石穿透 | AZ1: 裂石加成 | BA1: 即时小牵 | BB1: 即时大牵 | BC1: 牵丝穿透 | BD1: 牵丝加成 | BE1: 即时小破 | BF1: 即时大破 | BG1: 破竹穿透 | BH1: 破竹加成 | BI1: 生效精准 | BJ1: 生效会心 | BK1: 生效会心伤害 | BL1: 生效会意 | BM1: 生效会意伤害 | BN1: 会心占比 | BO1: 普攻占比 | BP1: 擦伤占比 | BQ1: 特殊增伤
A2: 外功 | B2: 3417.8 | C2: 2547.3 | D2: =58.4+IF($C$21="征人归",5.1,0) -> 58.4 | F2: 套装 | G2: 断岳 | H2: 防御 | I2: =559*IF(D17="√",0.94,1) -> 525.46 | K2: =($L2*$BN2+$M2*$BL2+$N2*$BO2+$O2*$BP2) -> 22941.82 | L2: =((($AN2+$AO2)/2*$AH2+$AI2)*(1+$AP2)*(1+$AQ2)+(($AS2+$AT2)/2*IF($G$1="鸣金",$AJ2,$AH2)+IF($G$1="鸣金",$AK2*1.5,0))*(1+$AU2)*(1+$AV2)+(($AW2+$AX2)/2*IF($G$1="裂石",$AJ2,$AH2)+IF($G$1="裂石",$AK2*1.5,0))*(1+$AY2)*(1+$AZ2)+(($BA2+$BB2)/2*IF($G$1="牵丝",$AJ2,$AH2)+IF($G$1="牵丝",$AK2*1.5,0))*(1+$BC2)*(1+$BD2)+(($BE2+$BF2)/2*IF($G$1="破竹",$AJ2,$AH2)+IF($G$1="破竹",$AK2*1.5,0))*(1+$BG2)*(1+$BH2))*(1+$AL2)*$BK2*$P2*(1+IF(VLOOKUP($Q2,武学奇术!$A:$ZZ,30,FALSE)="蓄力技",$B$21,0))*(1+$BQ2) -> 25119.625 | M2: =(($AO2*$AH2+$AI2)*(1+$AP2)*(1+$AQ2)+($AT2*IF($G$1="鸣金",$AJ2,$AH2)+IF($G$1="鸣金",$AK2*1.5,0))*(1+$AU2)*(1+$AV2)+($AX2*IF($G$1="裂石",$AJ2,$AH2)+IF($G$1="裂石",$AK2*1.5,0))*(1+$AY2)*(1+$AZ2)+($BB2*IF($G$1="牵丝",$AJ2,$AH2)+IF($G$1="牵丝",$AK2*1.5,0))*(1+$BC2)*(1+$BD2)+($BF2*IF($G$1="破竹",$AJ2,$AH2)+IF($G$1="破竹",$AK2*1.5,0))*(1+$BG2)*(1+$BH2))*(1+$AL2)*$BM2*$P2*(1+IF(VLOOKUP($Q2,武学奇术!$A:$ZZ,30,FALSE)="蓄力技",$B$21,0))*(1+$BQ2) -> 21716.426 | N2: =((($AN2+$AO2)/2*$AH2+$AI2)*(1+$AP2)*(1+$AQ2)+(($AS2+$AT2)/2*IF($G$1="鸣金",$AJ2,$AH2)+IF($G$1="鸣金",$AK2*1.5,0))*(1+$AU2)*(1+$AV2)+(($AW2+$AX2)/2*IF($G$1="裂石",$AJ2,$AH2)+IF($G$1="裂石",$AK2*1.5,0))*(1+$AY2)*(1+$AZ2)+(($BA2+$BB2)/2*IF($G$1="牵丝",$AJ2,$AH2)+IF($G$1="牵丝",$AK2*1.5,0))*(1+$BC2)*(1+$BD2)+(($BE2+$BF2)/2*IF($G$1="破竹",$AJ2,$AH2)+IF($G$1="破竹",$AK2*1.5,0))*(1+$BG2)*(1+$BH2))*(1+$AL2)*$P2*(1+IF(VLOOKUP($Q2,武学奇术!$A:$ZZ,30,FALSE)="蓄力技",$B$21,0))*(1+$BQ2) -> 14354.072 | O2: =((($AN2*$AH2+$AI2)*(1+$AP2)*(1+$AQ2)+($AS2*IF($G$1="鸣金",$AJ2,$AH2)+IF($G$1="鸣金",$AK2*1.5,0))*(1+$AU2)*(1+$AV2)+($AW2*IF($G$1="裂石",$AJ2,$AH2)+IF($G$1="裂石",$AK2*1.5,0))*(1+$AY2)*(1+$AZ2)+($BA2*IF($G$1="牵丝",$AJ2,$AH2)+IF($G$1="牵丝",$AK2*1.5,0))*(1+$BC2)*(1+$BD2)+($BE2*IF($G$1="破竹",$AJ2,$AH2)+IF($G$1="破竹",$AK2*1.5,0))*(1+$BG2)*(1+$BH2))*(1+$AL2))*$P2*(1+IF(VLOOKUP($Q2,武学奇术!$A:$ZZ,30,FALSE)="蓄力技",$B$21,0))*(1+$BQ2) -> 12621.902 | P2: 1 | Q2: 萧呤千浪流星 | R2: 易水歌1层 | S2: N/a | T2: N/a | U2: N/a | V2: N/a | W2: 近战笛 | X2: N/a | Y2: N/a | Z2: N/a | AA2: N/a | AB2: N/a | AC2: N/a | AD2: N/a | AE2: N/a | AF2: 铁衣 | AG2: =VLOOKUP($Q2,武学奇术!$A:$ZZ,25,FALSE) -> 群体奇术 | AH2: =VLOOKUP($Q2,武学奇术!$A:$ZZ,26,FALSE) -> 1.4902 | AI2: =VLOOKUP($Q2,武学奇术!$A:$ZZ,27,FALSE)*(1+IF(OR($AG2=$F$4,$AG2=$F$5),$B$22,0)) -> 358 | AJ2: =VLOOKUP($Q2,武学奇术!$A:$ZZ,28,FALSE) -> 2.2353 | AK2: =VLOOKUP($Q2,武学奇术!$A:$ZZ,29,FALSE)*(1+IF(OR($AG2=$F$4,$AG2=$F$5),$B$22,0)) -> 0 | AL2: {=$G$3+VLOOKUP($AG2,$F$4:$G$7,2,FALSE)+VLOOKUP($Q2,武学奇术!$A:$ZZ,2,FALSE)+SUM(_xlfn.XLOOKUP($R2:$AF2,增益!$A:$A,增益!$B:$B,0))} -> 0.493 | AM2: {=VLOOKUP($Q2,武学奇术!$A:$ZZ,5,FALSE)+SUM(_xlfn.XLOOKUP($R2:$AF2,增益!$A:$A,增益!$E:$E,0))} -> 0 | AN2: {=$D$10*(1+$AM2)+VLOOKUP($Q2,武学奇术!$A:$ZZ,3,FALSE)+SUM(_xlfn.XLOOKUP($R2:$AF2,增益!$A:$A,增益!$C:$C,0))-$I$2} -> 3052.34 | AO2: {=$E$10*(1+$AM2)+VLOOKUP($Q2,武学奇术!$A:$ZZ,4,FALSE)+SUM(_xlfn.XLOOKUP($R2:$AF2,增益!$A:$A,增益!$D:$D,0))-$I$2} -> 3052.34 | AP2: {=IF($F$10-$I$3+VLOOKUP($Q2,武学奇术!$A:$ZZ,6,FALSE)+SUM(_xlfn.XLOOKUP(R2:AF2,增益!$A:$A,增益!$F:$F,0))>0,($F$10-$I$3+VLOOKUP($Q2,武学奇术!$A:$ZZ,6,FALSE)+SUM(_xlfn.XLOOKUP(R2:AF2,增益!$A:$A,增益!$F:$F,0)))/200,($F$10-$I$3+VLOOKUP($Q2,武学奇术!$A:$ZZ,6,FALSE)+SUM(_xlfn.XLOOKUP(R2:AF2,增益!$A:$A,增益!$F:$F,0)))/100)} -> 0.352 | AQ2: {=$G$10+VLOOKUP($Q2,武学奇术!$A:$ZZ,7,FALSE)+SUM(_xlfn.XLOOKUP(R2:AF2,增益!$A:$A,增益!$G:$G,0))} -> 0 | AR2: {=VLOOKUP($Q2,武学奇术!$A:$ZZ,8,FALSE)+SUM(_xlfn.XLOOKUP(R2:AF2,增益!$A:$A,增益!$H:$H,0))} -> 0 | AS2: =$D$11*(1+$AR2) -> 0 | AT2: =$E$11*(1+$AR2) -> 0 | AU2: {=IF($F$11-$I$4+VLOOKUP($Q2,武学奇术!$A:$ZZ,9,FALSE)+SUM(_xlfn.XLOOKUP(R2:AF2,增益!$A:$A,增益!$I:$I,0))>0,($F$11-$I$4+VLOOKUP($Q2,武学奇术!$A:$ZZ,9,FALSE)+SUM(_xlfn.XLOOKUP(R2:AF2,增益!$A:$A,增益!$I:$I,0)))/200,($F$11-$I$4+VLOOKUP($Q2,武学奇术!$A:$ZZ,9,FALSE)+SUM(_xlfn.XLOOKUP(R2:AF2,增益!$A:$A,增益!$I:$I,0)))/100)} -> -0.24 | AV2: {=$G$11+VLOOKUP($Q2,武学奇术!$A:$ZZ,10,FALSE)+SUM(_xlfn.XLOOKUP(R2:AF2,增益!$A:$A,增益!$J:$J,0))} -> 0 | AW2: =$D$12*(1+$AR2) -> 634.5 | AX2: =$E$12*(1+$AR2) -> 1443.3 | AY2: {=IF($F$12-$I$4+VLOOKUP($Q2,武学奇术!$A:$ZZ,11,FALSE)+SUM(_xlfn.XLOOKUP(R2:AF2,增益!$A:$A,增益!$K:$K,0))>0,($F$12-$I$4+VLOOKUP($Q2,武学奇术!$A:$ZZ,11,FALSE)+SUM(_xlfn.XLOOKUP(R2:AF2,增益!$A:$A,增益!$K:$K,0)))/200,($F$12-$I$4+VLOOKUP($Q2,武学奇术!$A:$ZZ,11,FALSE)+SUM(_xlfn.XLOOKUP(R2:AF2,增益!$A:$A,增益!$K:$K,0)))/100)} -> 0.118 | AZ2: {=$G$12+VLOOKUP($Q2,武学奇术!$A:$ZZ,12,FALSE)+SUM(_xlfn.XLOOKUP(R2:AF2,增益!$A:$A,增益!$L:$L,0))} -> 0.148 | BA2: =$D$13*(1+$AR2) -> 0 | BB2: =$E$13*(1+$AR2) -> 0 | BC2: {=IF($F$13-$I$4+VLOOKUP($Q2,武学奇术!$A:$ZZ,13,FALSE)+SUM(_xlfn.XLOOKUP(R2:AF2,增益!$A:$A,增益!$M:$M,0))>0,($F$13-$I$4+VLOOKUP($Q2,武学奇术!$A:$ZZ,13,FALSE)+SUM(_xlfn.XLOOKUP(R2:AF2,增益!$A:$A,增益!$K:$K,0)))/200,($F$13-$I$4+VLOOKUP($Q2,武学奇术!$A:$ZZ,13,FALSE)+SUM(_xlfn.XLOOKUP(R2:AF2,增益!$A:$A,增益!$M:$M,0)))/100)} -> -0.24 | BD2: {=$G$13+VLOOKUP($Q2,武学奇术!$A:$ZZ,14,FALSE)+SUM(_xlfn.XLOOKUP(R2:AF2,增益!$A:$A,增益!$N:$N,0))} -> 0 | BE2: =$D$14*(1+$AR2) -> 0 | BF2: =$E$14*(1+$AR2) -> 0 | BG2: {=IF($F$14-$I$4+VLOOKUP($Q2,武学奇术!$A:$ZZ,15,FALSE)+SUM(_xlfn.XLOOKUP(R2:AF2,增益!$A:$A,增益!$O:$O,0))>0,($F$14-$I$4+VLOOKUP($Q2,武学奇术!$A:$ZZ,15,FALSE)+SUM(_xlfn.XLOOKUP(R2:AF2,增益!$A:$A,增益!$O:$O,0)))/200,($F$14-$I$4+VLOOKUP($Q2,武学奇术!$A:$ZZ,15,FALSE)+SUM(_xlfn.XLOOKUP(R2:AF2,增益!$A:$A,增益!$O:$O,0)))/100)} -> -0.24 | BH2: {=$G$14+VLOOKUP($Q2,武学奇术!$A:$ZZ,16,FALSE)+SUM(_xlfn.XLOOKUP(R2:AF2,增益!$A:$A,增益!$P:$P,0))} -> 0 | BI2: =MIN(IF(VLOOKUP($Q2,武学奇术!$A:$ZZ,23,FALSE)=1,100%,$B$8),100%) -> 0.8626 | BJ2: {=IF(VLOOKUP($Q2,武学奇术!$A:$ZZ,23,FALSE)=1,100%,MIN(80%,$B$9+VLOOKUP($Q2,武学奇术!$A:$ZZ,17,FALSE)+SUM(_xlfn.XLOOKUP(R2:AF2,增益!$A:$A,增益!$Q:$Q,0)))+$B$11+SUM(_xlfn.XLOOKUP(R2:AF2,增益!$A:$A,增益!$U:$U,0)))*IF(VLOOKUP($Q2,武学奇术!$A:$ZZ,24,FALSE)=1,0,1)} -> 0.8697 | BK2: {=1+$B$13+VLOOKUP($Q2,武学奇术!$A:$ZZ,18,FALSE)+SUM(_xlfn.XLOOKUP(R2:AF2,增益!$A:$A,增益!$R:$R,0))} -> 1.75 | BL2: {=IF(VLOOKUP($Q2,武学奇术!$A:$ZZ,24,FALSE)=1,100%,MIN(40%,$B$10+VLOOKUP($Q2,武学奇术!$A:$ZZ,19,FALSE)+SUM(_xlfn.XLOOKUP(R2:AF2,增益!$A:$A,增益!$S:$S,0)))+$B$12+SUM(_xlfn.XLOOKUP(R2:AF2,增益!$A:$A,增益!$V:$V,0)))*IF(VLOOKUP($Q2,武学奇术!$A:$ZZ,23,FALSE)=1,0,1)} -> 0.0986 | BM2: {=1+$B$14+VLOOKUP($Q2,武学奇术!$A:$ZZ,20,FALSE)+SUM(_xlfn.XLOOKUP(R2:AF2,增益!$A:$A,增益!$T:$T,0))} -> 1.35 | BN2: =MIN((1-BL2)*BI2,BI2*BJ2) -> 0.75020322 | BO2: =1-BL2-BN2-BP2 -> 0.02734442 | BP2: =IF(VLOOKUP($Q2,武学奇术!$A:$ZZ,22,FALSE)=1,0,(1-$BI2))*(1-$BL2) -> 0.12385236 | BQ2: {=SUM(_xlfn.XLOOKUP(R2:AF2,增益!$A:$A,增益!$W:$W,0))} -> 0
A3: 鸣金 | F3: 通用增伤 | G3: =B16+1.5%+15%+IF(G2="断岳",5%,0)+IF($D$16="√",8%,0)+IF($C$21="征人归",8%,0) -> 0.383 | H3: 外抗 | I3: =20-IF(D17="√",18,0) -> 2 | K3: =($L3*$BN3+$M3*$BL3+$N3*$BO3+$O3*$BP3) -> 28844.065 | L3: =((($AN3+$AO3)/2*$AH3+$AI3)*(1+$AP3)*(1+$AQ3)+(($AS3+$AT3)/2*IF($G$1="鸣金",$AJ3,$AH3)+IF($G$1="鸣金",$AK3*1.5,0))*(1+$AU3)*(1+$AV3)+(($AW3+$AX3)/2*IF($G$1="裂石",$AJ3,$AH3)+IF($G$1="裂石",$AK3*1.5,0))*(1+$AY3)*(1+$AZ3)+(($BA3+$BB3)/2*IF($G$1="牵丝",$AJ3,$AH3)+IF($G$1="牵丝",$AK3*1.5,0))*(1+$BC3)*(1+$BD3)+(($BE3+$BF3)/2*IF($G$1="破竹",$AJ3,$AH3)+IF($G$1="破竹",$AK3*1.5,0))*(1+$BG3)*(1+$BH3))*(1+$AL3)*$BK3*$P3*(1+IF(VLOOKUP($Q3,武学奇术!$A:$ZZ,30,FALSE)="蓄力技",$B$21,0))*(1+$BQ3) -> 31889.612 | M3: =(($AO3*$AH3+$AI3)*(1+$AP3)*(1+$AQ3)+($AT3*IF($G$1="鸣金",$AJ3,$AH3)+IF($G$1="鸣金",$AK3*1.5,0))*(1+$AU3)*(1+$AV3)+($AX3*IF($G$1="裂石",$AJ3,$AH3)+IF($G$1="裂石",$AK3*1.5,0))*(1+$AY3)*(1+$AZ3)+($BB3*IF($G$1="牵丝",$AJ3,$AH3)+IF($G$1="牵丝",$AK3*1.5,0))*(1+$BC3)*(1+$BD3)+($BF3*IF($G$1="破竹",$AJ3,$AH3)+IF($G$1="破竹",$AK3*1.5,0))*(1+$BG3)*(1+$BH3))*(1+$AL3)*$BM3*$P3*(1+IF(VLOOKUP($Q3,武学奇术!$A:$ZZ,30,FALSE)="蓄力技",$B$21,0))*(1+$BQ3) -> 26129.008 | N3: =((($AN3+$AO3)/2*$AH3+$AI3)*(1+$AP3)*(1+$AQ3)+(($AS3+$AT3)/2*IF($G$1="鸣金",$AJ3,$AH3)+IF($G$1="鸣金",$AK3*1.5,0))*(1+$AU3)*(1+$AV3)+(($AW3+$AX3)/2*IF($G$1="裂石",$AJ3,$AH3)+IF($G$1="裂石",$AK3*1.5,0))*(1+$AY3)*(1+$AZ3)+(($BA3+$BB3)/2*IF($G$1="牵丝",$AJ3,$AH3)+IF($G$1="牵丝",$AK3*1.5,0))*(1+$BC3)*(1+$BD3)+(($BE3+$BF3)/2*IF($G$1="破竹",$AJ3,$AH3)+IF($G$1="破竹",$AK3*1.5,0))*(1+$BG3)*(1+$BH3))*(1+$AL3)*$P3*(1+IF(VLOOKUP($Q3,武学奇术!$A:$ZZ,30,FALSE)="蓄力技",$B$21,0))*(1+$BQ3) -> 17237.628 | O3: =((($AN3*$AH3+$AI3)*(1+$AP3)*(1+$AQ3)+($AS3*IF($G$1="鸣金",$AJ3,$AH3)+IF($G$1="鸣金",$AK3*1.5,0))*(1+$AU3)*(1+$AV3)+($AW3*IF($G$1="裂石",$AJ3,$AH3)+IF($G$1="裂石",$AK3*1.5,0))*(1+$AY3)*(1+$AZ3)+($BA3*IF($G$1="牵丝",$AJ3,$AH3)+IF($G$1="牵丝",$AK3*1.5,0))*(1+$BC3)*(1+$BD3)+($BE3*IF($G$1="破竹",$AJ3,$AH3)+IF($G$1="破竹",$AK3*1.5,0))*(1+$BG3)*(1+$BH3))*(1+$AL3))*$P3*(1+IF(VLOOKUP($Q3,武学奇术!$A:$ZZ,30,FALSE)="蓄力技",$B$21,0))*(1+$BQ3) -> 15120.436 | P3: 1 | Q3: 萧呤千浪流星 | R3: 易水歌2层 | S3: 胆寒 | T3: 惧刃 | U3: 穿喉5(普) | V3: N/a | W3: 近战笛 | X3: N/a | Y3: N/a | Z3: N/a | AA3: N/a | AB3: N/a | AC3: N/a | AD3: N/a | AE3: N/a | AF3: 铁衣 | AG3: =VLOOKUP($Q3,武学奇术!$A:$ZZ,25,FALSE) -> 群体奇术 | AH3: =VLOOKUP($Q3,武学奇术!$A:$ZZ,26,FALSE) -> 1.4902 | AI3: =VLOOKUP($Q3,武学奇术!$A:$ZZ,27,FALSE)*(1+IF(OR($AG3=$F$4,$AG3=$F$5),$B$22,0)) -> 358 | AJ3: =VLOOKUP($Q3,武学奇术!$A:$ZZ,28,FALSE) -> 2.2353 | AK3: =VLOOKUP($Q3,武学奇术!$A:$ZZ,29,FALSE)*(1+IF(OR($AG3=$F$4,$AG3=$F$5),$B$22,0)) -> 0 | AL3: {=$G$3+IFERROR(VLOOKUP($AG3,$F$4:$G$7,2,FALSE),0)+VLOOKUP($Q3,武学奇术!$A:$ZZ,2,FALSE)+SUM(_xlfn.XLOOKUP($R3:$AF3,增益!$A:$A,增益!$B:$B,0))} -> 0.703 | AM3: {=VLOOKUP($Q3,武学奇术!$A:$ZZ,5,FALSE)+SUM(_xlfn.XLOOKUP($R3:$AF3,增益!$A:$A,增益!$E:$E,0))} -> 0 | AN3: {=$D$10*(1+$AM3)+VLOOKUP($Q3,武学奇术!$A:$ZZ,3,FALSE)+SUM(_xlfn.XLOOKUP($R3:$AF3,增益!$A:$A,增益!$C:$C,0))-$I$2} -> 3052.34 | AO3: {=$E$10*(1+$AM3)+VLOOKUP($Q3,武学奇术!$A:$ZZ,4,FALSE)+SUM(_xlfn.XLOOKUP($R3:$AF3,增益!$A:$A,增益!$D:$D,0))-$I$2} -> 3052.34 | AP3: {=IF($F$10-$I$3+VLOOKUP($Q3,武学奇术!$A:$ZZ,6,FALSE)+SUM(_xlfn.XLOOKUP(R3:AF3,增益!$A:$A,增益!$F:$F,0))>0,($F$10-$I$3+VLOOKUP($Q3,武学奇术!$A:$ZZ,6,FALSE)+SUM(_xlfn.XLOOKUP(R3:AF3,增益!$A:$A,增益!$F:$F,0)))/200,($F$10-$I$3+VLOOKUP($Q3,武学奇术!$A:$ZZ,6,FALSE)+SUM(_xlfn.XLOOKUP(R3:AF3,增益!$A:$A,增益!$F:$F,0)))/100)} -> 0.412 | AQ3: {=$G$10+VLOOKUP($Q3,武学奇术!$A:$ZZ,7,FALSE)+SUM(_xlfn.XLOOKUP(R3:AF3,增益!$A:$A,增益!$G:$G,0))} -> 0 | AR3: {=VLOOKUP($Q3,武学奇术!$A:$ZZ,8,FALSE)+SUM(_xlfn.XLOOKUP(R3:AF3,增益!$A:$A,增益!$H:$H,0))} -> 0 | AS3: =$D$11*(1+$AR3) -> 0 | AT3: =$E$11*(1+$AR3) -> 0 | AU3: {=IF($F$11-$I$4+VLOOKUP($Q3,武学奇术!$A:$ZZ,9,FALSE)+SUM(_xlfn.XLOOKUP(R3:AF3,增益!$A:$A,增益!$I:$I,0))>0,($F$11-$I$4+VLOOKUP($Q3,武学奇术!$A:$ZZ,9,FALSE)+SUM(_xlfn.XLOOKUP(R3:AF3,增益!$A:$A,增益!$I:$I,0)))/200,($F$11-$I$4+VLOOKUP($Q3,武学奇术!$A:$ZZ,9,FALSE)+SUM(_xlfn.XLOOKUP(R3:AF3,增益!$A:$A,增益!$I:$I,0)))/100)} -> -0.08 | AV3: {=$G$11+VLOOKUP($Q3,武学奇术!$A:$ZZ,10,FALSE)+SUM(_xlfn.XLOOKUP(R3:AF3,增益!$A:$A,增益!$J:$J,0))} -> 0 | AW3: =$D$12*(1+$AR3) -> 634.5 | AX3: =$E$12*(1+$AR3) -> 1443.3 | AY3: {=IF($F$12-$I$4+VLOOKUP($Q3,武学奇术!$A:$ZZ,11,FALSE)+SUM(_xlfn.XLOOKUP(R3:AF3,增益!$A:$A,增益!$K:$K,0))>0,($F$12-$I$4+VLOOKUP($Q3,武学奇术!$A:$ZZ,11,FALSE)+SUM(_xlfn.XLOOKUP(R3:AF3,增益!$A:$A,增益!$K:$K,0)))/200,($F$12-$I$4+VLOOKUP($Q3,武学奇术!$A:$ZZ,11,FALSE)+SUM(_xlfn.XLOOKUP(R3:AF3,增益!$A:$A,增益!$K:$K,0)))/100)} -> 0.198 | AZ3: {=$G$12+VLOOKUP($Q3,武学奇术!$A:$ZZ,12,FALSE)+SUM(_xlfn.XLOOKUP(R3:AF3,增益!$A:$A,增益!$L:$L,0))} -> 0.148 | BA3: =$D$13*(1+$AR3) -> 0 | BB3: =$E$13*(1+$AR3) -> 0 | BC3: {=IF($F$13-$I$4+VLOOKUP($Q3,武学奇术!$A:$ZZ,13,FALSE)+SUM(_xlfn.XLOOKUP(R3:AF3,增益!$A:$A,增益!$M:$M,0))>0,($F$13-$I$4+VLOOKUP($Q3,武学奇术!$A:$ZZ,13,FALSE)+SUM(_xlfn.XLOOKUP(R3:AF3,增益!$A:$A,增益!$K:$K,0)))/200,($F$13-$I$4+VLOOKUP($Q3,武学奇术!$A:$ZZ,13,FALSE)+SUM(_xlfn.XLOOKUP(R3:AF3,增益!$A:$A,增益!$M:$M,0)))/100)} -> -0.08 | BD3: {=$G$13+VLOOKUP($Q3,武学奇术!$A:$ZZ,14,FALSE)+SUM(_xlfn.XLOOKUP(R3:AF3,增益!$A:$A,增益!$N:$N,0))} -> 0 | BE3: =$D$14*(1+$AR3) -> 0 | BF3: =$E$14*(1+$AR3) -> 0 | BG3: {=IF($F$14-$I$4+VLOOKUP($Q3,武学奇术!$A:$ZZ,15,FALSE)+SUM(_xlfn.XLOOKUP(R3:AF3,增益!$A:$A,增益!$O:$O,0))>0,($F$14-$I$4+VLOOKUP($Q3,武学奇术!$A:$ZZ,15,FALSE)+SUM(_xlfn.XLOOKUP(R3:AF3,增益!$A:$A,增益!$O:$O,0)))/200,($F$14-$I$4+VLOOKUP($Q3,武学奇术!$A:$ZZ,15,FALSE)+SUM(_xlfn.XLOOKUP(R3:AF3,增益!$A:$A,增益!$O:$O,0)))/100)} -> -0.08 | BH3: {=$G$14+VLOOKUP($Q3,武学奇术!$A:$ZZ,16,FALSE)+SUM(_xlfn.XLOOKUP(R3:AF3,增益!$A:$A,增益!$P:$P,0))} -> 0 | BI3: =MIN(IF(VLOOKUP($Q3,武学奇术!$A:$ZZ,23,FALSE)=1,100%,$B$8),100%) -> 0.8626 | BJ3: {=IF(VLOOKUP($Q3,武学奇术!$A:$ZZ,23,FALSE)=1,100%,MIN(80%,$B$9+VLOOKUP($Q3,武学奇术!$A:$ZZ,17,FALSE)+SUM(_xlfn.XLOOKUP(R3:AF3,增益!$A:$A,增益!$Q:$Q,0)))+$B$11+SUM(_xlfn.XLOOKUP(R3:AF3,增益!$A:$A,增益!$U:$U,0)))*IF(VLOOKUP($Q3,武学奇术!$A:$ZZ,24,FALSE)=1,0,1)} -> 0.8697 | BK3: {=1+$B$13+VLOOKUP($Q3,武学奇术!$A:$ZZ,18,FALSE)+SUM(_xlfn.XLOOKUP(R3:AF3,增益!$A:$A,增益!$R:$R,0))} -> 1.85 | BL3: {=IF(VLOOKUP($Q3,武学奇术!$A:$ZZ,24,FALSE)=1,100%,MIN(40%,$B$10+VLOOKUP($Q3,武学奇术!$A:$ZZ,19,FALSE)+SUM(_xlfn.XLOOKUP(R3:AF3,增益!$A:$A,增益!$S:$S,0)))+$B$12+SUM(_xlfn.XLOOKUP(R3:AF3,增益!$A:$A,增益!$V:$V,0)))*IF(VLOOKUP($Q3,武学奇术!$A:$ZZ,23,FALSE)=1,0,1)} -> 0.0986 | BM3: {=1+$B$14+VLOOKUP($Q3,武学奇术!$A:$ZZ,20,FALSE)+SUM(_xlfn.XLOOKUP(R3:AF3,增益!$A:$A,增益!$T:$T,0))} -> 1.35 | BN3: =MIN((1-BL3)*BI3,BI3*BJ3) -> 0.75020322 | BO3: =1-BL3-BN3-BP3 -> 0.02734442 | BP3: =IF(VLOOKUP($Q3,武学奇术!$A:$ZZ,22,FALSE)=1,0,(1-$BI3))*(1-$BL3) -> 0.12385236 | BQ3: {=SUM(_xlfn.XLOOKUP(R3:AF3,增益!$A:$A,增益!$W:$W,0))} -> 0
A4: 裂石 | B4: 508.7 | C4: 1257.7 | D4: 35.6 | E4: 0.148 | F4: 陌刀 | G4: =B15+B17 -> 0.17 | H4: 属抗 | I4: 24 | K4: =($L4*$BN4+$M4*$BL4+$N4*$BO4+$O4*$BP4) -> 29153.984 | L4: =((($AN4+$AO4)/2*$AH4+$AI4)*(1+$AP4)*(1+$AQ4)+(($AS4+$AT4)/2*IF($G$1="鸣金",$AJ4,$AH4)+IF($G$1="鸣金",$AK4*1.5,0))*(1+$AU4)*(1+$AV4)+(($AW4+$AX4)/2*IF($G$1="裂石",$AJ4,$AH4)+IF($G$1="裂石",$AK4*1.5,0))*(1+$AY4)*(1+$AZ4)+(($BA4+$BB4)/2*IF($G$1="牵丝",$AJ4,$AH4)+IF($G$1="牵丝",$AK4*1.5,0))*(1+$BC4)*(1+$BD4)+(($BE4+$BF4)/2*IF($G$1="破竹",$AJ4,$AH4)+IF($G$1="破竹",$AK4*1.5,0))*(1+$BG4)*(1+$BH4))*(1+$AL4)*$BK4*$P4*(1+IF(VLOOKUP($Q4,武学奇术!$A:$ZZ,30,FALSE)="蓄力技",$B$21,0))*(1+$BQ4) -> 32232.36 | M4: =(($AO4*$AH4+$AI4)*(1+$AP4)*(1+$AQ4)+($AT4*IF($G$1="鸣金",$AJ4,$AH4)+IF($G$1="鸣金",$AK4*1.5,0))*(1+$AU4)*(1+$AV4)+($AX4*IF($G$1="裂石",$AJ4,$AH4)+IF($G$1="裂石",$AK4*1.5,0))*(1+$AY4)*(1+$AZ4)+($BB4*IF($G$1="牵丝",$AJ4,$AH4)+IF($G$1="牵丝",$AK4*1.5,0))*(1+$BC4)*(1+$BD4)+($BF4*IF($G$1="破竹",$AJ4,$AH4)+IF($G$1="破竹",$AK4*1.5,0))*(1+$BG4)*(1+$BH4))*(1+$AL4)*$BM4*$P4*(1+IF(VLOOKUP($Q4,武学奇术!$A:$ZZ,30,FALSE)="蓄力技",$B$21,0))*(1+$BQ4) -> 26395.905 | N4: =((($AN4+$AO4)/2*$AH4+$AI4)*(1+$AP4)*(1+$AQ4)+(($AS4+$AT4)/2*IF($G$1="鸣金",$AJ4,$AH4)+IF($G$1="鸣金",$AK4*1.5,0))*(1+$AU4)*(1+$AV4)+(($AW4+$AX4)/2*IF($G$1="裂石",$AJ4,$AH4)+IF($G$1="裂石",$AK4*1.5,0))*(1+$AY4)*(1+$AZ4)+(($BA4+$BB4)/2*IF($G$1="牵丝",$AJ4,$AH4)+IF($G$1="牵丝",$AK4*1.5,0))*(1+$BC4)*(1+$BD4)+(($BE4+$BF4)/2*IF($G$1="破竹",$AJ4,$AH4)+IF($G$1="破竹",$AK4*1.5,0))*(1+$BG4)*(1+$BH4))*(1+$AL4)*$P4*(1+IF(VLOOKUP($Q4,武学奇术!$A:$ZZ,30,FALSE)="蓄力技",$B$21,0))*(1+$BQ4) -> 17422.897 | O4: =((($AN4*$AH4+$AI4)*(1+$AP4)*(1+$AQ4)+($AS4*IF($G$1="鸣金",$AJ4,$AH4)+IF($G$1="鸣金",$AK4*1.5,0))*(1+$AU4)*(1+$AV4)+($AW4*IF($G$1="裂石",$AJ4,$AH4)+IF($G$1="裂石",$AK4*1.5,0))*(1+$AY4)*(1+$AZ4)+($BA4*IF($G$1="牵丝",$AJ4,$AH4)+IF($G$1="牵丝",$AK4*1.5,0))*(1+$BC4)*(1+$BD4)+($BE4*IF($G$1="破竹",$AJ4,$AH4)+IF($G$1="破竹",$AK4*1.5,0))*(1+$BG4)*(1+$BH4))*(1+$AL4))*$P4*(1+IF(VLOOKUP($Q4,武学奇术!$A:$ZZ,30,FALSE)="蓄力技",$B$21,0))*(1+$BQ4) -> 15293.273 | P4: 1 | Q4: 萧呤千浪流星 | R4: 易水歌3层 | S4: 胆寒 | T4: 惧刃 | U4: 穿喉5(普) | V4: N/a | W4: 近战笛 | X4: N/a | Y4: N/a | Z4: N/a | AA4: N/a | AB4: N/a | AC4: N/a | AD4: N/a | AE4: N/a | AF4: 铁衣 | AG4: =VLOOKUP($Q4,武学奇术!$A:$ZZ,25,FALSE) -> 群体奇术 | AH4: =VLOOKUP($Q4,武学奇术!$A:$ZZ,26,FALSE) -> 1.4902 | AI4: =VLOOKUP($Q4,武学奇术!$A:$ZZ,27,FALSE)*(1+IF(OR($AG4=$F$4,$AG4=$F$5),$B$22,0)) -> 358 | AJ4: =VLOOKUP($Q4,武学奇术!$A:$ZZ,28,FALSE) -> 2.2353 | AK4: =VLOOKUP($Q4,武学奇术!$A:$ZZ,29,FALSE)*(1+IF(OR($AG4=$F$4,$AG4=$F$5),$B$22,0)) -> 0 | AL4: {=$G$3+IFERROR(VLOOKUP($AG4,$F$4:$G$7,2,FALSE),0)+VLOOKUP($Q4,武学奇术!$A:$ZZ,2,FALSE)+SUM(_xlfn.XLOOKUP($R4:$AF4,增益!$A:$A,增益!$B:$B,0))} -> 0.713 | AM4: {=VLOOKUP($Q4,武学奇术!$A:$ZZ,5,FALSE)+SUM(_xlfn.XLOOKUP($R4:$AF4,增益!$A:$A,增益!$E:$E,0))} -> 0 | AN4: {=$D$10*(1+$AM4)+VLOOKUP($Q4,武学奇术!$A:$ZZ,3,FALSE)+SUM(_xlfn.XLOOKUP($R4:$AF4,增益!$A:$A,增益!$C:$C,0))-$I$2} -> 3052.34 | AO4: {=$E$10*(1+$AM4)+VLOOKUP($Q4,武学奇术!$A:$ZZ,4,FALSE)+SUM(_xlfn.XLOOKUP($R4:$AF4,增益!$A:$A,增益!$D:$D,0))-$I$2} -> 3052.34 | AP4: {=IF($F$10-$I$3+VLOOKUP($Q4,武学奇术!$A:$ZZ,6,FALSE)+SUM(_xlfn.XLOOKUP(R4:AF4,增益!$A:$A,增益!$F:$F,0))>0,($F$10-$I$3+VLOOKUP($Q4,武学奇术!$A:$ZZ,6,FALSE)+SUM(_xlfn.XLOOKUP(R4:AF4,增益!$A:$A,增益!$F:$F,0)))/200,($F$10-$I$3+VLOOKUP($Q4,武学奇术!$A:$ZZ,6,FALSE)+SUM(_xlfn.XLOOKUP(R4:AF4,增益!$A:$A,增益!$F:$F,0)))/100)} -> 0.422 | AQ4: {=$G$10+VLOOKUP($Q4,武学奇术!$A:$ZZ,7,FALSE)+SUM(_xlfn.XLOOKUP(R4:AF4,增益!$A:$A,增益!$G:$G,0))} -> 0 | AR4: {=VLOOKUP($Q4,武学奇术!$A:$ZZ,8,FALSE)+SUM(_xlfn.XLOOKUP(R4:AF4,增益!$A:$A,增益!$H:$H,0))} -> 0 | AS4: =$D$11*(1+$AR4) -> 0 | AT4: =$E$11*(1+$AR4) -> 0 | AU4: {=IF($F$11-$I$4+VLOOKUP($Q4,武学奇术!$A:$ZZ,9,FALSE)+SUM(_xlfn.XLOOKUP(R4:AF4,增益!$A:$A,增益!$I:$I,0))>0,($F$11-$I$4+VLOOKUP($Q4,武学奇术!$A:$ZZ,9,FALSE)+SUM(_xlfn.XLOOKUP(R4:AF4,增益!$A:$A,增益!$I:$I,0)))/200,($F$11-$I$4+VLOOKUP($Q4,武学奇术!$A:$ZZ,9,FALSE)+SUM(_xlfn.XLOOKUP(R4:AF4,增益!$A:$A,增益!$I:$I,0)))/100)} -> -0.08 | AV4: {=$G$11+VLOOKUP($Q4,武学奇术!$A:$ZZ,10,FALSE)+SUM(_xlfn.XLOOKUP(R4:AF4,增益!$A:$A,增益!$J:$J,0))} -> 0 | AW4: =$D$12*(1+$AR4) -> 634.5 | AX4: =$E$12*(1+$AR4) -> 1443.3 | AY4: {=IF($F$12-$I$4+VLOOKUP($Q4,武学奇术!$A:$ZZ,11,FALSE)+SUM(_xlfn.XLOOKUP(R4:AF4,增益!$A:$A,增益!$K:$K,0))>0,($F$12-$I$4+VLOOKUP($Q4,武学奇术!$A:$ZZ,11,FALSE)+SUM(_xlfn.XLOOKUP(R4:AF4,增益!$A:$A,增益!$K:$K,0)))/200,($F$12-$I$4+VLOOKUP($Q4,武学奇术!$A:$ZZ,11,FALSE)+SUM(_xlfn.XLOOKUP(R4:AF4,增益!$A:$A,增益!$K:$K,0)))/100)} -> 0.198 | AZ4: {=$G$12+VLOOKUP($Q4,武学奇术!$A:$ZZ,12,FALSE)+SUM(_xlfn.XLOOKUP(R4:AF4,增益!$A:$A,增益!$L:$L,0))} -> 0.148 | BA4: =$D$13*(1+$AR4) -> 0 | BB4: =$E$13*(1+$AR4) -> 0 | BC4: {=IF($F$13-$I$4+VLOOKUP($Q4,武学奇术!$A:$ZZ,13,FALSE)+SUM(_xlfn.XLOOKUP(R4:AF4,增益!$A:$A,增益!$M:$M,0))>0,($F$13-$I$4+VLOOKUP($Q4,武学奇术!$A:$ZZ,13,FALSE)+SUM(_xlfn.XLOOKUP(R4:AF4,增益!$A:$A,增益!$K:$K,0)))/200,($F$13-$I$4+VLOOKUP($Q4,武学奇术!$A:$ZZ,13,FALSE)+SUM(_xlfn.XLOOKUP(R4:AF4,增益!$A:$A,增益!$M:$M,0)))/100)} -> -0.08 | BD4: {=$G$13+VLOOKUP($Q4,武学奇术!$A:$ZZ,14,FALSE)+SUM(_xlfn.XLOOKUP(R4:AF4,增益!$A:$A,增益!$N:$N,0))} -> 0 | BE4: =$D$14*(1+$AR4) -> 0 | BF4: =$E$14*(1+$AR4) -> 0 | BG4: {=IF($F$14-$I$4+VLOOKUP($Q4,武学奇术!$A:$ZZ,15,FALSE)+SUM(_xlfn.XLOOKUP(R4:AF4,增益!$A:$A,增益!$O:$O,0))>0,($F$14-$I$4+VLOOKUP($Q4,武学奇术!$A:$ZZ,15,FALSE)+SUM(_xlfn.XLOOKUP(R4:AF4,增益!$A:$A,增益!$O:$O,0)))/200,($F$14-$I$4+VLOOKUP($Q4,武学奇术!$A:$ZZ,15,FALSE)+SUM(_xlfn.XLOOKUP(R4:AF4,增益!$A:$A,增益!$O:$O,0)))/100)} -> -0.08 | BH4: {=$G$14+VLOOKUP($Q4,武学奇术!$A:$ZZ,16,FALSE)+SUM(_xlfn.XLOOKUP(R4:AF4,增益!$A:$A,增益!$P:$P,0))} -> 0 | BI4: =MIN(IF(VLOOKUP($Q4,武学奇术!$A:$ZZ,23,FALSE)=1,100%,$B$8),100%) -> 0.8626 | BJ4: {=IF(VLOOKUP($Q4,武学奇术!$A:$ZZ,23,FALSE)=1,100%,MIN(80%,$B$9+VLOOKUP($Q4,武学奇术!$A:$ZZ,17,FALSE)+SUM(_xlfn.XLOOKUP(R4:AF4,增益!$A:$A,增益!$Q:$Q,0)))+$B$11+SUM(_xlfn.XLOOKUP(R4:AF4,增益!$A:$A,增益!$U:$U,0)))*IF(VLOOKUP($Q4,武学奇术!$A:$ZZ,24,FALSE)=1,0,1)} -> 0.8697 | BK4: {=1+$B$13+VLOOKUP($Q4,武学奇术!$A:$ZZ,18,FALSE)+SUM(_xlfn.XLOOKUP(R4:AF4,增益!$A:$A,增益!$R:$R,0))} -> 1.85 | BL4: {=IF(VLOOKUP($Q4,武学奇术!$A:$ZZ,24,FALSE)=1,100%,MIN(40%,$B$10+VLOOKUP($Q4,武学奇术!$A:$ZZ,19,FALSE)+SUM(_xlfn.XLOOKUP(R4:AF4,增益!$A:$A,增益!$S:$S,0)))+$B$12+SUM(_xlfn.XLOOKUP(R4:AF4,增益!$A:$A,增益!$V:$V,0)))*IF(VLOOKUP($Q4,武学奇术!$A:$ZZ,23,FALSE)=1,0,1)} -> 0.0986 | BM4: {=1+$B$14+VLOOKUP($Q4,武学奇术!$A:$ZZ,20,FALSE)+SUM(_xlfn.XLOOKUP(R4:AF4,增益!$A:$A,增益!$T:$T,0))} -> 1.35 | BN4: =MIN((1-BL4)*BI4,BI4*BJ4) -> 0.75020322 | BO4: =1-BL4-BN4-BP4 -> 0.02734442 | BP4: =IF(VLOOKUP($Q4,武学奇术!$A:$ZZ,22,FALSE)=1,0,(1-$BI4))*(1-$BL4) -> 0.12385236 | BQ4: {=SUM(_xlfn.XLOOKUP(R4:AF4,增益!$A:$A,增益!$W:$W,0))} -> 0
A5: 牵丝 | F5: 横刀 | G5: =B15+B18 -> 0.084 | K5: =($L5*$BN5+$M5*$BL5+$N5*$BO5+$O5*$BP5) -> 29465.544 | L5: =((($AN5+$AO5)/2*$AH5+$AI5)*(1+$AP5)*(1+$AQ5)+(($AS5+$AT5)/2*IF($G$1="鸣金",$AJ5,$AH5)+IF($G$1="鸣金",$AK5*1.5,0))*(1+$AU5)*(1+$AV5)+(($AW5+$AX5)/2*IF($G$1="裂石",$AJ5,$AH5)+IF($G$1="裂石",$AK5*1.5,0))*(1+$AY5)*(1+$AZ5)+(($BA5+$BB5)/2*IF($G$1="牵丝",$AJ5,$AH5)+IF($G$1="牵丝",$AK5*1.5,0))*(1+$BC5)*(1+$BD5)+(($BE5+$BF5)/2*IF($G$1="破竹",$AJ5,$AH5)+IF($G$1="破竹",$AK5*1.5,0))*(1+$BG5)*(1+$BH5))*(1+$AL5)*$BK5*$P5*(1+IF(VLOOKUP($Q5,武学奇术!$A:$ZZ,30,FALSE)="蓄力技",$B$21,0))*(1+$BQ5) -> 32576.924 | M5: =(($AO5*$AH5+$AI5)*(1+$AP5)*(1+$AQ5)+($AT5*IF($G$1="鸣金",$AJ5,$AH5)+IF($G$1="鸣金",$AK5*1.5,0))*(1+$AU5)*(1+$AV5)+($AX5*IF($G$1="裂石",$AJ5,$AH5)+IF($G$1="裂石",$AK5*1.5,0))*(1+$AY5)*(1+$AZ5)+($BB5*IF($G$1="牵丝",$AJ5,$AH5)+IF($G$1="牵丝",$AK5*1.5,0))*(1+$BC5)*(1+$BD5)+($BF5*IF($G$1="破竹",$AJ5,$AH5)+IF($G$1="破竹",$AK5*1.5,0))*(1+$BG5)*(1+$BH5))*(1+$AL5)*$BM5*$P5*(1+IF(VLOOKUP($Q5,武学奇术!$A:$ZZ,30,FALSE)="蓄力技",$B$21,0))*(1+$BQ5) -> 26664.126 | N5: =((($AN5+$AO5)/2*$AH5+$AI5)*(1+$AP5)*(1+$AQ5)+(($AS5+$AT5)/2*IF($G$1="鸣金",$AJ5,$AH5)+IF($G$1="鸣金",$AK5*1.5,0))*(1+$AU5)*(1+$AV5)+(($AW5+$AX5)/2*IF($G$1="裂石",$AJ5,$AH5)+IF($G$1="裂石",$AK5*1.5,0))*(1+$AY5)*(1+$AZ5)+(($BA5+$BB5)/2*IF($G$1="牵丝",$AJ5,$AH5)+IF($G$1="牵丝",$AK5*1.5,0))*(1+$BC5)*(1+$BD5)+(($BE5+$BF5)/2*IF($G$1="破竹",$AJ5,$AH5)+IF($G$1="破竹",$AK5*1.5,0))*(1+$BG5)*(1+$BH5))*(1+$AL5)*$P5*(1+IF(VLOOKUP($Q5,武学奇术!$A:$ZZ,30,FALSE)="蓄力技",$B$21,0))*(1+$BQ5) -> 17609.148 | O5: =((($AN5*$AH5+$AI5)*(1+$AP5)*(1+$AQ5)+($AS5*IF($G$1="鸣金",$AJ5,$AH5)+IF($G$1="鸣金",$AK5*1.5,0))*(1+$AU5)*(1+$AV5)+($AW5*IF($G$1="裂石",$AJ5,$AH5)+IF($G$1="裂石",$AK5*1.5,0))*(1+$AY5)*(1+$AZ5)+($BA5*IF($G$1="牵丝",$AJ5,$AH5)+IF($G$1="牵丝",$AK5*1.5,0))*(1+$BC5)*(1+$BD5)+($BE5*IF($G$1="破竹",$AJ5,$AH5)+IF($G$1="破竹",$AK5*1.5,0))*(1+$BG5)*(1+$BH5))*(1+$AL5))*$P5*(1+IF(VLOOKUP($Q5,武学奇术!$A:$ZZ,30,FALSE)="蓄力技",$B$21,0))*(1+$BQ5) -> 15467.091 | P5: 1 | Q5: 萧呤千浪流星 | R5: 易水歌4层 | S5: 胆寒 | T5: 惧刃 | U5: 穿喉5(普) | V5: N/a | W5: 近战笛 | X5: N/a | Y5: N/a | Z5: N/a | AA5: N/a | AB5: N/a | AC5: N/a | AD5: N/a | AE5: N/a | AF5: 铁衣 | AG5: =VLOOKUP($Q5,武学奇术!$A:$ZZ,25,FALSE) -> 群体奇术 | AH5: =VLOOKUP($Q5,武学奇术!$A:$ZZ,26,FALSE) -> 1.4902 | AI5: =VLOOKUP($Q5,武学奇术!$A:$ZZ,27,FALSE)*(1+IF(OR($AG5=$F$4,$AG5=$F$5),$B$22,0)) -> 358 | AJ5: =VLOOKUP($Q5,武学奇术!$A:$ZZ,28,FALSE) -> 2.2353 | AK5: =VLOOKUP($Q5,武学奇术!$A:$ZZ,29,FALSE)*(1+IF(OR($AG5=$F$4,$AG5=$F$5),$B$22,0)) -> 0 | AL5: {=$G$3+IFERROR(VLOOKUP($AG5,$F$4:$G$7,2,FALSE),0)+VLOOKUP($Q5,武学奇术!$A:$ZZ,2,FALSE)+SUM(_xlfn.XLOOKUP($R5:$AF5,增益!$A:$A,增益!$B:$B,0))} -> 0.723 | AM5: {=VLOOKUP($Q5,武学奇术!$A:$ZZ,5,FALSE)+SUM(_xlfn.XLOOKUP($R5:$AF5,增益!$A:$A,增益!$E:$E,0))} -> 0 | AN5: {=$D$10*(1+$AM5)+VLOOKUP($Q5,武学奇术!$A:$ZZ,3,FALSE)+SUM(_xlfn.XLOOKUP($R5:$AF5,增益!$A:$A,增益!$C:$C,0))-$I$2} -> 3052.34 | AO5: {=$E$10*(1+$AM5)+VLOOKUP($Q5,武学奇术!$A:$ZZ,4,FALSE)+SUM(_xlfn.XLOOKUP($R5:$AF5,增益!$A:$A,增益!$D:$D,0))-$I$2} -> 3052.34 | AP5: {=IF($F$10-$I$3+VLOOKUP($Q5,武学奇术!$A:$ZZ,6,FALSE)+SUM(_xlfn.XLOOKUP(R5:AF5,增益!$A:$A,增益!$F:$F,0))>0,($F$10-$I$3+VLOOKUP($Q5,武学奇术!$A:$ZZ,6,FALSE)+SUM(_xlfn.XLOOKUP(R5:AF5,增益!$A:$A,增益!$F:$F,0)))/200,($F$10-$I$3+VLOOKUP($Q5,武学奇术!$A:$ZZ,6,FALSE)+SUM(_xlfn.XLOOKUP(R5:AF5,增益!$A:$A,增益!$F:$F,0)))/100)} -> 0.432 | AQ5: {=$G$10+VLOOKUP($Q5,武学奇术!$A:$ZZ,7,FALSE)+SUM(_xlfn.XLOOKUP(R5:AF5,增益!$A:$A,增益!$G:$G,0))} -> 0 | AR5: {=VLOOKUP($Q5,武学奇术!$A:$ZZ,8,FALSE)+SUM(_xlfn.XLOOKUP(R5:AF5,增益!$A:$A,增益!$H:$H,0))} -> 0 | AS5: =$D$11*(1+$AR5) -> 0 | AT5: =$E$11*(1+$AR5) -> 0 | AU5: {=IF($F$11-$I$4+VLOOKUP($Q5,武学奇术!$A:$ZZ,9,FALSE)+SUM(_xlfn.XLOOKUP(R5:AF5,增益!$A:$A,增益!$I:$I,0))>0,($F$11-$I$4+VLOOKUP($Q5,武学奇术!$A:$ZZ,9,FALSE)+SUM(_xlfn.XLOOKUP(R5:AF5,增益!$A:$A,增益!$I:$I,0)))/200,($F$11-$I$4+VLOOKUP($Q5,武学奇术!$A:$ZZ,9,FALSE)+SUM(_xlfn.XLOOKUP(R5:AF5,增益!$A:$A,增益!$I:$I,0)))/100)} -> -0.08 | AV5: {=$G$11+VLOOKUP($Q5,武学奇术!$A:$ZZ,10,FALSE)+SUM(_xlfn.XLOOKUP(R5:AF5,增益!$A:$A,增益!$J:$J,0))} -> 0 | AW5: =$D$12*(1+$AR5) -> 634.5 | AX5: =$E$12*(1+$AR5) -> 1443.3 | AY5: {=IF($F$12-$I$4+VLOOKUP($Q5,武学奇术!$A:$ZZ,11,FALSE)+SUM(_xlfn.XLOOKUP(R5:AF5,增益!$A:$A,增益!$K:$K,0))>0,($F$12-$I$4+VLOOKUP($Q5,武学奇术!$A:$ZZ,11,FALSE)+SUM(_xlfn.XLOOKUP(R5:AF5,增益!$A:$A,增益!$K:$K,0)))/200,($F$12-$I$4+VLOOKUP($Q5,武学奇术!$A:$ZZ,11,FALSE)+SUM(_xlfn.XLOOKUP(R5:AF5,增益!$A:$A,增益!$K:$K,0)))/100)} -> 0.198 | AZ5: {=$G$12+VLOOKUP($Q5,武学奇术!$A:$ZZ,12,FALSE)+SUM(_xlfn.XLOOKUP(R5:AF5,增益!$A:$A,增益!$L:$L,0))} -> 0.148 | BA5: =$D$13*(1+$AR5) -> 0 | BB5: =$E$13*(1+$AR5) -> 0 | BC5: {=IF($F$13-$I$4+VLOOKUP($Q5,武学奇术!$A:$ZZ,13,FALSE)+SUM(_xlfn.XLOOKUP(R5:AF5,增益!$A:$A,增益!$M:$M,0))>0,($F$13-$I$4+VLOOKUP($Q5,武学奇术!$A:$ZZ,13,FALSE)+SUM(_xlfn.XLOOKUP(R5:AF5,增益!$A:$A,增益!$K:$K,0)))/200,($F$13-$I$4+VLOOKUP($Q5,武学奇术!$A:$ZZ,13,FALSE)+SUM(_xlfn.XLOOKUP(R5:AF5,增益!$A:$A,增益!$M:$M,0)))/100)} -> -0.08 | BD5: {=$G$13+VLOOKUP($Q5,武学奇术!$A:$ZZ,14,FALSE)+SUM(_xlfn.XLOOKUP(R5:AF5,增益!$A:$A,增益!$N:$N,0))} -> 0 | BE5: =$D$14*(1+$AR5) -> 0 | BF5: =$E$14*(1+$AR5) -> 0 | BG5: {=IF($F$14-$I$4+VLOOKUP($Q5,武学奇术!$A:$ZZ,15,FALSE)+SUM(_xlfn.XLOOKUP(R5:AF5,增益!$A:$A,增益!$O:$O,0))>0,($F$14-$I$4+VLOOKUP($Q5,武学奇术!$A:$ZZ,15,FALSE)+SUM(_xlfn.XLOOKUP(R5:AF5,增益!$A:$A,增益!$O:$O,0)))/200,($F$14-$I$4+VLOOKUP($Q5,武学奇术!$A:$ZZ,15,FALSE)+SUM(_xlfn.XLOOKUP(R5:AF5,增益!$A:$A,增益!$O:$O,0)))/100)} -> -0.08 | BH5: {=$G$14+VLOOKUP($Q5,武学奇术!$A:$ZZ,16,FALSE)+SUM(_xlfn.XLOOKUP(R5:AF5,增益!$A:$A,增益!$P:$P,0))} -> 0 | BI5: =MIN(IF(VLOOKUP($Q5,武学奇术!$A:$ZZ,23,FALSE)=1,100%,$B$8),100%) -> 0.8626 | BJ5: {=IF(VLOOKUP($Q5,武学奇术!$A:$ZZ,23,FALSE)=1,100%,MIN(80%,$B$9+VLOOKUP($Q5,武学奇术!$A:$ZZ,17,FALSE)+SUM(_xlfn.XLOOKUP(R5:AF5,增益!$A:$A,增益!$Q:$Q,0)))+$B$11+SUM(_xlfn.XLOOKUP(R5:AF5,增益!$A:$A,增益!$U:$U,0)))*IF(VLOOKUP($Q5,武学奇术!$A:$ZZ,24,FALSE)=1,0,1)} -> 0.8697 | BK5: {=1+$B$13+VLOOKUP($Q5,武学奇术!$A:$ZZ,18,FALSE)+SUM(_xlfn.XLOOKUP(R5:AF5,增益!$A:$A,增益!$R:$R,0))} -> 1.85 | BL5: {=IF(VLOOKUP($Q5,武学奇术!$A:$ZZ,24,FALSE)=1,100%,MIN(40%,$B$10+VLOOKUP($Q5,武学奇术!$A:$ZZ,19,FALSE)+SUM(_xlfn.XLOOKUP(R5:AF5,增益!$A:$A,增益!$S:$S,0)))+$B$12+SUM(_xlfn.XLOOKUP(R5:AF5,增益!$A:$A,增益!$V:$V,0)))*IF(VLOOKUP($Q5,武学奇术!$A:$ZZ,23,FALSE)=1,0,1)} -> 0.0986 | BM5: {=1+$B$14+VLOOKUP($Q5,武学奇术!$A:$ZZ,20,FALSE)+SUM(_xlfn.XLOOKUP(R5:AF5,增益!$A:$A,增益!$T:$T,0))} -> 1.35 | BN5: =MIN((1-BL5)*BI5,BI5*BJ5) -> 0.75020322 | BO5: =1-BL5-BN5-BP5 -> 0.02734442 | BP5: =IF(VLOOKUP($Q5,武学奇术!$A:$ZZ,22,FALSE)=1,0,(1-$BI5))*(1-$BL5) -> 0.12385236 | BQ5: {=SUM(_xlfn.XLOOKUP(R5:AF5,增益!$A:$A,增益!$W:$W,0))} -> 0
A6: 破竹 | F6: 单体奇术 | G6: =B19 -> 0 | K6: =($L6*$BN6+$M6*$BL6+$N6*$BO6+$O6*$BP6) -> 33649.981 | L6: =((($AN6+$AO6)/2*$AH6+$AI6)*(1+$AP6)*(1+$AQ6)+(($AS6+$AT6)/2*IF($G$1="鸣金",$AJ6,$AH6)+IF($G$1="鸣金",$AK6*1.5,0))*(1+$AU6)*(1+$AV6)+(($AW6+$AX6)/2*IF($G$1="裂石",$AJ6,$AH6)+IF($G$1="裂石",$AK6*1.5,0))*(1+$AY6)*(1+$AZ6)+(($BA6+$BB6)/2*IF($G$1="牵丝",$AJ6,$AH6)+IF($G$1="牵丝",$AK6*1.5,0))*(1+$BC6)*(1+$BD6)+(($BE6+$BF6)/2*IF($G$1="破竹",$AJ6,$AH6)+IF($G$1="破竹",$AK6*1.5,0))*(1+$BG6)*(1+$BH6))*(1+$AL6)*$BK6*$P6*(1+IF(VLOOKUP($Q6,武学奇术!$A:$ZZ,30,FALSE)="蓄力技",$B$21,0))*(1+$BQ6) -> 37203.332 | M6: =(($AO6*$AH6+$AI6)*(1+$AP6)*(1+$AQ6)+($AT6*IF($G$1="鸣金",$AJ6,$AH6)+IF($G$1="鸣金",$AK6*1.5,0))*(1+$AU6)*(1+$AV6)+($AX6*IF($G$1="裂石",$AJ6,$AH6)+IF($G$1="裂石",$AK6*1.5,0))*(1+$AY6)*(1+$AZ6)+($BB6*IF($G$1="牵丝",$AJ6,$AH6)+IF($G$1="牵丝",$AK6*1.5,0))*(1+$BC6)*(1+$BD6)+($BF6*IF($G$1="破竹",$AJ6,$AH6)+IF($G$1="破竹",$AK6*1.5,0))*(1+$BG6)*(1+$BH6))*(1+$AL6)*$BM6*$P6*(1+IF(VLOOKUP($Q6,武学奇术!$A:$ZZ,30,FALSE)="蓄力技",$B$21,0))*(1+$BQ6) -> 30435.05 | N6: =((($AN6+$AO6)/2*$AH6+$AI6)*(1+$AP6)*(1+$AQ6)+(($AS6+$AT6)/2*IF($G$1="鸣金",$AJ6,$AH6)+IF($G$1="鸣金",$AK6*1.5,0))*(1+$AU6)*(1+$AV6)+(($AW6+$AX6)/2*IF($G$1="裂石",$AJ6,$AH6)+IF($G$1="裂石",$AK6*1.5,0))*(1+$AY6)*(1+$AZ6)+(($BA6+$BB6)/2*IF($G$1="牵丝",$AJ6,$AH6)+IF($G$1="牵丝",$AK6*1.5,0))*(1+$BC6)*(1+$BD6)+(($BE6+$BF6)/2*IF($G$1="破竹",$AJ6,$AH6)+IF($G$1="破竹",$AK6*1.5,0))*(1+$BG6)*(1+$BH6))*(1+$AL6)*$P6*(1+IF(VLOOKUP($Q6,武学奇术!$A:$ZZ,30,FALSE)="蓄力技",$B$21,0))*(1+$BQ6) -> 20109.909 | O6: =((($AN6*$AH6+$AI6)*(1+$AP6)*(1+$AQ6)+($AS6*IF($G$1="鸣金",$AJ6,$AH6)+IF($G$1="鸣金",$AK6*1.5,0))*(1+$AU6)*(1+$AV6)+($AW6*IF($G$1="裂石",$AJ6,$AH6)+IF($G$1="裂石",$AK6*1.5,0))*(1+$AY6)*(1+$AZ6)+($BA6*IF($G$1="牵丝",$AJ6,$AH6)+IF($G$1="牵丝",$AK6*1.5,0))*(1+$BC6)*(1+$BD6)+($BE6*IF($G$1="破竹",$AJ6,$AH6)+IF($G$1="破竹",$AK6*1.5,0))*(1+$BG6)*(1+$BH6))*(1+$AL6))*$P6*(1+IF(VLOOKUP($Q6,武学奇术!$A:$ZZ,30,FALSE)="蓄力技",$B$21,0))*(1+$BQ6) -> 17675.337 | P6: 1 | Q6: 萧呤千浪流星 | R6: 易水歌5层 | S6: 胆寒 | T6: 惧刃 | U6: 穿喉5(普) | V6: N/a | W6: 近战笛 | X6: N/a | Y6: N/a | Z6: N/a | AA6: N/a | AB6: N/a | AC6: N/a | AD6: N/a | AE6: 铁花 | AF6: 铁衣 | AG6: =VLOOKUP($Q6,武学奇术!$A:$ZZ,25,FALSE) -> 群体奇术 | AH6: =VLOOKUP($Q6,武学奇术!$A:$ZZ,26,FALSE) -> 1.4902 | AI6: =VLOOKUP($Q6,武学奇术!$A:$ZZ,27,FALSE)*(1+IF(OR($AG6=$F$4,$AG6=$F$5),$B$22,0)) -> 358 | AJ6: =VLOOKUP($Q6,武学奇术!$A:$ZZ,28,FALSE) -> 2.2353 | AK6: =VLOOKUP($Q6,武学奇术!$A:$ZZ,29,FALSE)*(1+IF(OR($AG6=$F$4,$AG6=$F$5),$B$22,0)) -> 0 | AL6: {=$G$3+IFERROR(VLOOKUP($AG6,$F$4:$G$7,2,FALSE),0)+VLOOKUP($Q6,武学奇术!$A:$ZZ,2,FALSE)+SUM(_xlfn.XLOOKUP($R6:$AF6,增益!$A:$A,增益!$B:$B,0))} -> 0.733 | AM6: {=VLOOKUP($Q6,武学奇术!$A:$ZZ,5,FALSE)+SUM(_xlfn.XLOOKUP($R6:$AF6,增益!$A:$A,增益!$E:$E,0))} -> 0 | AN6: {=$D$10*(1+$AM6)+VLOOKUP($Q6,武学奇术!$A:$ZZ,3,FALSE)+SUM(_xlfn.XLOOKUP($R6:$AF6,增益!$A:$A,增益!$C:$C,0))-$I$2} -> 3052.34 | AO6: {=$E$10*(1+$AM6)+VLOOKUP($Q6,武学奇术!$A:$ZZ,4,FALSE)+SUM(_xlfn.XLOOKUP($R6:$AF6,增益!$A:$A,增益!$D:$D,0))-$I$2} -> 3052.34 | AP6: {=IF($F$10-$I$3+VLOOKUP($Q6,武学奇术!$A:$ZZ,6,FALSE)+SUM(_xlfn.XLOOKUP(R6:AF6,增益!$A:$A,增益!$F:$F,0))>0,($F$10-$I$3+VLOOKUP($Q6,武学奇术!$A:$ZZ,6,FALSE)+SUM(_xlfn.XLOOKUP(R6:AF6,增益!$A:$A,增益!$F:$F,0)))/200,($F$10-$I$3+VLOOKUP($Q6,武学奇术!$A:$ZZ,6,FALSE)+SUM(_xlfn.XLOOKUP(R6:AF6,增益!$A:$A,增益!$F:$F,0)))/100)} -> 0.442 | AQ6: {=$G$10+VLOOKUP($Q6,武学奇术!$A:$ZZ,7,FALSE)+SUM(_xlfn.XLOOKUP(R6:AF6,增益!$A:$A,增益!$G:$G,0))} -> 0 | AR6: {=VLOOKUP($Q6,武学奇术!$A:$ZZ,8,FALSE)+SUM(_xlfn.XLOOKUP(R6:AF6,增益!$A:$A,增益!$H:$H,0))} -> 0 | AS6: =$D$11*(1+$AR6) -> 0 | AT6: =$E$11*(1+$AR6) -> 0 | AU6: {=IF($F$11-$I$4+VLOOKUP($Q6,武学奇术!$A:$ZZ,9,FALSE)+SUM(_xlfn.XLOOKUP(R6:AF6,增益!$A:$A,增益!$I:$I,0))>0,($F$11-$I$4+VLOOKUP($Q6,武学奇术!$A:$ZZ,9,FALSE)+SUM(_xlfn.XLOOKUP(R6:AF6,增益!$A:$A,增益!$I:$I,0)))/200,($F$11-$I$4+VLOOKUP($Q6,武学奇术!$A:$ZZ,9,FALSE)+SUM(_xlfn.XLOOKUP(R6:AF6,增益!$A:$A,增益!$I:$I,0)))/100)} -> -0.08 | AV6: {=$G$11+VLOOKUP($Q6,武学奇术!$A:$ZZ,10,FALSE)+SUM(_xlfn.XLOOKUP(R6:AF6,增益!$A:$A,增益!$J:$J,0))} -> 0 | AW6: =$D$12*(1+$AR6) -> 634.5 | AX6: =$E$12*(1+$AR6) -> 1443.3 | AY6: {=IF($F$12-$I$4+VLOOKUP($Q6,武学奇术!$A:$ZZ,11,FALSE)+SUM(_xlfn.XLOOKUP(R6:AF6,增益!$A:$A,增益!$K:$K,0))>0,($F$12-$I$4+VLOOKUP($Q6,武学奇术!$A:$ZZ,11,FALSE)+SUM(_xlfn.XLOOKUP(R6:AF6,增益!$A:$A,增益!$K:$K,0)))/200,($F$12-$I$4+VLOOKUP($Q6,武学奇术!$A:$ZZ,11,FALSE)+SUM(_xlfn.XLOOKUP(R6:AF6,增益!$A:$A,增益!$K:$K,0)))/100)} -> 0.198 | AZ6: {=$G$12+VLOOKUP($Q6,武学奇术!$A:$ZZ,12,FALSE)+SUM(_xlfn.XLOOKUP(R6:AF6,增益!$A:$A,增益!$L:$L,0))} -> 0.148 | BA6: =$D$13*(1+$AR6) -> 0 | BB6: =$E$13*(1+$AR6) -> 0 | BC6: {=IF($F$13-$I$4+VLOOKUP($Q6,武学奇术!$A:$ZZ,13,FALSE)+SUM(_xlfn.XLOOKUP(R6:AF6,增益!$A:$A,增益!$M:$M,0))>0,($F$13-$I$4+VLOOKUP($Q6,武学奇术!$A:$ZZ,13,FALSE)+SUM(_xlfn.XLOOKUP(R6:AF6,增益!$A:$A,增益!$K:$K,0)))/200,($F$13-$I$4+VLOOKUP($Q6,武学奇术!$A:$ZZ,13,FALSE)+SUM(_xlfn.XLOOKUP(R6:AF6,增益!$A:$A,增益!$M:$M,0)))/100)} -> -0.08 | BD6: {=$G$13+VLOOKUP($Q6,武学奇术!$A:$ZZ,14,FALSE)+SUM(_xlfn.XLOOKUP(R6:AF6,增益!$A:$A,增益!$N:$N,0))} -> 0 | BE6: =$D$14*(1+$AR6) -> 0 | BF6: =$E$14*(1+$AR6) -> 0 | BG6: {=IF($F$14-$I$4+VLOOKUP($Q6,武学奇术!$A:$ZZ,15,FALSE)+SUM(_xlfn.XLOOKUP(R6:AF6,增益!$A:$A,增益!$O:$O,0))>0,($F$14-$I$4+VLOOKUP($Q6,武学奇术!$A:$ZZ,15,FALSE)+SUM(_xlfn.XLOOKUP(R6:AF6,增益!$A:$A,增益!$O:$O,0)))/200,($F$14-$I$4+VLOOKUP($Q6,武学奇术!$A:$ZZ,15,FALSE)+SUM(_xlfn.XLOOKUP(R6:AF6,增益!$A:$A,增益!$O:$O,0)))/100)} -> -0.08 | BH6: {=$G$14+VLOOKUP($Q6,武学奇术!$A:$ZZ,16,FALSE)+SUM(_xlfn.XLOOKUP(R6:AF6,增益!$A:$A,增益!$P:$P,0))} -> 0 | BI6: =MIN(IF(VLOOKUP($Q6,武学奇术!$A:$ZZ,23,FALSE)=1,100%,$B$8),100%) -> 0.8626 | BJ6: {=IF(VLOOKUP($Q6,武学奇术!$A:$ZZ,23,FALSE)=1,100%,MIN(80%,$B$9+VLOOKUP($Q6,武学奇术!$A:$ZZ,17,FALSE)+SUM(_xlfn.XLOOKUP(R6:AF6,增益!$A:$A,增益!$Q:$Q,0)))+$B$11+SUM(_xlfn.XLOOKUP(R6:AF6,增益!$A:$A,增益!$U:$U,0)))*IF(VLOOKUP($Q6,武学奇术!$A:$ZZ,24,FALSE)=1,0,1)} -> 0.8697 | BK6: {=1+$B$13+VLOOKUP($Q6,武学奇术!$A:$ZZ,18,FALSE)+SUM(_xlfn.XLOOKUP(R6:AF6,增益!$A:$A,增益!$R:$R,0))} -> 1.85 | BL6: {=IF(VLOOKUP($Q6,武学奇术!$A:$ZZ,24,FALSE)=1,100%,MIN(40%,$B$10+VLOOKUP($Q6,武学奇术!$A:$ZZ,19,FALSE)+SUM(_xlfn.XLOOKUP(R6:AF6,增益!$A:$A,增益!$S:$S,0)))+$B$12+SUM(_xlfn.XLOOKUP(R6:AF6,增益!$A:$A,增益!$V:$V,0)))*IF(VLOOKUP($Q6,武学奇术!$A:$ZZ,23,FALSE)=1,0,1)} -> 0.0986 | BM6: {=1+$B$14+VLOOKUP($Q6,武学奇术!$A:$ZZ,20,FALSE)+SUM(_xlfn.XLOOKUP(R6:AF6,增益!$A:$A,增益!$T:$T,0))} -> 1.35 | BN6: =MIN((1-BL6)*BI6,BI6*BJ6) -> 0.75020322 | BO6: =1-BL6-BN6-BP6 -> 0.02734442 | BP6: =IF(VLOOKUP($Q6,武学奇术!$A:$ZZ,22,FALSE)=1,0,(1-$BI6))*(1-$BL6) -> 0.12385236 | BQ6: {=SUM(_xlfn.XLOOKUP(R6:AF6,增益!$A:$A,增益!$W:$W,0))} -> 0.13
A7: 无相 | B7: 125.8 | C7: 185.6 | F7: 群体奇术 | G7: =B20 -> 0 | K7: =($L7*$BN7+$M7*$BL7+$N7*$BO7+$O7*$BP7) -> 65745.639 | L7: =((($AN7+$AO7)/2*$AH7+$AI7)*(1+$AP7)*(1+$AQ7)+(($AS7+$AT7)/2*IF($G$1="鸣金",$AJ7,$AH7)+IF($G$1="鸣金",$AK7*1.5,0))*(1+$AU7)*(1+$AV7)+(($AW7+$AX7)/2*IF($G$1="裂石",$AJ7,$AH7)+IF($G$1="裂石",$AK7*1.5,0))*(1+$AY7)*(1+$AZ7)+(($BA7+$BB7)/2*IF($G$1="牵丝",$AJ7,$AH7)+IF($G$1="牵丝",$AK7*1.5,0))*(1+$BC7)*(1+$BD7)+(($BE7+$BF7)/2*IF($G$1="破竹",$AJ7,$AH7)+IF($G$1="破竹",$AK7*1.5,0))*(1+$BG7)*(1+$BH7))*(1+$AL7)*$BK7*$P7*(1+IF(VLOOKUP($Q7,武学奇术!$A:$ZZ,30,FALSE)="蓄力技",$B$21,0))*(1+$BQ7) -> 71990.574 | M7: =(($AO7*$AH7+$AI7)*(1+$AP7)*(1+$AQ7)+($AT7*IF($G$1="鸣金",$AJ7,$AH7)+IF($G$1="鸣金",$AK7*1.5,0))*(1+$AU7)*(1+$AV7)+($AX7*IF($G$1="裂石",$AJ7,$AH7)+IF($G$1="裂石",$AK7*1.5,0))*(1+$AY7)*(1+$AZ7)+($BB7*IF($G$1="牵丝",$AJ7,$AH7)+IF($G$1="牵丝",$AK7*1.5,0))*(1+$BC7)*(1+$BD7)+($BF7*IF($G$1="破竹",$AJ7,$AH7)+IF($G$1="破竹",$AK7*1.5,0))*(1+$BG7)*(1+$BH7))*(1+$AL7)*$BM7*$P7*(1+IF(VLOOKUP($Q7,武学奇术!$A:$ZZ,30,FALSE)="蓄力技",$B$21,0))*(1+$BQ7) -> 61721.012 | N7: =((($AN7+$AO7)/2*$AH7+$AI7)*(1+$AP7)*(1+$AQ7)+(($AS7+$AT7)/2*IF($G$1="鸣金",$AJ7,$AH7)+IF($G$1="鸣金",$AK7*1.5,0))*(1+$AU7)*(1+$AV7)+(($AW7+$AX7)/2*IF($G$1="裂石",$AJ7,$AH7)+IF($G$1="裂石",$AK7*1.5,0))*(1+$AY7)*(1+$AZ7)+(($BA7+$BB7)/2*IF($G$1="牵丝",$AJ7,$AH7)+IF($G$1="牵丝",$AK7*1.5,0))*(1+$BC7)*(1+$BD7)+(($BE7+$BF7)/2*IF($G$1="破竹",$AJ7,$AH7)+IF($G$1="破竹",$AK7*1.5,0))*(1+$BG7)*(1+$BH7))*(1+$AL7)*$P7*(1+IF(VLOOKUP($Q7,武学奇术!$A:$ZZ,30,FALSE)="蓄力技",$B$21,0))*(1+$BQ7) -> 41137.471 | O7: =((($AN7*$AH7+$AI7)*(1+$AP7)*(1+$AQ7)+($AS7*IF($G$1="鸣金",$AJ7,$AH7)+IF($G$1="鸣金",$AK7*1.5,0))*(1+$AU7)*(1+$AV7)+($AW7*IF($G$1="裂石",$AJ7,$AH7)+IF($G$1="裂石",$AK7*1.5,0))*(1+$AY7)*(1+$AZ7)+($BA7*IF($G$1="牵丝",$AJ7,$AH7)+IF($G$1="牵丝",$AK7*1.5,0))*(1+$BC7)*(1+$BD7)+($BE7*IF($G$1="破竹",$AJ7,$AH7)+IF($G$1="破竹",$AK7*1.5,0))*(1+$BG7)*(1+$BH7))*(1+$AL7))*$P7*(1+IF(VLOOKUP($Q7,武学奇术!$A:$ZZ,30,FALSE)="蓄力技",$B$21,0))*(1+$BQ7) -> 36555.673 | P7: 1 | Q7: 横刀～ | R7: 易水歌1层 | S7: N/a | T7: N/a | U7: N/a | V7: N/a | W7: N/a | X7: N/a | Y7: N/a | Z7: N/a | AA7: N/a | AB7: N/a | AC7: N/a | AD7: N/a | AE7: N/a | AF7: 铁衣 | AG7: =VLOOKUP($Q7,武学奇术!$A:$ZZ,25,FALSE) -> 横刀 | AH7: =VLOOKUP($Q7,武学奇术!$A:$ZZ,26,FALSE) -> 3.7797 | AI7: =VLOOKUP($Q7,武学奇术!$A:$ZZ,27,FALSE)*(1+IF(OR($AG7=$F$4,$AG7=$F$5),$B$22,0)) -> 1358.5 | AJ7: =VLOOKUP($Q7,武学奇术!$A:$ZZ,28,FALSE) -> 5.6696 | AK7: =VLOOKUP($Q7,武学奇术!$A:$ZZ,29,FALSE)*(1+IF(OR($AG7=$F$4,$AG7=$F$5),$B$22,0)) -> 741 | AL7: {=$G$3+IFERROR(VLOOKUP($AG7,$F$4:$G$7,2,FALSE),0)+VLOOKUP($Q7,武学奇术!$A:$ZZ,2,FALSE)+SUM(_xlfn.XLOOKUP($R7:$AF7,增益!$A:$A,增益!$B:$B,0))} -> 0.557 | AM7: {=VLOOKUP($Q7,武学奇术!$A:$ZZ,5,FALSE)+SUM(_xlfn.XLOOKUP($R7:$AF7,增益!$A:$A,增益!$E:$E,0))} -> 0 | AN7: {=$D$10*(1+$AM7)+VLOOKUP($Q7,武学奇术!$A:$ZZ,3,FALSE)+SUM(_xlfn.XLOOKUP($R7:$AF7,增益!$A:$A,增益!$C:$C,0))-$I$2} -> 3052.34 | AO7: {=$E$10*(1+$AM7)+VLOOKUP($Q7,武学奇术!$A:$ZZ,4,FALSE)+SUM(_xlfn.XLOOKUP($R7:$AF7,增益!$A:$A,增益!$D:$D,0))-$I$2} -> 3052.34 | AP7: {=IF($F$10-$I$3+VLOOKUP($Q7,武学奇术!$A:$ZZ,6,FALSE)+SUM(_xlfn.XLOOKUP(R7:AF7,增益!$A:$A,增益!$F:$F,0))>0,($F$10-$I$3+VLOOKUP($Q7,武学奇术!$A:$ZZ,6,FALSE)+SUM(_xlfn.XLOOKUP(R7:AF7,增益!$A:$A,增益!$F:$F,0)))/200,($F$10-$I$3+VLOOKUP($Q7,武学奇术!$A:$ZZ,6,FALSE)+SUM(_xlfn.XLOOKUP(R7:AF7,增益!$A:$A,增益!$F:$F,0)))/100)} -> 0.352 | AQ7: {=$G$10+VLOOKUP($Q7,武学奇术!$A:$ZZ,7,FALSE)+SUM(_xlfn.XLOOKUP(R7:AF7,增益!$A:$A,增益!$G:$G,0))} -> 0 | AR7: {=VLOOKUP($Q7,武学奇术!$A:$ZZ,8,FALSE)+SUM(_xlfn.XLOOKUP(R7:AF7,增益!$A:$A,增益!$H:$H,0))} -> 0 | AS7: =$D$11*(1+$AR7) -> 0 | AT7: =$E$11*(1+$AR7) -> 0 | AU7: {=IF($F$11-$I$4+VLOOKUP($Q7,武学奇术!$A:$ZZ,9,FALSE)+SUM(_xlfn.XLOOKUP(R7:AF7,增益!$A:$A,增益!$I:$I,0))>0,($F$11-$I$4+VLOOKUP($Q7,武学奇术!$A:$ZZ,9,FALSE)+SUM(_xlfn.XLOOKUP(R7:AF7,增益!$A:$A,增益!$I:$I,0)))/200,($F$11-$I$4+VLOOKUP($Q7,武学奇术!$A:$ZZ,9,FALSE)+SUM(_xlfn.XLOOKUP(R7:AF7,增益!$A:$A,增益!$I:$I,0)))/100)} -> -0.24 | AV7: {=$G$11+VLOOKUP($Q7,武学奇术!$A:$ZZ,10,FALSE)+SUM(_xlfn.XLOOKUP(R7:AF7,增益!$A:$A,增益!$J:$J,0))} -> 0 | AW7: =$D$12*(1+$AR7) -> 634.5 | AX7: =$E$12*(1+$AR7) -> 1443.3 | AY7: {=IF($F$12-$I$4+VLOOKUP($Q7,武学奇术!$A:$ZZ,11,FALSE)+SUM(_xlfn.XLOOKUP(R7:AF7,增益!$A:$A,增益!$K:$K,0))>0,($F$12-$I$4+VLOOKUP($Q7,武学奇术!$A:$ZZ,11,FALSE)+SUM(_xlfn.XLOOKUP(R7:AF7,增益!$A:$A,增益!$K:$K,0)))/200,($F$12-$I$4+VLOOKUP($Q7,武学奇术!$A:$ZZ,11,FALSE)+SUM(_xlfn.XLOOKUP(R7:AF7,增益!$A:$A,增益!$K:$K,0)))/100)} -> 0.118 | AZ7: {=$G$12+VLOOKUP($Q7,武学奇术!$A:$ZZ,12,FALSE)+SUM(_xlfn.XLOOKUP(R7:AF7,增益!$A:$A,增益!$L:$L,0))} -> 0.148 | BA7: =$D$13*(1+$AR7) -> 0 | BB7: =$E$13*(1+$AR7) -> 0 | BC7: {=IF($F$13-$I$4+VLOOKUP($Q7,武学奇术!$A:$ZZ,13,FALSE)+SUM(_xlfn.XLOOKUP(R7:AF7,增益!$A:$A,增益!$M:$M,0))>0,($F$13-$I$4+VLOOKUP($Q7,武学奇术!$A:$ZZ,13,FALSE)+SUM(_xlfn.XLOOKUP(R7:AF7,增益!$A:$A,增益!$K:$K,0)))/200,($F$13-$I$4+VLOOKUP($Q7,武学奇术!$A:$ZZ,13,FALSE)+SUM(_xlfn.XLOOKUP(R7:AF7,增益!$A:$A,增益!$M:$M,0)))/100)} -> -0.24 | BD7: {=$G$13+VLOOKUP($Q7,武学奇术!$A:$ZZ,14,FALSE)+SUM(_xlfn.XLOOKUP(R7:AF7,增益!$A:$A,增益!$N:$N,0))} -> 0 | BE7: =$D$14*(1+$AR7) -> 0 | BF7: =$E$14*(1+$AR7) -> 0 | BG7: {=IF($F$14-$I$4+VLOOKUP($Q7,武学奇术!$A:$ZZ,15,FALSE)+SUM(_xlfn.XLOOKUP(R7:AF7,增益!$A:$A,增益!$O:$O,0))>0,($F$14-$I$4+VLOOKUP($Q7,武学奇术!$A:$ZZ,15,FALSE)+SUM(_xlfn.XLOOKUP(R7:AF7,增益!$A:$A,增益!$O:$O,0)))/200,($F$14-$I$4+VLOOKUP($Q7,武学奇术!$A:$ZZ,15,FALSE)+SUM(_xlfn.XLOOKUP(R7:AF7,增益!$A:$A,增益!$O:$O,0)))/100)} -> -0.24 | BH7: {=$G$14+VLOOKUP($Q7,武学奇术!$A:$ZZ,16,FALSE)+SUM(_xlfn.XLOOKUP(R7:AF7,增益!$A:$A,增益!$P:$P,0))} -> 0 | BI7: =MIN(IF(VLOOKUP($Q7,武学奇术!$A:$ZZ,23,FALSE)=1,100%,$B$8),100%) -> 0.8626 | BJ7: {=IF(VLOOKUP($Q7,武学奇术!$A:$ZZ,23,FALSE)=1,100%,MIN(80%,$B$9+VLOOKUP($Q7,武学奇术!$A:$ZZ,17,FALSE)+SUM(_xlfn.XLOOKUP(R7:AF7,增益!$A:$A,增益!$Q:$Q,0)))+$B$11+SUM(_xlfn.XLOOKUP(R7:AF7,增益!$A:$A,增益!$U:$U,0)))*IF(VLOOKUP($Q7,武学奇术!$A:$ZZ,24,FALSE)=1,0,1)} -> 0.8697 | BK7: {=1+$B$13+VLOOKUP($Q7,武学奇术!$A:$ZZ,18,FALSE)+SUM(_xlfn.XLOOKUP(R7:AF7,增益!$A:$A,增益!$R:$R,0))} -> 1.75 | BL7: {=IF(VLOOKUP($Q7,武学奇术!$A:$ZZ,24,FALSE)=1,100%,MIN(40%,$B$10+VLOOKUP($Q7,武学奇术!$A:$ZZ,19,FALSE)+SUM(_xlfn.XLOOKUP(R7:AF7,增益!$A:$A,增益!$S:$S,0)))+$B$12+SUM(_xlfn.XLOOKUP(R7:AF7,增益!$A:$A,增益!$V:$V,0)))*IF(VLOOKUP($Q7,武学奇术!$A:$ZZ,23,FALSE)=1,0,1)} -> 0.0986 | BM7: {=1+$B$14+VLOOKUP($Q7,武学奇术!$A:$ZZ,20,FALSE)+SUM(_xlfn.XLOOKUP(R7:AF7,增益!$A:$A,增益!$T:$T,0))} -> 1.35 | BN7: =MIN((1-BL7)*BI7,BI7*BJ7) -> 0.75020322 | BO7: =1-BL7-BN7-BP7 -> 0.02734442 | BP7: =IF(VLOOKUP($Q7,武学奇术!$A:$ZZ,22,FALSE)=1,0,(1-$BI7))*(1-$BL7) -> 0.12385236 | BQ7: {=SUM(_xlfn.XLOOKUP(R7:AF7,增益!$A:$A,增益!$W:$W,0))} -> 0
A8: 精准率 | B8: 0.8626 | C8: 实际属性 | H8: 战斗时间 | I8: 95 | K8: =($L8*$BN8+$M8*$BL8+$N8*$BO8+$O8*$BP8) -> 39478.841 | L8: =((($AN8+$AO8)/2*$AH8+$AI8)*(1+$AP8)*(1+$AQ8)+(($AS8+$AT8)/2*IF($G$1="鸣金",$AJ8,$AH8)+IF($G$1="鸣金",$AK8*1.5,0))*(1+$AU8)*(1+$AV8)+(($AW8+$AX8)/2*IF($G$1="裂石",$AJ8,$AH8)+IF($G$1="裂石",$AK8*1.5,0))*(1+$AY8)*(1+$AZ8)+(($BA8+$BB8)/2*IF($G$1="牵丝",$AJ8,$AH8)+IF($G$1="牵丝",$AK8*1.5,0))*(1+$BC8)*(1+$BD8)+(($BE8+$BF8)/2*IF($G$1="破竹",$AJ8,$AH8)+IF($G$1="破竹",$AK8*1.5,0))*(1+$BG8)*(1+$BH8))*(1+$AL8)*$BK8*$P8*(1+IF(VLOOKUP($Q8,武学奇术!$A:$ZZ,30,FALSE)="蓄力技",$B$21,0))*(1+$BQ8) -> 43228.793 | M8: =(($AO8*$AH8+$AI8)*(1+$AP8)*(1+$AQ8)+($AT8*IF($G$1="鸣金",$AJ8,$AH8)+IF($G$1="鸣金",$AK8*1.5,0))*(1+$AU8)*(1+$AV8)+($AX8*IF($G$1="裂石",$AJ8,$AH8)+IF($G$1="裂石",$AK8*1.5,0))*(1+$AY8)*(1+$AZ8)+($BB8*IF($G$1="牵丝",$AJ8,$AH8)+IF($G$1="牵丝",$AK8*1.5,0))*(1+$BC8)*(1+$BD8)+($BF8*IF($G$1="破竹",$AJ8,$AH8)+IF($G$1="破竹",$AK8*1.5,0))*(1+$BG8)*(1+$BH8))*(1+$AL8)*$BM8*$P8*(1+IF(VLOOKUP($Q8,武学奇术!$A:$ZZ,30,FALSE)="蓄力技",$B$21,0))*(1+$BQ8) -> 37061.662 | N8: =((($AN8+$AO8)/2*$AH8+$AI8)*(1+$AP8)*(1+$AQ8)+(($AS8+$AT8)/2*IF($G$1="鸣金",$AJ8,$AH8)+IF($G$1="鸣金",$AK8*1.5,0))*(1+$AU8)*(1+$AV8)+(($AW8+$AX8)/2*IF($G$1="裂石",$AJ8,$AH8)+IF($G$1="裂石",$AK8*1.5,0))*(1+$AY8)*(1+$AZ8)+(($BA8+$BB8)/2*IF($G$1="牵丝",$AJ8,$AH8)+IF($G$1="牵丝",$AK8*1.5,0))*(1+$BC8)*(1+$BD8)+(($BE8+$BF8)/2*IF($G$1="破竹",$AJ8,$AH8)+IF($G$1="破竹",$AK8*1.5,0))*(1+$BG8)*(1+$BH8))*(1+$AL8)*$P8*(1+IF(VLOOKUP($Q8,武学奇术!$A:$ZZ,30,FALSE)="蓄力技",$B$21,0))*(1+$BQ8) -> 24702.168 | O8: =((($AN8*$AH8+$AI8)*(1+$AP8)*(1+$AQ8)+($AS8*IF($G$1="鸣金",$AJ8,$AH8)+IF($G$1="鸣金",$AK8*1.5,0))*(1+$AU8)*(1+$AV8)+($AW8*IF($G$1="裂石",$AJ8,$AH8)+IF($G$1="裂石",$AK8*1.5,0))*(1+$AY8)*(1+$AZ8)+($BA8*IF($G$1="牵丝",$AJ8,$AH8)+IF($G$1="牵丝",$AK8*1.5,0))*(1+$BC8)*(1+$BD8)+($BE8*IF($G$1="破竹",$AJ8,$AH8)+IF($G$1="破竹",$AK8*1.5,0))*(1+$BG8)*(1+$BH8))*(1+$AL8))*$P8*(1+IF(VLOOKUP($Q8,武学奇术!$A:$ZZ,30,FALSE)="蓄力技",$B$21,0))*(1+$BQ8) -> 21951.252 | P8: 1 | Q8: 白刃杀将刺 | R8: 易水歌1层 | S8: N/a | T8: N/a | U8: N/a | V8: N/a | W8: 近战笛 | X8: N/a | Y8: N/a | Z8: N/a | AA8: 断岳 | AB8: N/a | AC8: N/a | AD8: N/a | AE8: N/a | AF8: 铁衣 | AG8: =VLOOKUP($Q8,武学奇术!$A:$ZZ,25,FALSE) -> 横刀 | AH8: =VLOOKUP($Q8,武学奇术!$A:$ZZ,26,FALSE) -> 2.1324 | AI8: =VLOOKUP($Q8,武学奇术!$A:$ZZ,27,FALSE)*(1+IF(OR($AG8=$F$4,$AG8=$F$5),$B$22,0)) -> 767 | AJ8: =VLOOKUP($Q8,武学奇术!$A:$ZZ,28,FALSE) -> 3.1986 | AK8: =VLOOKUP($Q8,武学奇术!$A:$ZZ,29,FALSE)*(1+IF(OR($AG8=$F$4,$AG8=$F$5),$B$22,0)) -> 418.6 | AL8: {=$G$3+IFERROR(VLOOKUP($AG8,$F$4:$G$7,2,FALSE),0)+VLOOKUP($Q8,武学奇术!$A:$ZZ,2,FALSE)+SUM(_xlfn.XLOOKUP($R8:$AF8,增益!$A:$A,增益!$B:$B,0))} -> 0.657 | AM8: {=VLOOKUP($Q8,武学奇术!$A:$ZZ,5,FALSE)+SUM(_xlfn.XLOOKUP($R8:$AF8,增益!$A:$A,增益!$E:$E,0))} -> 0 | AN8: {=$D$10*(1+$AM8)+VLOOKUP($Q8,武学奇术!$A:$ZZ,3,FALSE)+SUM(_xlfn.XLOOKUP($R8:$AF8,增益!$A:$A,增益!$C:$C,0))-$I$2} -> 3052.34 | AO8: {=$E$10*(1+$AM8)+VLOOKUP($Q8,武学奇术!$A:$ZZ,4,FALSE)+SUM(_xlfn.XLOOKUP($R8:$AF8,增益!$A:$A,增益!$D:$D,0))-$I$2} -> 3052.34 | AP8: {=IF($F$10-$I$3+VLOOKUP($Q8,武学奇术!$A:$ZZ,6,FALSE)+SUM(_xlfn.XLOOKUP(R8:AF8,增益!$A:$A,增益!$F:$F,0))>0,($F$10-$I$3+VLOOKUP($Q8,武学奇术!$A:$ZZ,6,FALSE)+SUM(_xlfn.XLOOKUP(R8:AF8,增益!$A:$A,增益!$F:$F,0)))/200,($F$10-$I$3+VLOOKUP($Q8,武学奇术!$A:$ZZ,6,FALSE)+SUM(_xlfn.XLOOKUP(R8:AF8,增益!$A:$A,增益!$F:$F,0)))/100)} -> 0.352 | AQ8: {=$G$10+VLOOKUP($Q8,武学奇术!$A:$ZZ,7,FALSE)+SUM(_xlfn.XLOOKUP(R8:AF8,增益!$A:$A,增益!$G:$G,0))} -> 0 | AR8: {=VLOOKUP($Q8,武学奇术!$A:$ZZ,8,FALSE)+SUM(_xlfn.XLOOKUP(R8:AF8,增益!$A:$A,增益!$H:$H,0))} -> 0 | AS8: =$D$11*(1+$AR8) -> 0 | AT8: =$E$11*(1+$AR8) -> 0 | AU8: {=IF($F$11-$I$4+VLOOKUP($Q8,武学奇术!$A:$ZZ,9,FALSE)+SUM(_xlfn.XLOOKUP(R8:AF8,增益!$A:$A,增益!$I:$I,0))>0,($F$11-$I$4+VLOOKUP($Q8,武学奇术!$A:$ZZ,9,FALSE)+SUM(_xlfn.XLOOKUP(R8:AF8,增益!$A:$A,增益!$I:$I,0)))/200,($F$11-$I$4+VLOOKUP($Q8,武学奇术!$A:$ZZ,9,FALSE)+SUM(_xlfn.XLOOKUP(R8:AF8,增益!$A:$A,增益!$I:$I,0)))/100)} -> -0.24 | AV8: {=$G$11+VLOOKUP($Q8,武学奇术!$A:$ZZ,10,FALSE)+SUM(_xlfn.XLOOKUP(R8:AF8,增益!$A:$A,增益!$J:$J,0))} -> 0 | AW8: =$D$12*(1+$AR8) -> 634.5 | AX8: =$E$12*(1+$AR8) -> 1443.3 | AY8: {=IF($F$12-$I$4+VLOOKUP($Q8,武学奇术!$A:$ZZ,11,FALSE)+SUM(_xlfn.XLOOKUP(R8:AF8,增益!$A:$A,增益!$K:$K,0))>0,($F$12-$I$4+VLOOKUP($Q8,武学奇术!$A:$ZZ,11,FALSE)+SUM(_xlfn.XLOOKUP(R8:AF8,增益!$A:$A,增益!$K:$K,0)))/200,($F$12-$I$4+VLOOKUP($Q8,武学奇术!$A:$ZZ,11,FALSE)+SUM(_xlfn.XLOOKUP(R8:AF8,增益!$A:$A,增益!$K:$K,0)))/100)} -> 0.118 | AZ8: {=$G$12+VLOOKUP($Q8,武学奇术!$A:$ZZ,12,FALSE)+SUM(_xlfn.XLOOKUP(R8:AF8,增益!$A:$A,增益!$L:$L,0))} -> 0.148 | BA8: =$D$13*(1+$AR8) -> 0 | BB8: =$E$13*(1+$AR8) -> 0 | BC8: {=IF($F$13-$I$4+VLOOKUP($Q8,武学奇术!$A:$ZZ,13,FALSE)+SUM(_xlfn.XLOOKUP(R8:AF8,增益!$A:$A,增益!$M:$M,0))>0,($F$13-$I$4+VLOOKUP($Q8,武学奇术!$A:$ZZ,13,FALSE)+SUM(_xlfn.XLOOKUP(R8:AF8,增益!$A:$A,增益!$K:$K,0)))/200,($F$13-$I$4+VLOOKUP($Q8,武学奇术!$A:$ZZ,13,FALSE)+SUM(_xlfn.XLOOKUP(R8:AF8,增益!$A:$A,增益!$M:$M,0)))/100)} -> -0.24 | BD8: {=$G$13+VLOOKUP($Q8,武学奇术!$A:$ZZ,14,FALSE)+SUM(_xlfn.XLOOKUP(R8:AF8,增益!$A:$A,增益!$N:$N,0))} -> 0 | BE8: =$D$14*(1+$AR8) -> 0 | BF8: =$E$14*(1+$AR8) -> 0 | BG8: {=IF($F$14-$I$4+VLOOKUP($Q8,武学奇术!$A:$ZZ,15,FALSE)+SUM(_xlfn.XLOOKUP(R8:AF8,增益!$A:$A,增益!$O:$O,0))>0,($F$14-$I$4+VLOOKUP($Q8,武学奇术!$A:$ZZ,15,FALSE)+SUM(_xlfn.XLOOKUP(R8:AF8,增益!$A:$A,增益!$O:$O,0)))/200,($F$14-$I$4+VLOOKUP($Q8,武学奇术!$A:$ZZ,15,FALSE)+SUM(_xlfn.XLOOKUP(R8:AF8,增益!$A:$A,增益!$O:$O,0)))/100)} -> -0.24 | BH8: {=$G$14+VLOOKUP($Q8,武学奇术!$A:$ZZ,16,FALSE)+SUM(_xlfn.XLOOKUP(R8:AF8,增益!$A:$A,增益!$P:$P,0))} -> 0 | BI8: =MIN(IF(VLOOKUP($Q8,武学奇术!$A:$ZZ,23,FALSE)=1,100%,$B$8),100%) -> 0.8626 | BJ8: {=IF(VLOOKUP($Q8,武学奇术!$A:$ZZ,23,FALSE)=1,100%,MIN(80%,$B$9+VLOOKUP($Q8,武学奇术!$A:$ZZ,17,FALSE)+SUM(_xlfn.XLOOKUP(R8:AF8,增益!$A:$A,增益!$Q:$Q,0)))+$B$11+SUM(_xlfn.XLOOKUP(R8:AF8,增益!$A:$A,增益!$U:$U,0)))*IF(VLOOKUP($Q8,武学奇术!$A:$ZZ,24,FALSE)=1,0,1)} -> 0.8697 | BK8: {=1+$B$13+VLOOKUP($Q8,武学奇术!$A:$ZZ,18,FALSE)+SUM(_xlfn.XLOOKUP(R8:AF8,增益!$A:$A,增益!$R:$R,0))} -> 1.75 | BL8: {=IF(VLOOKUP($Q8,武学奇术!$A:$ZZ,24,FALSE)=1,100%,MIN(40%,$B$10+VLOOKUP($Q8,武学奇术!$A:$ZZ,19,FALSE)+SUM(_xlfn.XLOOKUP(R8:AF8,增益!$A:$A,增益!$S:$S,0)))+$B$12+SUM(_xlfn.XLOOKUP(R8:AF8,增益!$A:$A,增益!$V:$V,0)))*IF(VLOOKUP($Q8,武学奇术!$A:$ZZ,23,FALSE)=1,0,1)} -> 0.0986 | BM8: {=1+$B$14+VLOOKUP($Q8,武学奇术!$A:$ZZ,20,FALSE)+SUM(_xlfn.XLOOKUP(R8:AF8,增益!$A:$A,增益!$T:$T,0))} -> 1.35 | BN8: =MIN((1-BL8)*BI8,BI8*BJ8) -> 0.75020322 | BO8: =1-BL8-BN8-BP8 -> 0.02734442 | BP8: =IF(VLOOKUP($Q8,武学奇术!$A:$ZZ,22,FALSE)=1,0,(1-$BI8))*(1-$BL8) -> 0.12385236 | BQ8: {=SUM(_xlfn.XLOOKUP(R8:AF8,增益!$A:$A,增益!$W:$W,0))} -> 0
A9: 会心率 | B9: 0.7777 | D9: 最小攻击 | E9: 最大攻击 | F9: 穿透 | G9: 伤害加成 | K9: =($L9*$BN9+$M9*$BL9+$N9*$BO9+$O9*$BP9) -> 26322.619 | L9: =((($AN9+$AO9)/2*$AH9+$AI9)*(1+$AP9)*(1+$AQ9)+(($AS9+$AT9)/2*IF($G$1="鸣金",$AJ9,$AH9)+IF($G$1="鸣金",$AK9*1.5,0))*(1+$AU9)*(1+$AV9)+(($AW9+$AX9)/2*IF($G$1="裂石",$AJ9,$AH9)+IF($G$1="裂石",$AK9*1.5,0))*(1+$AY9)*(1+$AZ9)+(($BA9+$BB9)/2*IF($G$1="牵丝",$AJ9,$AH9)+IF($G$1="牵丝",$AK9*1.5,0))*(1+$BC9)*(1+$BD9)+(($BE9+$BF9)/2*IF($G$1="破竹",$AJ9,$AH9)+IF($G$1="破竹",$AK9*1.5,0))*(1+$BG9)*(1+$BH9))*(1+$AL9)*$BK9*$P9*(1+IF(VLOOKUP($Q9,武学奇术!$A:$ZZ,30,FALSE)="蓄力技",$B$21,0))*(1+$BQ9) -> 28819.396 | M9: =(($AO9*$AH9+$AI9)*(1+$AP9)*(1+$AQ9)+($AT9*IF($G$1="鸣金",$AJ9,$AH9)+IF($G$1="鸣金",$AK9*1.5,0))*(1+$AU9)*(1+$AV9)+($AX9*IF($G$1="裂石",$AJ9,$AH9)+IF($G$1="裂石",$AK9*1.5,0))*(1+$AY9)*(1+$AZ9)+($BB9*IF($G$1="牵丝",$AJ9,$AH9)+IF($G$1="牵丝",$AK9*1.5,0))*(1+$BC9)*(1+$BD9)+($BF9*IF($G$1="破竹",$AJ9,$AH9)+IF($G$1="破竹",$AK9*1.5,0))*(1+$BG9)*(1+$BH9))*(1+$AL9)*$BM9*$P9*(1+IF(VLOOKUP($Q9,武学奇术!$A:$ZZ,30,FALSE)="蓄力技",$B$21,0))*(1+$BQ9) -> 25175.898 | N9: =((($AN9+$AO9)/2*$AH9+$AI9)*(1+$AP9)*(1+$AQ9)+(($AS9+$AT9)/2*IF($G$1="鸣金",$AJ9,$AH9)+IF($G$1="鸣金",$AK9*1.5,0))*(1+$AU9)*(1+$AV9)+(($AW9+$AX9)/2*IF($G$1="裂石",$AJ9,$AH9)+IF($G$1="裂石",$AK9*1.5,0))*(1+$AY9)*(1+$AZ9)+(($BA9+$BB9)/2*IF($G$1="牵丝",$AJ9,$AH9)+IF($G$1="牵丝",$AK9*1.5,0))*(1+$BC9)*(1+$BD9)+(($BE9+$BF9)/2*IF($G$1="破竹",$AJ9,$AH9)+IF($G$1="破竹",$AK9*1.5,0))*(1+$BG9)*(1+$BH9))*(1+$AL9)*$P9*(1+IF(VLOOKUP($Q9,武学奇术!$A:$ZZ,30,FALSE)="蓄力技",$B$21,0))*(1+$BQ9) -> 16468.226 | O9: =((($AN9*$AH9+$AI9)*(1+$AP9)*(1+$AQ9)+($AS9*IF($G$1="鸣金",$AJ9,$AH9)+IF($G$1="鸣金",$AK9*1.5,0))*(1+$AU9)*(1+$AV9)+($AW9*IF($G$1="裂石",$AJ9,$AH9)+IF($G$1="裂石",$AK9*1.5,0))*(1+$AY9)*(1+$AZ9)+($BA9*IF($G$1="牵丝",$AJ9,$AH9)+IF($G$1="牵丝",$AK9*1.5,0))*(1+$BC9)*(1+$BD9)+($BE9*IF($G$1="破竹",$AJ9,$AH9)+IF($G$1="破竹",$AK9*1.5,0))*(1+$BG9)*(1+$BH9))*(1+$AL9))*$P9*(1+IF(VLOOKUP($Q9,武学奇术!$A:$ZZ,30,FALSE)="蓄力技",$B$21,0))*(1+$BQ9) -> 14287.639 | P9: 1 | Q9: 横刀安西军 | R9: 易水歌2层 | S9: 胆寒 | T9: 惧刃 | U9: N/a | V9: N/a | W9: 近战笛 | X9: N/a | Y9: N/a | Z9: N/a | AA9: 断岳 | AB9: N/a | AC9: N/a | AD9: N/a | AE9: N/a | AF9: 铁衣 | AG9: =VLOOKUP($Q9,武学奇术!$A:$ZZ,25,FALSE) -> 横刀 | AH9: =VLOOKUP($Q9,武学奇术!$A:$ZZ,26,FALSE) -> 1.4 | AI9: =VLOOKUP($Q9,武学奇术!$A:$ZZ,27,FALSE)*(1+IF(OR($AG9=$F$4,$AG9=$F$5),$B$22,0)) -> 0 | AJ9: =VLOOKUP($Q9,武学奇术!$A:$ZZ,28,FALSE) -> 2.1 | AK9: =VLOOKUP($Q9,武学奇术!$A:$ZZ,29,FALSE)*(1+IF(OR($AG9=$F$4,$AG9=$F$5),$B$22,0)) -> 0 | AL9: {=$G$3+IFERROR(VLOOKUP($AG9,$F$4:$G$7,2,FALSE),0)+VLOOKUP($Q9,武学奇术!$A:$ZZ,2,FALSE)+SUM(_xlfn.XLOOKUP($R9:$AF9,增益!$A:$A,增益!$B:$B,0))} -> 0.867 | AM9: {=VLOOKUP($Q9,武学奇术!$A:$ZZ,5,FALSE)+SUM(_xlfn.XLOOKUP($R9:$AF9,增益!$A:$A,增益!$E:$E,0))} -> 0 | AN9: {=$D$10*(1+$AM9)+VLOOKUP($Q9,武学奇术!$A:$ZZ,3,FALSE)+SUM(_xlfn.XLOOKUP($R9:$AF9,增益!$A:$A,增益!$C:$C,0))-$I$2} -> 3052.34 | AO9: {=$E$10*(1+$AM9)+VLOOKUP($Q9,武学奇术!$A:$ZZ,4,FALSE)+SUM(_xlfn.XLOOKUP($R9:$AF9,增益!$A:$A,增益!$D:$D,0))-$I$2} -> 3052.34 | AP9: {=IF($F$10-$I$3+VLOOKUP($Q9,武学奇术!$A:$ZZ,6,FALSE)+SUM(_xlfn.XLOOKUP(R9:AF9,增益!$A:$A,增益!$F:$F,0))>0,($F$10-$I$3+VLOOKUP($Q9,武学奇术!$A:$ZZ,6,FALSE)+SUM(_xlfn.XLOOKUP(R9:AF9,增益!$A:$A,增益!$F:$F,0)))/200,($F$10-$I$3+VLOOKUP($Q9,武学奇术!$A:$ZZ,6,FALSE)+SUM(_xlfn.XLOOKUP(R9:AF9,增益!$A:$A,增益!$F:$F,0)))/100)} -> 0.362 | AQ9: {=$G$10+VLOOKUP($Q9,武学奇术!$A:$ZZ,7,FALSE)+SUM(_xlfn.XLOOKUP(R9:AF9,增益!$A:$A,增益!$G:$G,0))} -> 0 | AR9: {=VLOOKUP($Q9,武学奇术!$A:$ZZ,8,FALSE)+SUM(_xlfn.XLOOKUP(R9:AF9,增益!$A:$A,增益!$H:$H,0))} -> 0 | AS9: =$D$11*(1+$AR9) -> 0 | AT9: =$E$11*(1+$AR9) -> 0 | AU9: {=IF($F$11-$I$4+VLOOKUP($Q9,武学奇术!$A:$ZZ,9,FALSE)+SUM(_xlfn.XLOOKUP(R9:AF9,增益!$A:$A,增益!$I:$I,0))>0,($F$11-$I$4+VLOOKUP($Q9,武学奇术!$A:$ZZ,9,FALSE)+SUM(_xlfn.XLOOKUP(R9:AF9,增益!$A:$A,增益!$I:$I,0)))/200,($F$11-$I$4+VLOOKUP($Q9,武学奇术!$A:$ZZ,9,FALSE)+SUM(_xlfn.XLOOKUP(R9:AF9,增益!$A:$A,增益!$I:$I,0)))/100)} -> -0.08 | AV9: {=$G$11+VLOOKUP($Q9,武学奇术!$A:$ZZ,10,FALSE)+SUM(_xlfn.XLOOKUP(R9:AF9,增益!$A:$A,增益!$J:$J,0))} -> 0 | AW9: =$D$12*(1+$AR9) -> 634.5 | AX9: =$E$12*(1+$AR9) -> 1443.3 | AY9: {=IF($F$12-$I$4+VLOOKUP($Q9,武学奇术!$A:$ZZ,11,FALSE)+SUM(_xlfn.XLOOKUP(R9:AF9,增益!$A:$A,增益!$K:$K,0))>0,($F$12-$I$4+VLOOKUP($Q9,武学奇术!$A:$ZZ,11,FALSE)+SUM(_xlfn.XLOOKUP(R9:AF9,增益!$A:$A,增益!$K:$K,0)))/200,($F$12-$I$4+VLOOKUP($Q9,武学奇术!$A:$ZZ,11,FALSE)+SUM(_xlfn.XLOOKUP(R9:AF9,增益!$A:$A,增益!$K:$K,0)))/100)} -> 0.198 | AZ9: {=$G$12+VLOOKUP($Q9,武学奇术!$A:$ZZ,12,FALSE)+SUM(_xlfn.XLOOKUP(R9:AF9,增益!$A:$A,增益!$L:$L,0))} -> 0.148 | BA9: =$D$13*(1+$AR9) -> 0 | BB9: =$E$13*(1+$AR9) -> 0 | BC9: {=IF($F$13-$I$4+VLOOKUP($Q9,武学奇术!$A:$ZZ,13,FALSE)+SUM(_xlfn.XLOOKUP(R9:AF9,增益!$A:$A,增益!$M:$M,0))>0,($F$13-$I$4+VLOOKUP($Q9,武学奇术!$A:$ZZ,13,FALSE)+SUM(_xlfn.XLOOKUP(R9:AF9,增益!$A:$A,增益!$K:$K,0)))/200,($F$13-$I$4+VLOOKUP($Q9,武学奇术!$A:$ZZ,13,FALSE)+SUM(_xlfn.XLOOKUP(R9:AF9,增益!$A:$A,增益!$M:$M,0)))/100)} -> -0.08 | BD9: {=$G$13+VLOOKUP($Q9,武学奇术!$A:$ZZ,14,FALSE)+SUM(_xlfn.XLOOKUP(R9:AF9,增益!$A:$A,增益!$N:$N,0))} -> 0 | BE9: =$D$14*(1+$AR9) -> 0 | BF9: =$E$14*(1+$AR9) -> 0 | BG9: {=IF($F$14-$I$4+VLOOKUP($Q9,武学奇术!$A:$ZZ,15,FALSE)+SUM(_xlfn.XLOOKUP(R9:AF9,增益!$A:$A,增益!$O:$O,0))>0,($F$14-$I$4+VLOOKUP($Q9,武学奇术!$A:$ZZ,15,FALSE)+SUM(_xlfn.XLOOKUP(R9:AF9,增益!$A:$A,增益!$O:$O,0)))/200,($F$14-$I$4+VLOOKUP($Q9,武学奇术!$A:$ZZ,15,FALSE)+SUM(_xlfn.XLOOKUP(R9:AF9,增益!$A:$A,增益!$O:$O,0)))/100)} -> -0.08 | BH9: {=$G$14+VLOOKUP($Q9,武学奇术!$A:$ZZ,16,FALSE)+SUM(_xlfn.XLOOKUP(R9:AF9,增益!$A:$A,增益!$P:$P,0))} -> 0 | BI9: =MIN(IF(VLOOKUP($Q9,武学奇术!$A:$ZZ,23,FALSE)=1,100%,$B$8),100%) -> 0.8626 | BJ9: {=IF(VLOOKUP($Q9,武学奇术!$A:$ZZ,23,FALSE)=1,100%,MIN(80%,$B$9+VLOOKUP($Q9,武学奇术!$A:$ZZ,17,FALSE)+SUM(_xlfn.XLOOKUP(R9:AF9,增益!$A:$A,增益!$Q:$Q,0)))+$B$11+SUM(_xlfn.XLOOKUP(R9:AF9,增益!$A:$A,增益!$U:$U,0)))*IF(VLOOKUP($Q9,武学奇术!$A:$ZZ,24,FALSE)=1,0,1)} -> 0.8697 | BK9: {=1+$B$13+VLOOKUP($Q9,武学奇术!$A:$ZZ,18,FALSE)+SUM(_xlfn.XLOOKUP(R9:AF9,增益!$A:$A,增益!$R:$R,0))} -> 1.75 | BL9: {=IF(VLOOKUP($Q9,武学奇术!$A:$ZZ,24,FALSE)=1,100%,MIN(40%,$B$10+VLOOKUP($Q9,武学奇术!$A:$ZZ,19,FALSE)+SUM(_xlfn.XLOOKUP(R9:AF9,增益!$A:$A,增益!$S:$S,0)))+$B$12+SUM(_xlfn.XLOOKUP(R9:AF9,增益!$A:$A,增益!$V:$V,0)))*IF(VLOOKUP($Q9,武学奇术!$A:$ZZ,23,FALSE)=1,0,1)} -> 0.0986 | BM9: {=1+$B$14+VLOOKUP($Q9,武学奇术!$A:$ZZ,20,FALSE)+SUM(_xlfn.XLOOKUP(R9:AF9,增益!$A:$A,增益!$T:$T,0))} -> 1.35 | BN9: =MIN((1-BL9)*BI9,BI9*BJ9) -> 0.75020322 | BO9: =1-BL9-BN9-BP9 -> 0.02734442 | BP9: =IF(VLOOKUP($Q9,武学奇术!$A:$ZZ,22,FALSE)=1,0,(1-$BI9))*(1-$BL9) -> 0.12385236 | BQ9: {=SUM(_xlfn.XLOOKUP(R9:AF9,增益!$A:$A,增益!$W:$W,0))} -> 0
A10: 会意率 | B10: 0.0986 | C10: 外功 | D10: =B2+B23 -> 3577.8 | E10: =MAX(B2+B23,C2+B24) -> 3577.8 | F10: =D2 -> 58.4 | G10: =E2 -> 0 | H10: 总伤 | I10: =SUM(K:K) -> 12310888 | K10: =($L10*$BN10+$M10*$BL10+$N10*$BO10+$O10*$BP10) -> 14326.982 | L10: =((($AN10+$AO10)/2*$AH10+$AI10)*(1+$AP10)*(1+$AQ10)+(($AS10+$AT10)/2*IF($G$1="鸣金",$AJ10,$AH10)+IF($G$1="鸣金",$AK10*1.5,0))*(1+$AU10)*(1+$AV10)+(($AW10+$AX10)/2*IF($G$1="裂石",$AJ10,$AH10)+IF($G$1="裂石",$AK10*1.5,0))*(1+$AY10)*(1+$AZ10)+(($BA10+$BB10)/2*IF($G$1="牵丝",$AJ10,$AH10)+IF($G$1="牵丝",$AK10*1.5,0))*(1+$BC10)*(1+$BD10)+(($BE10+$BF10)/2*IF($G$1="破竹",$AJ10,$AH10)+IF($G$1="破竹",$AK10*1.5,0))*(1+$BG10)*(1+$BH10))*(1+$AL10)*$BK10*$P10*(1+IF(VLOOKUP($Q10,武学奇术!$A:$ZZ,30,FALSE)="蓄力技",$B$21,0))*(1+$BQ10) -> 15868.163 | M10: =(($AO10*$AH10+$AI10)*(1+$AP10)*(1+$AQ10)+($AT10*IF($G$1="鸣金",$AJ10,$AH10)+IF($G$1="鸣金",$AK10*1.5,0))*(1+$AU10)*(1+$AV10)+($AX10*IF($G$1="裂石",$AJ10,$AH10)+IF($G$1="裂石",$AK10*1.5,0))*(1+$AY10)*(1+$AZ10)+($BB10*IF($G$1="牵丝",$AJ10,$AH10)+IF($G$1="牵丝",$AK10*1.5,0))*(1+$BC10)*(1+$BD10)+($BF10*IF($G$1="破竹",$AJ10,$AH10)+IF($G$1="破竹",$AK10*1.5,0))*(1+$BG10)*(1+$BH10))*(1+$AL10)*$BM10*$P10*(1+IF(VLOOKUP($Q10,武学奇术!$A:$ZZ,30,FALSE)="蓄力技",$B$21,0))*(1+$BQ10) -> 12929.639 | N10: =((($AN10+$AO10)/2*$AH10+$AI10)*(1+$AP10)*(1+$AQ10)+(($AS10+$AT10)/2*IF($G$1="鸣金",$AJ10,$AH10)+IF($G$1="鸣金",$AK10*1.5,0))*(1+$AU10)*(1+$AV10)+(($AW10+$AX10)/2*IF($G$1="裂石",$AJ10,$AH10)+IF($G$1="裂石",$AK10*1.5,0))*(1+$AY10)*(1+$AZ10)+(($BA10+$BB10)/2*IF($G$1="牵丝",$AJ10,$AH10)+IF($G$1="牵丝",$AK10*1.5,0))*(1+$BC10)*(1+$BD10)+(($BE10+$BF10)/2*IF($G$1="破竹",$AJ10,$AH10)+IF($G$1="破竹",$AK10*1.5,0))*(1+$BG10)*(1+$BH10))*(1+$AL10)*$P10*(1+IF(VLOOKUP($Q10,武学奇术!$A:$ZZ,30,FALSE)="蓄力技",$B$21,0))*(1+$BQ10) -> 8485.6485 | O10: =((($AN10*$AH10+$AI10)*(1+$AP10)*(1+$AQ10)+($AS10*IF($G$1="鸣金",$AJ10,$AH10)+IF($G$1="鸣金",$AK10*1.5,0))*(1+$AU10)*(1+$AV10)+($AW10*IF($G$1="裂石",$AJ10,$AH10)+IF($G$1="裂石",$AK10*1.5,0))*(1+$AY10)*(1+$AZ10)+($BA10*IF($G$1="牵丝",$AJ10,$AH10)+IF($G$1="牵丝",$AK10*1.5,0))*(1+$BC10)*(1+$BD10)+($BE10*IF($G$1="破竹",$AJ10,$AH10)+IF($G$1="破竹",$AK10*1.5,0))*(1+$BG10)*(1+$BH10))*(1+$AL10))*$P10*(1+IF(VLOOKUP($Q10,武学奇术!$A:$ZZ,30,FALSE)="蓄力技",$B$21,0))*(1+$BQ10) -> 7393.7865 | P10: 1 | Q10: 陌刀安西军下劈无开山 | R10: 易水歌2层 | S10: 胆寒 | T10: 惧刃 | U10: 穿喉4 | V10: N/a | W10: 中程笛(小人) | X10: N/a | Y10: N/a | Z10: N/a | AA10: 断岳 | AB10: N/a | AC10: N/a | AD10: N/a | AE10: N/a | AF10: 铁衣 | AG10: =VLOOKUP($Q10,武学奇术!$A:$ZZ,25,FALSE) -> 陌刀 | AH10: =VLOOKUP($Q10,武学奇术!$A:$ZZ,26,FALSE) -> 0.5 | AI10: =VLOOKUP($Q10,武学奇术!$A:$ZZ,27,FALSE)*(1+IF(OR($AG10=$F$4,$AG10=$F$5),$B$22,0)) -> 0 | AJ10: =VLOOKUP($Q10,武学奇术!$A:$ZZ,28,FALSE) -> 0.75 | AK10: =VLOOKUP($Q10,武学奇术!$A:$ZZ,29,FALSE)*(1+IF(OR($AG10=$F$4,$AG10=$F$5),$B$22,0)) -> 0 | AL10: {=$G$3+IFERROR(VLOOKUP($AG10,$F$4:$G$7,2,FALSE),0)+VLOOKUP($Q10,武学奇术!$A:$ZZ,2,FALSE)+SUM(_xlfn.XLOOKUP($R10:$AF10,增益!$A:$A,增益!$B:$B,0))} -> 0.983 | AM10: {=VLOOKUP($Q10,武学奇术!$A:$ZZ,5,FALSE)+SUM(_xlfn.XLOOKUP($R10:$AF10,增益!$A:$A,增益!$E:$E,0))} -> 0 | AN10: {=$D$10*(1+$AM10)+VLOOKUP($Q10,武学奇术!$A:$ZZ,3,FALSE)+SUM(_xlfn.XLOOKUP($R10:$AF10,增益!$A:$A,增益!$C:$C,0))-$I$2} -> 3052.34 | AO10: {=$E$10*(1+$AM10)+VLOOKUP($Q10,武学奇术!$A:$ZZ,4,FALSE)+SUM(_xlfn.XLOOKUP($R10:$AF10,增益!$A:$A,增益!$D:$D,0))-$I$2} -> 3052.34 | AP10: {=IF($F$10-$I$3+VLOOKUP($Q10,武学奇术!$A:$ZZ,6,FALSE)+SUM(_xlfn.XLOOKUP(R10:AF10,增益!$A:$A,增益!$F:$F,0))>0,($F$10-$I$3+VLOOKUP($Q10,武学奇术!$A:$ZZ,6,FALSE)+SUM(_xlfn.XLOOKUP(R10:AF10,增益!$A:$A,增益!$F:$F,0)))/200,($F$10-$I$3+VLOOKUP($Q10,武学奇术!$A:$ZZ,6,FALSE)+SUM(_xlfn.XLOOKUP(R10:AF10,增益!$A:$A,增益!$F:$F,0)))/100)} -> 0.422 | AQ10: {=$G$10+VLOOKUP($Q10,武学奇术!$A:$ZZ,7,FALSE)+SUM(_xlfn.XLOOKUP(R10:AF10,增益!$A:$A,增益!$G:$G,0))} -> 0 | AR10: {=VLOOKUP($Q10,武学奇术!$A:$ZZ,8,FALSE)+SUM(_xlfn.XLOOKUP(R10:AF10,增益!$A:$A,增益!$H:$H,0))} -> 0 | AS10: =$D$11*(1+$AR10) -> 0 | AT10: =$E$11*(1+$AR10) -> 0 | AU10: {=IF($F$11-$I$4+VLOOKUP($Q10,武学奇术!$A:$ZZ,9,FALSE)+SUM(_xlfn.XLOOKUP(R10:AF10,增益!$A:$A,增益!$I:$I,0))>0,($F$11-$I$4+VLOOKUP($Q10,武学奇术!$A:$ZZ,9,FALSE)+SUM(_xlfn.XLOOKUP(R10:AF10,增益!$A:$A,增益!$I:$I,0)))/200,($F$11-$I$4+VLOOKUP($Q10,武学奇术!$A:$ZZ,9,FALSE)+SUM(_xlfn.XLOOKUP(R10:AF10,增益!$A:$A,增益!$I:$I,0)))/100)} -> -0.08 | AV10: {=$G$11+VLOOKUP($Q10,武学奇术!$A:$ZZ,10,FALSE)+SUM(_xlfn.XLOOKUP(R10:AF10,增益!$A:$A,增益!$J:$J,0))} -> 0 | AW10: =$D$12*(1+$AR10) -> 634.5 | AX10: =$E$12*(1+$AR10) -> 1443.3 | AY10: {=IF($F$12-$I$4+VLOOKUP($Q10,武学奇术!$A:$ZZ,11,FALSE)+SUM(_xlfn.XLOOKUP(R10:AF10,增益!$A:$A,增益!$K:$K,0))>0,($F$12-$I$4+VLOOKUP($Q10,武学奇术!$A:$ZZ,11,FALSE)+SUM(_xlfn.XLOOKUP(R10:AF10,增益!$A:$A,增益!$K:$K,0)))/200,($F$12-$I$4+VLOOKUP($Q10,武学奇术!$A:$ZZ,11,FALSE)+SUM(_xlfn.XLOOKUP(R10:AF10,增益!$A:$A,增益!$K:$K,0)))/100)} -> 0.198 | AZ10: {=$G$12+VLOOKUP($Q10,武学奇术!$A:$ZZ,12,FALSE)+SUM(_xlfn.XLOOKUP(R10:AF10,增益!$A:$A,增益!$L:$L,0))} -> 0.148 | BA10: =$D$13*(1+$AR10) -> 0 | BB10: =$E$13*(1+$AR10) -> 0 | BC10: {=IF($F$13-$I$4+VLOOKUP($Q10,武学奇术!$A:$ZZ,13,FALSE)+SUM(_xlfn.XLOOKUP(R10:AF10,增益!$A:$A,增益!$M:$M,0))>0,($F$13-$I$4+VLOOKUP($Q10,武学奇术!$A:$ZZ,13,FALSE)+SUM(_xlfn.XLOOKUP(R10:AF10,增益!$A:$A,增益!$K:$K,0)))/200,($F$13-$I$4+VLOOKUP($Q10,武学奇术!$A:$ZZ,13,FALSE)+SUM(_xlfn.XLOOKUP(R10:AF10,增益!$A:$A,增益!$M:$M,0)))/100)} -> -0.08 | BD10: {=$G$13+VLOOKUP($Q10,武学奇术!$A:$ZZ,14,FALSE)+SUM(_xlfn.XLOOKUP(R10:AF10,增益!$A:$A,增益!$N:$N,0))} -> 0 | BE10: =$D$14*(1+$AR10) -> 0 | BF10: =$E$14*(1+$AR10) -> 0 | BG10: {=IF($F$14-$I$4+VLOOKUP($Q10,武学奇术!$A:$ZZ,15,FALSE)+SUM(_xlfn.XLOOKUP(R10:AF10,增益!$A:$A,增益!$O:$O,0))>0,($F$14-$I$4+VLOOKUP($Q10,武学奇术!$A:$ZZ,15,FALSE)+SUM(_xlfn.XLOOKUP(R10:AF10,增益!$A:$A,增益!$O:$O,0)))/200,($F$14-$I$4+VLOOKUP($Q10,武学奇术!$A:$ZZ,15,FALSE)+SUM(_xlfn.XLOOKUP(R10:AF10,增益!$A:$A,增益!$O:$O,0)))/100)} -> -0.08 | BH10: {=$G$14+VLOOKUP($Q10,武学奇术!$A:$ZZ,16,FALSE)+SUM(_xlfn.XLOOKUP(R10:AF10,增益!$A:$A,增益!$P:$P,0))} -> 0 | BI10: =MIN(IF(VLOOKUP($Q10,武学奇术!$A:$ZZ,23,FALSE)=1,100%,$B$8),100%) -> 0.8626 | BJ10: {=IF(VLOOKUP($Q10,武学奇术!$A:$ZZ,23,FALSE)=1,100%,MIN(80%,$B$9+VLOOKUP($Q10,武学奇术!$A:$ZZ,17,FALSE)+SUM(_xlfn.XLOOKUP(R10:AF10,增益!$A:$A,增益!$Q:$Q,0)))+$B$11+SUM(_xlfn.XLOOKUP(R10:AF10,增益!$A:$A,增益!$U:$U,0)))*IF(VLOOKUP($Q10,武学奇术!$A:$ZZ,24,FALSE)=1,0,1)} -> 0.8697 | BK10: {=1+$B$13+VLOOKUP($Q10,武学奇术!$A:$ZZ,18,FALSE)+SUM(_xlfn.XLOOKUP(R10:AF10,增益!$A:$A,增益!$R:$R,0))} -> 1.87 | BL10: {=IF(VLOOKUP($Q10,武学奇术!$A:$ZZ,24,FALSE)=1,100%,MIN(40%,$B$10+VLOOKUP($Q10,武学奇术!$A:$ZZ,19,FALSE)+SUM(_xlfn.XLOOKUP(R10:AF10,增益!$A:$A,增益!$S:$S,0)))+$B$12+SUM(_xlfn.XLOOKUP(R10:AF10,增益!$A:$A,增益!$V:$V,0)))*IF(VLOOKUP($Q10,武学奇术!$A:$ZZ,23,FALSE)=1,0,1)} -> 0.0986 | BM10: {=1+$B$14+VLOOKUP($Q10,武学奇术!$A:$ZZ,20,FALSE)+SUM(_xlfn.XLOOKUP(R10:AF10,增益!$A:$A,增益!$T:$T,0))} -> 1.35 | BN10: =MIN((1-BL10)*BI10,BI10*BJ10) -> 0.75020322 | BO10: =1-BL10-BN10-BP10 -> 0.02734442 | BP10: =IF(VLOOKUP($Q10,武学奇术!$A:$ZZ,22,FALSE)=1,0,(1-$BI10))*(1-$BL10) -> 0.12385236 | BQ10: {=SUM(_xlfn.XLOOKUP(R10:AF10,增益!$A:$A,增益!$W:$W,0))} -> 0
